<?xml version='1.0' encoding='utf-8'?>
<mujoco model="miku">
  <compiler angle="radian" meshdir="../meshes/" />

  <asset>
    <mesh name="pelvis_visual" content_type="model/stl" file="pelvis_visual.stl" />
    <mesh name="right_hip_pitch_visual" content_type="model/stl" file="right_hip_pitch_visual.stl" />
    <mesh name="right_hip_roll_visual" content_type="model/stl" file="right_hip_roll_visual.stl" />
    <mesh name="right_hip_yaw_visual" content_type="model/stl" file="right_hip_yaw_visual.stl" />
    <mesh name="right_knee_pitch_visual" content_type="model/stl" file="right_knee_pitch_visual.stl" />
    <mesh name="right_ankle_roll_visual" content_type="model/stl" file="right_ankle_roll_visual.stl" />
    <mesh name="right_ankle_yaw_visual" content_type="model/stl" file="right_ankle_yaw_visual.stl" />
    <mesh name="right_foot_visual" content_type="model/stl" file="right_foot_visual.stl" />
    <mesh name="left_hip_pitch_visual" content_type="model/stl" file="left_hip_pitch_visual.stl" />
    <mesh name="left_hip_roll_visual" content_type="model/stl" file="left_hip_roll_visual.stl" />
    <mesh name="left_hip_yaw_visual" content_type="model/stl" file="left_hip_yaw_visual.stl" />
    <mesh name="left_knee_pitch_visual" content_type="model/stl" file="left_knee_pitch_visual.stl" />
    <mesh name="left_ankle_roll_visual" content_type="model/stl" file="left_ankle_roll_visual.stl" />
    <mesh name="left_ankle_yaw_visual" content_type="model/stl" file="left_ankle_yaw_visual.stl" />
    <mesh name="left_foot_visual" content_type="model/stl" file="left_foot_visual.stl" />
    <mesh name="waist_yaw_visual" content_type="model/stl" file="waist_yaw_visual.stl" />
    <mesh name="waist_pitch_visual" content_type="model/stl" file="waist_pitch_visual.stl" />
    <mesh name="shoulder_base_visual" content_type="model/stl" file="shoulder_base_visual.stl" />
    <mesh name="left_shoulder_pitch_visual" content_type="model/stl"
      file="left_shoulder_pitch_visual.stl" />
    <mesh name="left_shoulder_roll_visual" content_type="model/stl"
      file="left_shoulder_roll_visual.stl" />
    <mesh name="left_shoulder_yaw_visual" content_type="model/stl"
      file="left_shoulder_yaw_visual.stl" />
    <mesh name="left_elbow_pitch_visual" content_type="model/stl" file="left_elbow_pitch_visual.stl" />
    <mesh name="left_wrist_roll_visual" content_type="model/stl" file="left_wrist_roll_visual.stl" />
    <mesh name="left_wrist_yaw_visual" content_type="model/stl" file="left_wrist_yaw_visual.stl" />
    <mesh name="left_palm_visual" content_type="model/stl" file="left_palm_visual.stl" />
    <mesh name="left_finger_1_mcp_visual" content_type="model/stl"
      file="left_finger_1_mcp_visual.stl" />
    <mesh name="left_finger_1_proximal_visual" content_type="model/stl"
      file="left_finger_1_proximal_visual.stl" />
    <mesh name="left_finger_1_intermediate_visual" content_type="model/stl"
      file="left_finger_1_intermediate_visual.stl" />
    <mesh name="left_finger_1_distal_visual" content_type="model/stl"
      file="left_finger_1_distal_visual.stl" />
    <mesh name="left_finger_2_mcp_visual" content_type="model/stl"
      file="left_finger_2_mcp_visual.stl" />
    <mesh name="left_finger_2_proximal_visual" content_type="model/stl"
      file="left_finger_2_proximal_visual.stl" />
    <mesh name="left_finger_2_intermediate_visual" content_type="model/stl"
      file="left_finger_2_intermediate_visual.stl" />
    <mesh name="left_finger_2_distal_visual" content_type="model/stl"
      file="left_finger_2_distal_visual.stl" />
    <mesh name="left_finger_3_mcp_visual" content_type="model/stl"
      file="left_finger_3_mcp_visual.stl" />
    <mesh name="left_finger_3_proximal_visual" content_type="model/stl"
      file="left_finger_3_proximal_visual.stl" />
    <mesh name="left_finger_3_intermediate_visual" content_type="model/stl"
      file="left_finger_3_intermediate_visual.stl" />
    <mesh name="left_finger_3_distal_visual" content_type="model/stl"
      file="left_finger_3_distal_visual.stl" />
    <mesh name="left_finger_4_mcp_visual" content_type="model/stl"
      file="left_finger_4_mcp_visual.stl" />
    <mesh name="left_finger_4_proximal_visual" content_type="model/stl"
      file="left_finger_4_proximal_visual.stl" />
    <mesh name="left_finger_4_intermediate_visual" content_type="model/stl"
      file="left_finger_4_intermediate_visual.stl" />
    <mesh name="left_finger_4_distal_visual" content_type="model/stl"
      file="left_finger_4_distal_visual.stl" />
    <mesh name="left_finger_5_mcp_visual" content_type="model/stl"
      file="left_finger_5_mcp_visual.stl" />
    <mesh name="left_finger_5_proximal_visual" content_type="model/stl"
      file="left_finger_5_proximal_visual.stl" />
    <mesh name="left_finger_5_intermediate_visual" content_type="model/stl"
      file="left_finger_5_intermediate_visual.stl" />
    <mesh name="left_finger_5_distal_visual" content_type="model/stl"
      file="left_finger_5_distal_visual.stl" />
    <mesh name="right_shoulder_pitch_visual" content_type="model/stl"
      file="right_shoulder_pitch_visual.stl" />
    <mesh name="right_shoulder_roll_visual" content_type="model/stl"
      file="right_shoulder_roll_visual.stl" />
    <mesh name="right_shoulder_yaw_visual" content_type="model/stl"
      file="right_shoulder_yaw_visual.stl" />
    <mesh name="right_elbow_pitch_visual" content_type="model/stl"
      file="right_elbow_pitch_visual.stl" />
    <mesh name="right_wrist_roll_visual" content_type="model/stl" file="right_wrist_roll_visual.stl" />
    <mesh name="right_wrist_yaw_visual" content_type="model/stl" file="right_wrist_yaw_visual.stl" />
    <mesh name="right_palm_visual" content_type="model/stl" file="right_palm_visual.stl" />
    <mesh name="right_finger_1_mcp_visual" content_type="model/stl"
      file="right_finger_1_mcp_visual.stl" />
    <mesh name="right_finger_1_proximal_visual" content_type="model/stl"
      file="right_finger_1_proximal_visual.stl" />
    <mesh name="right_finger_1_intermediate_visual" content_type="model/stl"
      file="right_finger_1_intermediate_visual.stl" />
    <mesh name="right_finger_1_distal_visual" content_type="model/stl"
      file="right_finger_1_distal_visual.stl" />
    <mesh name="right_finger_2_mcp_visual" content_type="model/stl"
      file="right_finger_2_mcp_visual.stl" />
    <mesh name="right_finger_2_proximal_visual" content_type="model/stl"
      file="right_finger_2_proximal_visual.stl" />
    <mesh name="right_finger_2_intermediate_visual" content_type="model/stl"
      file="right_finger_2_intermediate_visual.stl" />
    <mesh name="right_finger_2_distal_visual" content_type="model/stl"
      file="right_finger_2_distal_visual.stl" />
    <mesh name="right_finger_3_mcp_visual" content_type="model/stl"
      file="right_finger_3_mcp_visual.stl" />
    <mesh name="right_finger_3_proximal_visual" content_type="model/stl"
      file="right_finger_3_proximal_visual.stl" />
    <mesh name="right_finger_3_intermediate_visual" content_type="model/stl"
      file="right_finger_3_intermediate_visual.stl" />
    <mesh name="right_finger_3_distal_visual" content_type="model/stl"
      file="right_finger_3_distal_visual.stl" />
    <mesh name="right_finger_4_mcp_visual" content_type="model/stl"
      file="right_finger_4_mcp_visual.stl" />
    <mesh name="right_finger_4_proximal_visual" content_type="model/stl"
      file="right_finger_4_proximal_visual.stl" />
    <mesh name="right_finger_4_intermediate_visual" content_type="model/stl"
      file="right_finger_4_intermediate_visual.stl" />
    <mesh name="right_finger_4_distal_visual" content_type="model/stl"
      file="right_finger_4_distal_visual.stl" />
    <mesh name="right_finger_5_mcp_visual" content_type="model/stl"
      file="right_finger_5_mcp_visual.stl" />
    <mesh name="right_finger_5_proximal_visual" content_type="model/stl"
      file="right_finger_5_proximal_visual.stl" />
    <mesh name="right_finger_5_intermediate_visual" content_type="model/stl"
      file="right_finger_5_intermediate_visual.stl" />
    <mesh name="right_finger_5_distal_visual" content_type="model/stl"
      file="right_finger_5_distal_visual.stl" />
    <mesh name="neck_yaw_visual" content_type="model/stl" file="neck_yaw_visual.stl" />
    <mesh name="neck_roll_visual" content_type="model/stl" file="neck_roll_visual.stl" />
    <mesh name="head_visual" content_type="model/stl" file="head_visual.stl" />
  </asset>

  <worldbody>
    <body name="pelvis">
      <inertial pos="8.97668e-09 0 0.891865" quat="0.707107 0.707107 2.2164e-05 -2.2164e-05"
        mass="1.63184" diaginertia="0.00445142 0.00442459 0.00217002" />
      <geom pos="8.97668e-09 0 0.891865" quat="1 0 0 0" type="mesh" contype="0" conaffinity="0"
        group="1" density="0" rgba="0.615686 0.811765 0.929412 1" mesh="pelvis_visual" />
      <body name="right_hip_pitch" pos="0 -0.08 0.89" quat="0.707105 0.707108 0 0">
        <inertial pos="-0.075 0 0" mass="0.486947" diaginertia="0.000608684 0.000405789 0.000405789" />
        <joint name="left_hip_pitch" pos="0 0 0" axis="0 0 1" range="-0.785398 2.35619"
          actuatorfrcrange="-100 100" frictionloss="0.1" armature="0.01" />
        <geom pos="-0.075 0 0" quat="0.707105 -0.707108 0 0" type="mesh" contype="0" conaffinity="0"
          group="1" density="0" rgba="0.647059 0.647059 0.647059 1" mesh="right_hip_pitch_visual" />
        <body name="right_hip_roll" pos="-0.05 0 0"
          quat="9.38184e-07 -0.707105 -9.38187e-07 -0.707108">
          <inertial pos="0 0.21 0.05" quat="0.707107 0.707107 0 0" mass="3.11646"
            diaginertia="0.0285416 0.0285416 0.00389557" />
          <joint name="left_hip_roll" pos="0 0 0" axis="0 0 1" range="-0.261799 1.5708"
            actuatorfrcrange="-100 100" frictionloss="0.1" armature="0.01" />
          <geom size="0.05 0.1" pos="0 0.212 0.05" quat="0.707105 0.707108 0 0" type="cylinder" />
          <geom pos="0 0.21 0.05" quat="0.499998 0.5 -0.5 0.500002" type="mesh" contype="0"
            conaffinity="0" group="1" density="0" rgba="0.231373 0.380392 0.705882 1"
            mesh="right_hip_roll_visual" />
          <body name="right_hip_yaw" pos="0 0.37 0.05" quat="0.707105 -0.707108 0 0">
            <inertial pos="0 0 0.05" mass="0.486947"
              diaginertia="0.000608684 0.000405789 0.000405789" />
            <joint name="left_hip_yaw" pos="0 0 0" axis="0 0 1" range="-0.785398 0.785398"
              actuatorfrcrange="-100 100" frictionloss="0.1" armature="0.01" />
            <geom pos="0 0 0.05" quat="9.38184e-07 0.707105 -0.707108 -9.38187e-07" type="mesh"
              contype="0" conaffinity="0" group="1" density="0" rgba="0.917647 0.917647 0.917647 1"
              mesh="right_hip_yaw_visual" />
            <body name="right_knee_pitch" pos="0.025 0 0.05" quat="0.499998 -0.5 0.500002 -0.5">
              <inertial pos="0 -0.197 -0.025" quat="0.707107 0.707107 0 0" mass="2.86325"
                diaginertia="0.0224135 0.0224135 0.00357906" />
              <joint name="left_knee_pitch" pos="0 0 0" axis="0 0 1" range="-2.35619 0"
                actuatorfrcrange="-100 100" frictionloss="0.1" armature="0.01" />
              <geom size="0.05 0.075" pos="0 -0.222 -0.025" quat="0.499998 -0.5 -0.5 -0.500002"
                type="cylinder" />
              <geom pos="0 -0.197 -0.025" quat="0.707105 -0.707108 0 0" type="mesh" contype="0"
                conaffinity="0" group="1" density="0" rgba="0.768627 0.886275 0.952941 1"
                mesh="right_knee_pitch_visual" />
              <body name="right_ankle_roll" pos="0 -0.344 -0.025" quat="0.499998 0.5 -0.5 0.500002">
                <inertial pos="0 0 0.05" quat="0.707107 0.707107 0 0" mass="0.121737"
                  diaginertia="4.43832e-05 4.43832e-05 3.80427e-05" />
                <joint name="left_ankle_yaw" pos="0 0 0" axis="0 0 1" range="-0.785398 0.785398"
                  actuatorfrcrange="-100 100" frictionloss="0.1" armature="0.01" />
                <geom pos="0 0 0.05" quat="9.38184e-07 0.707105 -0.707108 -9.38187e-07" type="mesh"
                  contype="0" conaffinity="0" group="1" density="0"
                  rgba="0.498039 0.498039 0.498039 1" mesh="right_ankle_roll_visual" />
                <body name="right_ankle_yaw" pos="0 0.025 0.05" quat="0.707105 -0.707108 0 0">
                  <inertial pos="0 0 -0.025" quat="0.5 0.5 0.5 0.5" mass="0.121737"
                    diaginertia="4.43832e-05 4.43832e-05 3.80427e-05" />
                  <joint name="left_ankle_roll" pos="0 0 0" axis="0 0 1" range="-0.349066 0.349066"
                    actuatorfrcrange="-100 100" frictionloss="0.1" armature="0.01" />
                  <geom pos="0 0 -0.025" quat="0.499998 -0.5 0.5 0.500002" type="mesh" contype="0"
                    conaffinity="0" group="1" density="0" rgba="0.768627 0.886275 0.952941 1"
                    mesh="right_ankle_yaw_visual" />
                  <body name="right_foot" pos="0.025 0 -0.025" quat="0.707105 0 0.707108 0">
                    <inertial pos="0.0525 -0.063 -0.025" quat="0.5 0.5 0.5 0.5" mass="0.433566"
                      diaginertia="0.00137997 0.00126908 0.000175919" />
                    <joint name="left_ankle_pitch" pos="0 0 0" axis="0 0 1"
                      range="-0.785398 0.785398" actuatorfrcrange="-100 100" frictionloss="0.1"
                      armature="0.01" />
                    <geom size="0.0315 0.0925 0.015" pos="0.052 -0.063 -0.025"
                      quat="0.499998 -0.5 -0.5 -0.500002" type="box" />
                    <geom pos="0.0525 -0.063 -0.025" quat="0.707105 -0.707108 0 0" type="mesh"
                      contype="0" conaffinity="0" group="1" density="0"
                      rgba="0.972549 0.529412 0.00392157 1" mesh="right_foot_visual" />
                  </body>
                </body>
              </body>
            </body>
          </body>
        </body>
      </body>
      <body name="left_hip_pitch" pos="0 0.08 0.89" quat="0.707105 -0.707108 0 0">
        <inertial pos="-0.075 0 0" mass="0.486947" diaginertia="0.000608684 0.000405789 0.000405789" />
        <joint name="right_hip_pitch" pos="0 0 0" axis="0 0 1" range="-2.35619 0.785398"
          actuatorfrcrange="-100 100" frictionloss="0.1" armature="0.01" />
        <geom pos="-0.075 0 0" quat="0.707105 0.707108 0 0" type="mesh" contype="0" conaffinity="0"
          group="1" density="0" rgba="0.647059 0.647059 0.647059 1" mesh="left_hip_pitch_visual" />
        <body name="left_hip_roll" pos="-0.05 0 0" quat="0.707105 0 0.707108 0">
          <inertial pos="0 0.21 0.05" quat="0.707107 0.707107 0 0" mass="3.11646"
            diaginertia="0.0285416 0.0285416 0.00389557" />
          <joint name="right_hip_roll" pos="0 0 0" axis="0 0 1" range="-1.5708 0.261799"
            actuatorfrcrange="-100 100" frictionloss="0.1" armature="0.01" />
          <geom size="0.05 0.1" pos="0 0.212 0.05" quat="0.707105 0.707108 0 0" type="cylinder" />
          <geom pos="0 0.21 0.05" quat="0.499998 0.5 -0.5 0.500002" type="mesh" contype="0"
            conaffinity="0" group="1" density="0" rgba="0.231373 0.380392 0.705882 1"
            mesh="left_hip_roll_visual" />
          <body name="left_hip_yaw" pos="0 0.37 0.05" quat="0.707105 -0.707108 0 0">
            <inertial pos="0 0 0.05" mass="0.486947"
              diaginertia="0.000608684 0.000405789 0.000405789" />
            <joint name="right_hip_yaw" pos="0 0 0" axis="0 0 1" range="-0.785398 0.785398"
              actuatorfrcrange="-100 100" frictionloss="0.1" armature="0.01" />
            <geom pos="0 0 0.05" quat="9.38184e-07 -0.707105 0.707108 -9.38187e-07" type="mesh"
              contype="0" conaffinity="0" group="1" density="0" rgba="0.917647 0.917647 0.917647 1"
              mesh="left_hip_yaw_visual" />
            <body name="left_knee_pitch" pos="-0.025 0 0.05" quat="0.499998 0.5 -0.500002 -0.5">
              <inertial pos="0 0.197 -0.025" quat="0.707107 0.707107 0 0" mass="2.86325"
                diaginertia="0.0224135 0.0224135 0.00357906" />
              <joint name="right_knee_pitch" pos="0 0 0" axis="0 0 1" range="0 2.35619"
                actuatorfrcrange="-100 100" frictionloss="0.1" armature="0.01" />
              <geom size="0.05 0.075" pos="0 0.222 -0.025" quat="0.499998 0.5 0.5 -0.500002"
                type="cylinder" />
              <geom pos="0 0.197 -0.025" quat="0.707105 0.707108 0 0" type="mesh" contype="0"
                conaffinity="0" group="1" density="0" rgba="0.768627 0.886275 0.952941 1"
                mesh="left_knee_pitch_visual" />
              <body name="left_ankle_roll" pos="0 0.344 -0.025" quat="0.499998 -0.5 0.5 0.500002">
                <inertial pos="0 0 0.05" quat="0.707107 0.707107 0 0" mass="0.121737"
                  diaginertia="4.43832e-05 4.43832e-05 3.80427e-05" />
                <joint name="right_ankle_yaw" pos="0 0 0" axis="0 0 1" range="-0.785398 0.785398"
                  actuatorfrcrange="-100 100" frictionloss="0.1" armature="0.01" />
                <geom pos="0 0 0.05" quat="9.38184e-07 -0.707105 0.707108 -9.38187e-07" type="mesh"
                  contype="0" conaffinity="0" group="1" density="0"
                  rgba="0.498039 0.498039 0.498039 1" mesh="left_ankle_roll_visual" />
                <body name="left_ankle_yaw" pos="0 0.025 0.05" quat="0.707105 -0.707108 0 0">
                  <inertial pos="0 0 -0.025" quat="0.5 0.5 0.5 0.5" mass="0.121737"
                    diaginertia="4.43832e-05 4.43832e-05 3.80427e-05" />
                  <joint name="right_ankle_roll" pos="0 0 0" axis="0 0 1" range="-0.349066 0.349066"
                    actuatorfrcrange="-100 100" frictionloss="0.1" armature="0.01" />
                  <geom pos="0 0 -0.025" quat="0.499998 -0.5 0.5 0.500002" type="mesh" contype="0"
                    conaffinity="0" group="1" density="0" rgba="0.768627 0.886275 0.952941 1"
                    mesh="left_ankle_yaw_visual" />
                  <body name="left_foot" pos="-0.025 0 -0.025"
                    quat="9.38184e-07 0.707105 9.38187e-07 -0.707108">
                    <inertial pos="0.0525 0.063 -0.025" quat="0.5 0.5 0.5 0.5" mass="0.433566"
                      diaginertia="0.00137997 0.00126908 0.000175919" />
                    <joint name="right_ankle_pitch" pos="0 0 0" axis="0 0 1"
                      range="-0.785398 0.785398" actuatorfrcrange="-100 100" frictionloss="0.1"
                      armature="0.01" />
                    <geom size="0.0315 0.0925 0.015" pos="0.052 0.063 -0.025"
                      quat="0.499998 0.5 0.5 -0.500002" type="box" />
                    <geom pos="0.0525 0.063 -0.025" quat="0.707105 0.707108 0 0" type="mesh"
                      contype="0" conaffinity="0" group="1" density="0"
                      rgba="0.972549 0.529412 0.00392157 1" mesh="left_foot_visual" />
                  </body>
                </body>
              </body>
            </body>
          </body>
        </body>
      </body>
      <body name="waist_yaw" pos="0 0 0.94" quat="0.707105 0 0 -0.707108">
        <inertial pos="0 0 0.040516" mass="0.311646"
          diaginertia="0.000249317 0.000189585 0.000189585" />
        <joint name="waist_yaw" pos="0 0 0" axis="0 0 1" range="-0.785398 0.785398"
          actuatorfrcrange="-100 100" frictionloss="0.1" armature="0.01" />
        <geom pos="0 0 0.040516" quat="0.707105 0 0 0.707108" type="mesh" contype="0"
          conaffinity="0" group="1" density="0" rgba="0.615686 0.811765 0.929412 1"
          mesh="waist_yaw_visual" />
        <body name="waist_pitch" pos="0.025 0 0.040516" quat="0.499998 0.5 0.500002 0.5">
          <inertial pos="0 0.118004 -0.025" mass="0.486947"
            diaginertia="0.000608684 0.000405789 0.000405789" />
          <joint name="waist_pitch" pos="0 0 0" axis="0 0 1" range="-0.523599 0.523599"
            actuatorfrcrange="-100 100" frictionloss="0.1" armature="0.01" />
          <geom pos="0 0.118004 -0.025" quat="0.707105 -0.707108 0 0" type="mesh" contype="0"
            conaffinity="0" group="1" density="0" rgba="0.980392 0.713725 0.00392157 1"
            mesh="waist_pitch_visual" />
          <body name="shoulder_base" pos="0.025 0.118004 -0.025"
            quat="9.38184e-07 -0.707105 -9.38187e-07 -0.707108">
            <inertial pos="3.67182e-08 -0.151463 -0.0249996" quat="0.500009 0.499999 -0.499992 0.5"
              mass="1.35594" diaginertia="0.00312204 0.00285851 0.00182667" />
            <joint name="waist_roll" pos="0 0 0" axis="0 0 1" range="-0.523599 0.523599"
              actuatorfrcrange="-100 100" frictionloss="0.1" armature="0.01" />
            <geom size="0.05 0.1" pos="0 -0.09948 -0.025" quat="0.707105 0.707108 0 0"
              type="cylinder" />
            <geom pos="3.67182e-08 -0.151463 -0.0249996" quat="0.499998 0.5 -0.5 0.500002"
              type="mesh" contype="0" conaffinity="0" group="1" density="0"
              rgba="0.647059 0.647059 0.647059 1" mesh="shoulder_base_visual" />
            <body name="left_shoulder_pitch" pos="-0.052 -0.16948 -0.025"
              quat="0.707105 0 -0.707108 0">
              <inertial pos="0 0 0.04" mass="0.311646"
                diaginertia="0.000249317 0.000189585 0.000189585" />
              <joint name="left_shoulder_pitch" pos="0 0 0" axis="0 0 1" range="-3.14159 0.785398"
                actuatorfrcrange="-100 100" frictionloss="0.1" armature="0.01" />
              <geom pos="0 0 0.04" quat="0.707105 0.707108 0 0" type="mesh" contype="0"
                conaffinity="0" group="1" density="0" rgba="0.231373 0.380392 0.705882 1"
                mesh="left_shoulder_pitch_visual" />
              <body name="left_shoulder_roll" pos="0.025 0 0.04" quat="0.707105 0 0.707108 0">
                <inertial pos="-0.108 0 -0.025" quat="0.5 0.5 0.5 0.5" mass="0.476818"
                  diaginertia="0.00084222 0.00084222 0.000214568" />
                <joint name="left_shoulder_roll" pos="0 0 0" axis="0 0 1" range="-3.14159 0.261799"
                  actuatorfrcrange="-100 100" frictionloss="0.1" armature="0.01" />
                <geom size="0.03 0.04" pos="-0.108 0 -0.025" quat="0.499998 0.5 0.500002 0.5"
                  type="cylinder" />
                <geom pos="-0.108 0 -0.025" quat="0.499998 0.5 -0.5 0.500002" type="mesh"
                  contype="0" conaffinity="0" group="1" density="0"
                  rgba="0.917647 0.917647 0.917647 1" mesh="left_shoulder_roll_visual" />
                <body name="left_shoulder_yaw" pos="-0.176 0 -0.025" quat="0.707105 0 -0.707108 0">
                  <inertial pos="0 0 0.03" quat="0.707107 0 0 0.707107" mass="0.175301"
                    diaginertia="7.88854e-05 7.59637e-05 7.59637e-05" />
                  <joint name="left_shoulder_yaw" pos="0 0 0" axis="0 0 1" range="-1.5708 1.5708"
                    actuatorfrcrange="-100 100" frictionloss="0.1" armature="0.01" />
                  <geom pos="0 0 0.03" quat="0.707105 0.707108 0 0" type="mesh" contype="0"
                    conaffinity="0" group="1" density="0" rgba="0.768627 0.886275 0.952941 1"
                    mesh="left_shoulder_yaw_visual" />
                  <body name="left_elbow_pitch" pos="0 -0.025 0.03"
                    quat="0.499998 0.5 0.5 -0.500002">
                    <inertial pos="-0.0925 0 -0.025" quat="0.5 0.5 0.5 0.5" mass="0.304342"
                      diaginertia="0.000443832 0.000443832 9.51068e-05" />
                    <joint name="left_elbow_pitch" pos="0 0 0" axis="0 0 1" range="-2.35619 0"
                      actuatorfrcrange="-100 100" frictionloss="0.1" armature="0.01" />
                    <geom size="0.025 0.04" pos="-0.102 0 -0.025" quat="0.707105 0 0.707108 0"
                      type="cylinder" />
                    <geom pos="-0.0925 0 -0.025" quat="0.707105 0 0 0.707108" type="mesh"
                      contype="0" conaffinity="0" group="1" density="0"
                      rgba="0.972549 0.529412 0.00392157 1" mesh="left_elbow_pitch_visual" />
                    <body name="left_wrist_roll" pos="-0.155 0 -0.025"
                      quat="0.499998 -0.5 -0.500002 0.5">
                      <inertial pos="0 0 0.025" quat="0.707107 0.707107 0 0" mass="0.0779115"
                        diaginertia="2.40227e-05 2.40227e-05 1.55823e-05" />
                      <joint name="left_wrist_yaw" pos="0 0 0" axis="0 0 1" range="-1.5708 1.5708"
                        actuatorfrcrange="-100 100" frictionloss="0.1" armature="0.01" />
                      <geom pos="0 0 0.025" quat="0.707105 0.707108 0 0" type="mesh" contype="0"
                        conaffinity="0" group="1" density="0" rgba="0.980392 0.713725 0.00392157 1"
                        mesh="left_wrist_roll_visual" />
                      <body name="left_wrist_yaw" pos="0 -0.025 0.025"
                        quat="0.499998 0.5 0.5 -0.500002">
                        <inertial pos="0 0 -0.025" quat="0.707107 0.707107 0 0" mass="0.0779115"
                          diaginertia="2.40227e-05 2.40227e-05 1.55823e-05" />
                        <joint name="left_wrist_roll" pos="0 0 0" axis="0 0 1"
                          range="-0.349066 0.349066" actuatorfrcrange="-100 100" frictionloss="0.1"
                          armature="0.01" />
                        <geom pos="0 0 -0.025" quat="0.707105 0 0 0.707108" type="mesh" contype="0"
                          conaffinity="0" group="1" density="0" rgba="0.498039 0.498039 0.498039 1"
                          mesh="left_wrist_yaw_visual" />
                        <body name="left_palm" pos="0 0.025 -0.025" quat="0.707105 -0.707108 0 0">
                          <inertial pos="-0.0475 0 -0.04" quat="0.707107 0 0 0.707107"
                            mass="0.03255" diaginertia="1.01041e-05 7.39156e-06 3.93312e-06" />
                          <joint name="left_wrist_pitch" pos="0 0 0" axis="0 0 1"
                            range="-1.5708 1.5708" actuatorfrcrange="-100 100" frictionloss="0.1"
                            armature="0.01" />
                          <geom size="0.05 0.03 0.0075" pos="-0.072 0 -0.025"
                            quat="0.707105 0.707108 0 0" type="box" />
                          <geom pos="-0.0475 0 -0.04" quat="0.499998 0.5 -0.5 0.500002" type="mesh"
                            contype="0" conaffinity="0" group="1" density="0"
                            rgba="0.615686 0.811765 0.929412 1" mesh="left_palm_visual" />
                          <body name="left_finger_1_mcp" pos="-0.0307574 0 -0.00575736"
                            quat="0.92388 0 0.382683 0">
                            <inertial pos="-0.0025 0 -0.006" mass="0.000744"
                              diaginertia="1.5128e-08 1.0478e-08 7.75e-09" />
                            <joint name="left_hand_finger1_joint1" pos="0 0 0" axis="0 0 1"
                              range="-1.5708 0" actuatorfrcrange="-100 100" frictionloss="0.05"
                              armature="0.001" />
                            <geom pos="-0.0025 0 -0.006"
                              quat="-0.270598 -0.270598 0.653282 -0.653281" type="mesh" contype="0"
                              conaffinity="0" group="1" density="0"
                              rgba="0.498039 0.498039 0.498039 1" mesh="left_finger_1_mcp_visual" />
                            <body name="left_finger_1_proximal" pos="-0.007 0.005 -0.006"
                              quat="0.65328 0.653283 -0.270597 0.270598">
                              <inertial pos="-0.00707107 0.00707107 0.005"
                                quat="0.270598 0.653281 -0.270598 0.653281" mass="0.002976"
                                diaginertia="1.34912e-07 1.24e-07 6.0512e-08" />
                              <joint name="left_hand_finger1_joint2" pos="0 0 0" axis="0 0 1"
                                range="-0.349066 0.349066" actuatorfrcrange="-100 100"
                                frictionloss="0.05" armature="0.001" />
                              <geom pos="-0.00707107 0.00707107 0.005" quat="0.707105 0 0 0.707108"
                                type="mesh" contype="0" conaffinity="0" group="1" density="0"
                                rgba="0.972549 0.529412 0.00392157 1"
                                mesh="left_finger_1_proximal_visual" />
                              <body name="left_finger_1_intermediate"
                                pos="-0.0120208 0.0190919 0.005"
                                quat="0.65328 -0.653283 0.270598 -0.270597">
                                <inertial pos="-0.01 0 -0.005" quat="0.5 0.5 0.5 0.5"
                                  mass="0.001984" diaginertia="8.26667e-08 7.67147e-08 2.71147e-08" />
                                <joint name="left_hand_finger1_joint3" pos="0 0 0" axis="0 0 1"
                                  range="-1.5708 0" actuatorfrcrange="-100 100" frictionloss="0.05"
                                  armature="0.001" />
                                <geom pos="-0.01 0 -0.005"
                                  quat="0.270599 0.270597 -0.653283 0.65328" type="mesh" contype="0"
                                  conaffinity="0" group="1" density="0"
                                  rgba="0.498039 0.498039 0.498039 1"
                                  mesh="left_finger_1_intermediate_visual" />
                                <body name="left_finger_1_distal" pos="-0.022 0 0" quat="1 0 0 0">
                                  <inertial pos="-0.0075 0 -0.005" quat="0.5 0.5 0.5 0.5"
                                    mass="0.001488" diaginertia="4.03e-08 3.5836e-08 2.0336e-08" />
                                  <joint name="left_hand_finger1_joint4" pos="0 0 0" axis="0 0 1"
                                    range="-1.5708 0" actuatorfrcrange="-100 100"
                                    frictionloss="0.05" armature="0.001" />
                                  <geom pos="-0.0075 0 -0.005"
                                    quat="0.270599 0.270597 -0.653283 0.65328" type="mesh"
                                    contype="0" conaffinity="0" group="1" density="0"
                                    rgba="0.980392 0.713725 0.00392157 1"
                                    mesh="left_finger_1_distal_visual" />
                                </body>
                              </body>
                            </body>
                          </body>
                          <body name="left_finger_2_mcp" pos="-0.067 0 -0.016">
                            <inertial pos="-0.0025 0 -0.004" quat="0.707107 0.707107 0 0"
                              mass="0.000496" diaginertia="6.77867e-09 5.16667e-09 3.67867e-09" />
                            <joint name="left_hand_finger2_joint1" pos="0 0 0" axis="0 0 1"
                              range="-1.5708 0" actuatorfrcrange="-100 100" frictionloss="0.05"
                              armature="0.001" />
                            <geom pos="-0.0025 0 -0.004" quat="0.499998 0.5 -0.5 0.500002"
                              type="mesh" contype="0" conaffinity="0" group="1" density="0"
                              rgba="0.980392 0.713725 0.00392157 1" mesh="left_finger_2_mcp_visual" />
                            <body name="left_finger_2_proximal" pos="-0.007 0.005 -0.004"
                              quat="0.707105 0.707108 0 0">
                              <inertial pos="-0.0125 0 0.005" quat="0.5 0.5 0.5 0.5" mass="0.00248"
                                diaginertia="1.49833e-07 1.42393e-07 3.38933e-08" />
                              <joint name="left_hand_finger2_joint2" pos="0 0 0" axis="0 0 1"
                                range="-0.349066 0.349066" actuatorfrcrange="-100 100"
                                frictionloss="0.05" armature="0.001" />
                              <geom pos="-0.0125 0 0.005" quat="0.707105 0 0 0.707108" type="mesh"
                                contype="0" conaffinity="0" group="1" density="0"
                                rgba="0.647059 0.647059 0.647059 1"
                                mesh="left_finger_2_proximal_visual" />
                              <body name="left_finger_2_intermediate" pos="-0.027 0.003 0.005"
                                quat="0.707105 -0.707108 0 0">
                                <inertial pos="-0.01 0 -0.003" quat="0 0.707107 0 0.707107"
                                  mass="0.0011904" diaginertia="4.60288e-08 4.32512e-08 9.92e-09" />
                                <joint name="left_hand_finger2_joint3" pos="0 0 0" axis="0 0 1"
                                  range="-1.5708 0" actuatorfrcrange="-100 100" frictionloss="0.05"
                                  armature="0.001" />
                                <geom pos="-0.01 0 -0.003" quat="0.499998 0.5 -0.5 0.500002"
                                  type="mesh" contype="0" conaffinity="0" group="1" density="0"
                                  rgba="0.498039 0.498039 0.498039 1"
                                  mesh="left_finger_2_intermediate_visual" />
                                <body name="left_finger_2_distal" pos="-0.022 0 -0.0005">
                                  <inertial pos="-0.005 0 -0.0025" quat="0 0.707107 0 0.707107"
                                    mass="0.000496"
                                    diaginertia="6.77867e-09 5.16667e-09 3.67867e-09" />
                                  <joint name="left_hand_finger2_joint4" pos="0 0 0" axis="0 0 1"
                                    range="-1.5708 0" actuatorfrcrange="-100 100"
                                    frictionloss="0.05" armature="0.001" />
                                  <geom pos="-0.005 0 -0.0025" quat="0.499998 0.5 -0.5 0.500002"
                                    type="mesh" contype="0" conaffinity="0" group="1" density="0"
                                    rgba="0.980392 0.713725 0.00392157 1"
                                    mesh="left_finger_2_distal_visual" />
                                </body>
                              </body>
                            </body>
                          </body>
                          <body name="left_finger_3_mcp" pos="-0.067 0 -0.031">
                            <inertial pos="-0.0025 0 -0.004" quat="0.707107 0.707107 0 0"
                              mass="0.000496" diaginertia="6.77867e-09 5.16667e-09 3.67867e-09" />
                            <joint name="left_hand_finger3_joint1" pos="0 0 0" axis="0 0 1"
                              range="-1.5708 0" actuatorfrcrange="-100 100" frictionloss="0.05"
                              armature="0.001" />
                            <geom pos="-0.0025 0 -0.004" quat="0.499998 0.5 -0.5 0.500002"
                              type="mesh" contype="0" conaffinity="0" group="1" density="0"
                              rgba="0.615686 0.811765 0.929412 1" mesh="left_finger_3_mcp_visual" />
                            <body name="left_finger_3_proximal" pos="-0.007 0.005 -0.004"
                              quat="0.707105 0.707108 0 0">
                              <inertial pos="-0.015 0 0.005" quat="0.5 0.5 0.5 0.5" mass="0.002976"
                                diaginertia="2.48e-07 2.39072e-07 4.0672e-08" />
                              <joint name="left_hand_finger3_joint2" pos="0 0 0" axis="0 0 1"
                                range="-0.349066 0.349066" actuatorfrcrange="-100 100"
                                frictionloss="0.05" armature="0.001" />
                              <geom pos="-0.015 0 0.005" quat="0.707105 0 0 0.707108" type="mesh"
                                contype="0" conaffinity="0" group="1" density="0"
                                rgba="0.231373 0.380392 0.705882 1"
                                mesh="left_finger_3_proximal_visual" />
                              <body name="left_finger_3_intermediate" pos="-0.032 0.003 0.005"
                                quat="0.707105 -0.707108 0 0">
                                <inertial pos="-0.0125 0 -0.003" quat="0 0.707107 0 0.707107"
                                  mass="0.001488" diaginertia="8.5436e-08 8.1964e-08 1.24e-08" />
                                <joint name="left_hand_finger3_joint3" pos="0 0 0" axis="0 0 1"
                                  range="-1.5708 0" actuatorfrcrange="-100 100" frictionloss="0.05"
                                  armature="0.001" />
                                <geom pos="-0.0125 0 -0.003" quat="0.499998 0.5 -0.5 0.500002"
                                  type="mesh" contype="0" conaffinity="0" group="1" density="0"
                                  rgba="0.615686 0.811765 0.929412 1"
                                  mesh="left_finger_3_intermediate_visual" />
                                <body name="left_finger_3_distal" pos="-0.027 0 -0.0005">
                                  <inertial pos="-0.005 0 -0.0025" quat="0 0.707107 0 0.707107"
                                    mass="0.000496"
                                    diaginertia="6.77867e-09 5.16667e-09 3.67867e-09" />
                                  <joint name="left_hand_finger3_joint4" pos="0 0 0" axis="0 0 1"
                                    range="-1.5708 0" actuatorfrcrange="-100 100"
                                    frictionloss="0.05" armature="0.001" />
                                  <geom pos="-0.005 0 -0.0025" quat="0.499998 0.5 -0.5 0.500002"
                                    type="mesh" contype="0" conaffinity="0" group="1" density="0"
                                    rgba="0.647059 0.647059 0.647059 1"
                                    mesh="left_finger_3_distal_visual" />
                                </body>
                              </body>
                            </body>
                          </body>
                          <body name="left_finger_4_mcp" pos="-0.067 0 -0.046">
                            <inertial pos="-0.0025 0 -0.004" quat="0.707107 0.707107 0 0"
                              mass="0.000496" diaginertia="6.77867e-09 5.16667e-09 3.67867e-09" />
                            <joint name="left_hand_finger4_joint1" pos="0 0 0" axis="0 0 1"
                              range="-1.5708 0" actuatorfrcrange="-100 100" frictionloss="0.05"
                              armature="0.001" />
                            <geom pos="-0.0025 0 -0.004" quat="0.499998 0.5 -0.5 0.500002"
                              type="mesh" contype="0" conaffinity="0" group="1" density="0"
                              rgba="0.647059 0.647059 0.647059 1" mesh="left_finger_4_mcp_visual" />
                            <body name="left_finger_4_proximal" pos="-0.007 0.005 -0.004"
                              quat="0.707105 0.707108 0 0">
                              <inertial pos="-0.015 0 0.005" quat="0.5 0.5 0.5 0.5" mass="0.002976"
                                diaginertia="2.48e-07 2.39072e-07 4.0672e-08" />
                              <joint name="left_hand_finger4_joint2" pos="0 0 0" axis="0 0 1"
                                range="-0.349066 0.349066" actuatorfrcrange="-100 100"
                                frictionloss="0.05" armature="0.001" />
                              <geom pos="-0.015 0 0.005" quat="0.707105 0 0 0.707108" type="mesh"
                                contype="0" conaffinity="0" group="1" density="0"
                                rgba="0.917647 0.917647 0.917647 1"
                                mesh="left_finger_4_proximal_visual" />
                              <body name="left_finger_4_intermediate" pos="-0.032 0.003 0.005"
                                quat="0.707105 -0.707108 0 0">
                                <inertial pos="-0.01 0 -0.003" quat="0 0.707107 0 0.707107"
                                  mass="0.0011904" diaginertia="4.60288e-08 4.32512e-08 9.92e-09" />
                                <joint name="left_hand_finger4_joint3" pos="0 0 0" axis="0 0 1"
                                  range="-1.5708 0" actuatorfrcrange="-100 100" frictionloss="0.05"
                                  armature="0.001" />
                                <geom pos="-0.01 0 -0.003" quat="0.499998 0.5 -0.5 0.500002"
                                  type="mesh" contype="0" conaffinity="0" group="1" density="0"
                                  rgba="0.231373 0.380392 0.705882 1"
                                  mesh="left_finger_4_intermediate_visual" />
                                <body name="left_finger_4_distal" pos="-0.022 0 -0.0005">
                                  <inertial pos="-0.005 0 -0.0025" quat="0 0.707107 0 0.707107"
                                    mass="0.000496"
                                    diaginertia="6.77867e-09 5.16667e-09 3.67867e-09" />
                                  <joint name="left_hand_finger4_joint4" pos="0 0 0" axis="0 0 1"
                                    range="-1.5708 0" actuatorfrcrange="-100 100"
                                    frictionloss="0.05" armature="0.001" />
                                  <geom pos="-0.005 0 -0.0025" quat="0.499998 0.5 -0.5 0.500002"
                                    type="mesh" contype="0" conaffinity="0" group="1" density="0"
                                    rgba="0.917647 0.917647 0.917647 1"
                                    mesh="left_finger_4_distal_visual" />
                                </body>
                              </body>
                            </body>
                          </body>
                          <body name="left_finger_5_mcp" pos="-0.067 0 -0.061">
                            <inertial pos="-0.0025 0 -0.004" quat="0.707107 0.707107 0 0"
                              mass="0.000496" diaginertia="6.77867e-09 5.16667e-09 3.67867e-09" />
                            <joint name="left_hand_finger5_joint1" pos="0 0 0" axis="0 0 1"
                              range="-1.5708 0" actuatorfrcrange="-100 100" frictionloss="0.05"
                              armature="0.001" />
                            <geom pos="-0.0025 0 -0.004" quat="0.499998 0.5 -0.5 0.500002"
                              type="mesh" contype="0" conaffinity="0" group="1" density="0"
                              rgba="0.231373 0.380392 0.705882 1" mesh="left_finger_5_mcp_visual" />
                            <body name="left_finger_5_proximal" pos="-0.007 0.005 -0.004"
                              quat="0.707105 0.707108 0 0">
                              <inertial pos="-0.01 0 0.005" quat="0.5 0.5 0.5 0.5" mass="0.001984"
                                diaginertia="8.26667e-08 7.67147e-08 2.71147e-08" />
                              <joint name="left_hand_finger5_joint2" pos="0 0 0" axis="0 0 1"
                                range="-0.349066 0.349066" actuatorfrcrange="-100 100"
                                frictionloss="0.05" armature="0.001" />
                              <geom pos="-0.01 0 0.005" quat="0.707105 0 0 0.707108" type="mesh"
                                contype="0" conaffinity="0" group="1" density="0"
                                rgba="0.768627 0.886275 0.952941 1"
                                mesh="left_finger_5_proximal_visual" />
                              <body name="left_finger_5_intermediate" pos="-0.022 0.003 0.005"
                                quat="0.707105 -0.707108 0 0">
                                <inertial pos="-0.0075 0 -0.003" quat="0 0.707107 0 0.707107"
                                  mass="0.0008928" diaginertia="2.15016e-08 1.94184e-08 7.44e-09" />
                                <joint name="left_hand_finger5_joint3" pos="0 0 0" axis="0 0 1"
                                  range="-1.5708 0" actuatorfrcrange="-100 100" frictionloss="0.05"
                                  armature="0.001" />
                                <geom pos="-0.0075 0 -0.003" quat="0.499998 0.5 -0.5 0.500002"
                                  type="mesh" contype="0" conaffinity="0" group="1" density="0"
                                  rgba="0.768627 0.886275 0.952941 1"
                                  mesh="left_finger_5_intermediate_visual" />
                                <body name="left_finger_5_distal" pos="-0.017 0 -0.0005">
                                  <inertial pos="-0.005 0 -0.0025" quat="0 0.707107 0 0.707107"
                                    mass="0.000496"
                                    diaginertia="6.77867e-09 5.16667e-09 3.67867e-09" />
                                  <joint name="left_hand_finger5_joint4" pos="0 0 0" axis="0 0 1"
                                    range="-1.5708 0" actuatorfrcrange="-100 100"
                                    frictionloss="0.05" armature="0.001" />
                                  <geom pos="-0.005 0 -0.0025" quat="0.499998 0.5 -0.5 0.500002"
                                    type="mesh" contype="0" conaffinity="0" group="1" density="0"
                                    rgba="0.972549 0.529412 0.00392157 1"
                                    mesh="left_finger_5_distal_visual" />
                                </body>
                              </body>
                            </body>
                          </body>
                        </body>
                      </body>
                    </body>
                  </body>
                </body>
              </body>
            </body>
            <body name="right_shoulder_pitch" pos="0.052 -0.16948 -0.025"
              quat="9.38184e-07 0.707105 -9.38187e-07 0.707108">
              <inertial pos="0 0 0.04" mass="0.311646"
                diaginertia="0.000249317 0.000189585 0.000189585" />
              <joint name="right_shoulder_pitch" pos="0 0 0" axis="0 0 1" range="-3.14159 0.785398"
                actuatorfrcrange="-100 100" frictionloss="0.1" armature="0.01" />
              <geom pos="0 0 0.04" quat="0.707105 -0.707108 0 0" type="mesh" contype="0"
                conaffinity="0" group="1" density="0" rgba="0.231373 0.380392 0.705882 1"
                mesh="right_shoulder_pitch_visual" />
              <body name="right_shoulder_roll" pos="0.025 0 0.04"
                quat="9.38184e-07 -0.707105 -9.38187e-07 -0.707108">
                <inertial pos="0.108 0 -0.025" quat="0.5 0.5 0.5 0.5" mass="0.476818"
                  diaginertia="0.00084222 0.00084222 0.000214568" />
                <joint name="right_shoulder_roll" pos="0 0 0" axis="0 0 1" range="-0.261799 3.14159"
                  actuatorfrcrange="-100 100" frictionloss="0.1" armature="0.01" />
                <geom size="0.03 0.04" pos="0.108 0 -0.025" quat="0.499998 0.5 0.500002 0.5"
                  type="cylinder" />
                <geom pos="0.108 0 -0.025" quat="0.499998 0.5 -0.5 0.500002" type="mesh" contype="0"
                  conaffinity="0" group="1" density="0" rgba="0.917647 0.917647 0.917647 1"
                  mesh="right_shoulder_roll_visual" />
                <body name="right_shoulder_yaw" pos="0.176 0 -0.025"
                  quat="9.38184e-07 -0.707105 -9.38187e-07 -0.707108">
                  <inertial pos="0 0 0.03" quat="0.707107 0 0 0.707107" mass="0.175301"
                    diaginertia="7.88854e-05 7.59637e-05 7.59637e-05" />
                  <joint name="right_shoulder_yaw" pos="0 0 0" axis="0 0 1" range="-1.5708 1.5708"
                    actuatorfrcrange="-100 100" frictionloss="0.1" armature="0.01" />
                  <geom pos="0 0 0.03" quat="0.707105 -0.707108 0 0" type="mesh" contype="0"
                    conaffinity="0" group="1" density="0" rgba="0.768627 0.886275 0.952941 1"
                    mesh="right_shoulder_yaw_visual" />
                  <body name="right_elbow_pitch" pos="0 0.025 0.03"
                    quat="0.499998 -0.5 -0.5 -0.500002">
                    <inertial pos="0.0925 0 -0.025" quat="0.5 0.5 0.5 0.5" mass="0.304342"
                      diaginertia="0.000443832 0.000443832 9.51068e-05" />
                    <joint name="right_elbow_pitch" pos="0 0 0" axis="0 0 1" range="0 2.35619"
                      actuatorfrcrange="-100 100" frictionloss="0.1" armature="0.01" />
                    <geom size="0.025 0.04" pos="0.102 0 -0.025" quat="0.707105 0 0.707108 0"
                      type="cylinder" />
                    <geom pos="0.0925 0 -0.025" quat="0.707105 0 0 0.707108" type="mesh" contype="0"
                      conaffinity="0" group="1" density="0" rgba="0.972549 0.529412 0.00392157 1"
                      mesh="right_elbow_pitch_visual" />
                    <body name="right_wrist_roll" pos="0.155 0 -0.025"
                      quat="0.499998 0.5 0.500002 0.5">
                      <inertial pos="0 0 0.025" quat="0.707107 0.707107 0 0" mass="0.0779115"
                        diaginertia="2.40227e-05 2.40227e-05 1.55823e-05" />
                      <joint name="right_wrist_yaw" pos="0 0 0" axis="0 0 1" range="-1.5708 1.5708"
                        actuatorfrcrange="-100 100" frictionloss="0.1" armature="0.01" />
                      <geom pos="0 0 0.025" quat="0.707105 -0.707108 0 0" type="mesh" contype="0"
                        conaffinity="0" group="1" density="0" rgba="0.980392 0.713725 0.00392157 1"
                        mesh="right_wrist_roll_visual" />
                      <body name="right_wrist_yaw" pos="0 0.025 0.025"
                        quat="0.499998 -0.5 -0.5 -0.500002">
                        <inertial pos="0 0 -0.025" quat="0.707107 0.707107 0 0" mass="0.0779115"
                          diaginertia="2.40227e-05 2.40227e-05 1.55823e-05" />
                        <joint name="right_wrist_roll" pos="0 0 0" axis="0 0 1"
                          range="-0.349066 0.349066" actuatorfrcrange="-100 100" frictionloss="0.1"
                          armature="0.01" />
                        <geom pos="0 0 -0.025" quat="0.707105 0 0 0.707108" type="mesh" contype="0"
                          conaffinity="0" group="1" density="0" rgba="0.498039 0.498039 0.498039 1"
                          mesh="right_wrist_yaw_visual" />
                        <body name="right_palm" pos="0 0.025 -0.025" quat="0.707105 -0.707108 0 0">
                          <inertial pos="0.0475 0 -0.04" quat="0.707107 0 0 0.707107" mass="0.03255"
                            diaginertia="1.01041e-05 7.39156e-06 3.93312e-06" />
                          <joint name="right_wrist_pitch" pos="0 0 0" axis="0 0 1"
                            range="-1.5708 1.5708" actuatorfrcrange="-100 100" frictionloss="0.1"
                            armature="0.01" />
                          <geom size="0.05 0.03 0.0075" pos="0.072 0 -0.025"
                            quat="0.707105 0.707108 0 0" type="box" />
                          <geom pos="0.0475 0 -0.04" quat="0.499998 0.5 -0.5 0.500002" type="mesh"
                            contype="0" conaffinity="0" group="1" density="0"
                            rgba="0.615686 0.811765 0.929412 1" mesh="right_palm_visual" />
                          <body name="right_finger_1_mcp" pos="0.0307574 0 -0.00575736"
                            quat="0.92388 0 -0.382683 0">
                            <inertial pos="0.0025 0 -0.006" mass="0.000744"
                              diaginertia="1.5128e-08 1.0478e-08 7.75e-09" />
                            <joint name="right_hand_finger1_joint1" pos="0 0 0" axis="0 0 1"
                              range="0 1.5708" actuatorfrcrange="-100 100" frictionloss="0.05"
                              armature="0.001" />
                            <geom pos="0.0025 0 -0.006" quat="0.65328 0.653283 -0.270597 0.270598"
                              type="mesh" contype="0" conaffinity="0" group="1" density="0"
                              rgba="0.498039 0.498039 0.498039 1" mesh="right_finger_1_mcp_visual" />
                            <body name="right_finger_1_proximal" pos="0.007 0.005 -0.006"
                              quat="0.65328 0.653283 0.270597 -0.270598">
                              <inertial pos="0.00707107 0.00707107 0.005"
                                quat="0.653281 0.270598 -0.653281 0.270598" mass="0.002976"
                                diaginertia="1.34912e-07 1.24e-07 6.0512e-08" />
                              <joint name="right_hand_finger1_joint2" pos="0 0 0" axis="0 0 1"
                                range="-0.349066 0.349066" actuatorfrcrange="-100 100"
                                frictionloss="0.05" armature="0.001" />
                              <geom pos="0.00707107 0.00707107 0.005" quat="0.707105 0 0 0.707108"
                                type="mesh" contype="0" conaffinity="0" group="1" density="0"
                                rgba="0.972549 0.529412 0.00392157 1"
                                mesh="right_finger_1_proximal_visual" />
                              <body name="right_finger_1_intermediate"
                                pos="0.0120208 0.0190919 0.005"
                                quat="0.65328 -0.653283 -0.270598 0.270597">
                                <inertial pos="0.01 0 -0.005" quat="0.5 0.5 0.5 0.5" mass="0.001984"
                                  diaginertia="8.26667e-08 7.67147e-08 2.71147e-08" />
                                <joint name="right_hand_finger1_joint3" pos="0 0 0" axis="0 0 1"
                                  range="0 1.5708" actuatorfrcrange="-100 100" frictionloss="0.05"
                                  armature="0.001" />
                                <geom pos="0.01 0 -0.005" quat="0.65328 0.653283 -0.270597 0.270598"
                                  type="mesh" contype="0" conaffinity="0" group="1" density="0"
                                  rgba="0.498039 0.498039 0.498039 1"
                                  mesh="right_finger_1_intermediate_visual" />
                                <body name="right_finger_1_distal" pos="0.022 0 0">
                                  <inertial pos="0.0075 0 -0.005" quat="0.5 0.5 0.5 0.5"
                                    mass="0.001488" diaginertia="4.03e-08 3.5836e-08 2.0336e-08" />
                                  <joint name="right_hand_finger1_joint4" pos="0 0 0" axis="0 0 1"
                                    range="0 1.5708" actuatorfrcrange="-100 100" frictionloss="0.05"
                                    armature="0.001" />
                                  <geom pos="0.0075 0 -0.005"
                                    quat="0.65328 0.653283 -0.270597 0.270598" type="mesh"
                                    contype="0" conaffinity="0" group="1" density="0"
                                    rgba="0.980392 0.713725 0.00392157 1"
                                    mesh="right_finger_1_distal_visual" />
                                </body>
                              </body>
                            </body>
                          </body>
                          <body name="right_finger_2_mcp" pos="0.067 0 -0.016">
                            <inertial pos="0.0025 0 -0.004" quat="0.707107 0.707107 0 0"
                              mass="0.000496" diaginertia="6.77867e-09 5.16667e-09 3.67867e-09" />
                            <joint name="right_hand_finger2_joint1" pos="0 0 0" axis="0 0 1"
                              range="0 1.5708" actuatorfrcrange="-100 100" frictionloss="0.05"
                              armature="0.001" />
                            <geom pos="0.0025 0 -0.004" quat="0.499998 0.5 -0.5 0.500002"
                              type="mesh" contype="0" conaffinity="0" group="1" density="0"
                              rgba="0.980392 0.713725 0.00392157 1" mesh="right_finger_2_mcp_visual" />
                            <body name="right_finger_2_proximal" pos="0.007 0.005 -0.004"
                              quat="0.707105 0.707108 0 0">
                              <inertial pos="0.0125 0 0.005" quat="0.5 0.5 0.5 0.5" mass="0.00248"
                                diaginertia="1.49833e-07 1.42393e-07 3.38933e-08" />
                              <joint name="right_hand_finger2_joint2" pos="0 0 0" axis="0 0 1"
                                range="-0.349066 0.349066" actuatorfrcrange="-100 100"
                                frictionloss="0.05" armature="0.001" />
                              <geom pos="0.0125 0 0.005" quat="0.707105 0 0 0.707108" type="mesh"
                                contype="0" conaffinity="0" group="1" density="0"
                                rgba="0.647059 0.647059 0.647059 1"
                                mesh="right_finger_2_proximal_visual" />
                              <body name="right_finger_2_intermediate" pos="0.027 0.003 0.005"
                                quat="0.707105 -0.707108 0 0">
                                <inertial pos="0.01 0 -0.003" quat="0 0.707107 0 0.707107"
                                  mass="0.0011904" diaginertia="4.60288e-08 4.32512e-08 9.92e-09" />
                                <joint name="right_hand_finger2_joint3" pos="0 0 0" axis="0 0 1"
                                  range="0 1.5708" actuatorfrcrange="-100 100" frictionloss="0.05"
                                  armature="0.001" />
                                <geom pos="0.01 0 -0.003" quat="0.499998 0.5 -0.5 0.500002"
                                  type="mesh" contype="0" conaffinity="0" group="1" density="0"
                                  rgba="0.498039 0.498039 0.498039 1"
                                  mesh="right_finger_2_intermediate_visual" />
                                <body name="right_finger_2_distal" pos="0.022 0 -0.0005"
                                  quat="1 0 0 0">
                                  <inertial pos="0.005 0 -0.0025" quat="0 0.707107 0 0.707107"
                                    mass="0.000496"
                                    diaginertia="6.77867e-09 5.16667e-09 3.67867e-09" />
                                  <joint name="right_hand_finger2_joint4" pos="0 0 0" axis="0 0 1"
                                    range="0 1.5708" actuatorfrcrange="-100 100" frictionloss="0.05"
                                    armature="0.001" />
                                  <geom pos="0.005 0 -0.0025" quat="0.499998 0.5 -0.5 0.500002"
                                    type="mesh" contype="0" conaffinity="0" group="1" density="0"
                                    rgba="0.980392 0.713725 0.00392157 1"
                                    mesh="right_finger_2_distal_visual" />
                                </body>
                              </body>
                            </body>
                          </body>
                          <body name="right_finger_3_mcp" pos="0.067 0 -0.031" quat="1 0 0 0">
                            <inertial pos="0.0025 0 -0.004" quat="0.707107 0.707107 0 0"
                              mass="0.000496" diaginertia="6.77867e-09 5.16667e-09 3.67867e-09" />
                            <joint name="right_hand_finger3_joint1" pos="0 0 0" axis="0 0 1"
                              range="0 1.5708" actuatorfrcrange="-100 100" frictionloss="0.05"
                              armature="0.001" />
                            <geom pos="0.0025 0 -0.004" quat="0.499998 0.5 -0.5 0.500002"
                              type="mesh" contype="0" conaffinity="0" group="1" density="0"
                              rgba="0.615686 0.811765 0.929412 1" mesh="right_finger_3_mcp_visual" />
                            <body name="right_finger_3_proximal" pos="0.007 0.005 -0.004"
                              quat="0.707105 0.707108 0 0">
                              <inertial pos="0.015 0 0.005" quat="0.5 0.5 0.5 0.5" mass="0.002976"
                                diaginertia="2.48e-07 2.39072e-07 4.0672e-08" />
                              <joint name="right_hand_finger3_joint2" pos="0 0 0" axis="0 0 1"
                                range="-0.349066 0.349066" actuatorfrcrange="-100 100"
                                frictionloss="0.05" armature="0.001" />
                              <geom pos="0.015 0 0.005" quat="0.707105 0 0 0.707108" type="mesh"
                                contype="0" conaffinity="0" group="1" density="0"
                                rgba="0.231373 0.380392 0.705882 1"
                                mesh="right_finger_3_proximal_visual" />
                              <body name="right_finger_3_intermediate" pos="0.032 0.003 0.005"
                                quat="0.707105 -0.707108 0 0">
                                <inertial pos="0.0125 0 -0.003" quat="0 0.707107 0 0.707107"
                                  mass="0.001488" diaginertia="8.5436e-08 8.1964e-08 1.24e-08" />
                                <joint name="right_hand_finger3_joint3" pos="0 0 0" axis="0 0 1"
                                  range="0 1.5708" actuatorfrcrange="-100 100" frictionloss="0.05"
                                  armature="0.001" />
                                <geom pos="0.0125 0 -0.003" quat="0.499998 0.5 -0.5 0.500002"
                                  type="mesh" contype="0" conaffinity="0" group="1" density="0"
                                  rgba="0.615686 0.811765 0.929412 1"
                                  mesh="right_finger_3_intermediate_visual" />
                                <body name="right_finger_3_distal" pos="0.027 0 -0.0005">
                                  <inertial pos="0.005 0 -0.0025" quat="0 0.707107 0 0.707107"
                                    mass="0.000496"
                                    diaginertia="6.77867e-09 5.16667e-09 3.67867e-09" />
                                  <joint name="right_hand_finger3_joint4" pos="0 0 0" axis="0 0 1"
                                    range="0 1.5708" actuatorfrcrange="-100 100" frictionloss="0.05"
                                    armature="0.001" />
                                  <geom pos="0.005 0 -0.0025" quat="0.499998 0.5 -0.5 0.500002"
                                    type="mesh" contype="0" conaffinity="0" group="1" density="0"
                                    rgba="0.647059 0.647059 0.647059 1"
                                    mesh="right_finger_3_distal_visual" />
                                </body>
                              </body>
                            </body>
                          </body>
                          <body name="right_finger_4_mcp" pos="0.067 0 -0.046">
                            <inertial pos="0.0025 0 -0.004" quat="0.707107 0.707107 0 0"
                              mass="0.000496" diaginertia="6.77867e-09 5.16667e-09 3.67867e-09" />
                            <joint name="right_hand_finger4_joint1" pos="0 0 0" axis="0 0 1"
                              range="0 1.5708" actuatorfrcrange="-100 100" frictionloss="0.05"
                              armature="0.001" />
                            <geom pos="0.0025 0 -0.004" quat="0.499998 0.5 -0.5 0.500002"
                              type="mesh" contype="0" conaffinity="0" group="1" density="0"
                              rgba="0.647059 0.647059 0.647059 1" mesh="right_finger_4_mcp_visual" />
                            <body name="right_finger_4_proximal" pos="0.007 0.005 -0.004"
                              quat="0.707105 0.707108 0 0">
                              <inertial pos="0.015 0 0.005" quat="0.5 0.5 0.5 0.5" mass="0.002976"
                                diaginertia="2.48e-07 2.39072e-07 4.0672e-08" />
                              <joint name="right_hand_finger4_joint2" pos="0 0 0" axis="0 0 1"
                                range="-0.349066 0.349066" actuatorfrcrange="-100 100"
                                frictionloss="0.05" armature="0.001" />
                              <geom pos="0.015 0 0.005" quat="0.707105 0 0 0.707108" type="mesh"
                                contype="0" conaffinity="0" group="1" density="0"
                                rgba="0.917647 0.917647 0.917647 1"
                                mesh="right_finger_4_proximal_visual" />
                              <body name="right_finger_4_intermediate" pos="0.032 0.003 0.005"
                                quat="0.707105 -0.707108 0 0">
                                <inertial pos="0.01 0 -0.003" quat="0 0.707107 0 0.707107"
                                  mass="0.0011904" diaginertia="4.60288e-08 4.32512e-08 9.92e-09" />
                                <joint name="right_hand_finger4_joint3" pos="0 0 0" axis="0 0 1"
                                  range="0 1.5708" actuatorfrcrange="-100 100" frictionloss="0.05"
                                  armature="0.001" />
                                <geom pos="0.01 0 -0.003" quat="0.499998 0.5 -0.5 0.500002"
                                  type="mesh" contype="0" conaffinity="0" group="1" density="0"
                                  rgba="0.231373 0.380392 0.705882 1"
                                  mesh="right_finger_4_intermediate_visual" />
                                <body name="right_finger_4_distal" pos="0.022 0 -0.0005">
                                  <inertial pos="0.005 0 -0.0025" quat="0 0.707107 0 0.707107"
                                    mass="0.000496"
                                    diaginertia="6.77867e-09 5.16667e-09 3.67867e-09" />
                                  <joint name="right_hand_finger4_joint4" pos="0 0 0" axis="0 0 1"
                                    range="0 1.5708" actuatorfrcrange="-100 100" frictionloss="0.05"
                                    armature="0.001" />
                                  <geom pos="0.005 0 -0.0025" quat="0.499998 0.5 -0.5 0.500002"
                                    type="mesh" contype="0" conaffinity="0" group="1" density="0"
                                    rgba="0.917647 0.917647 0.917647 1"
                                    mesh="right_finger_4_distal_visual" />
                                </body>
                              </body>
                            </body>
                          </body>
                          <body name="right_finger_5_mcp" pos="0.067 0 -0.061">
                            <inertial pos="0.0025 0 -0.004" quat="0.707107 0.707107 0 0"
                              mass="0.000496" diaginertia="6.77867e-09 5.16667e-09 3.67867e-09" />
                            <joint name="right_hand_finger5_joint1" pos="0 0 0" axis="0 0 1"
                              range="0 1.5708" actuatorfrcrange="-100 100" frictionloss="0.05"
                              armature="0.001" />
                            <geom pos="0.0025 0 -0.004" quat="0.499998 0.5 -0.5 0.500002"
                              type="mesh" contype="0" conaffinity="0" group="1" density="0"
                              rgba="0.231373 0.380392 0.705882 1" mesh="right_finger_5_mcp_visual" />
                            <body name="right_finger_5_proximal" pos="0.007 0.005 -0.004"
                              quat="0.707105 0.707108 0 0">
                              <inertial pos="0.01 0 0.005" quat="0.5 0.5 0.5 0.5" mass="0.001984"
                                diaginertia="8.26667e-08 7.67147e-08 2.71147e-08" />
                              <joint name="right_hand_finger5_joint2" pos="0 0 0" axis="0 0 1"
                                range="-0.349066 0.349066" actuatorfrcrange="-100 100"
                                frictionloss="0.05" armature="0.001" />
                              <geom pos="0.01 0 0.005" quat="0.707105 0 0 0.707108" type="mesh"
                                contype="0" conaffinity="0" group="1" density="0"
                                rgba="0.768627 0.886275 0.952941 1"
                                mesh="right_finger_5_proximal_visual" />
                              <body name="right_finger_5_intermediate" pos="0.022 0.003 0.005"
                                quat="0.707105 -0.707108 0 0">
                                <inertial pos="0.0075 0 -0.003" quat="0 0.707107 0 0.707107"
                                  mass="0.0008928" diaginertia="2.15016e-08 1.94184e-08 7.44e-09" />
                                <joint name="right_hand_finger5_joint3" pos="0 0 0" axis="0 0 1"
                                  range="0 1.5708" actuatorfrcrange="-100 100" frictionloss="0.05"
                                  armature="0.001" />
                                <geom pos="0.0075 0 -0.003" quat="0.499998 0.5 -0.5 0.500002"
                                  type="mesh" contype="0" conaffinity="0" group="1" density="0"
                                  rgba="0.768627 0.886275 0.952941 1"
                                  mesh="right_finger_5_intermediate_visual" />
                                <body name="right_finger_5_distal" pos="0.017 0 -0.0005">
                                  <inertial pos="0.005 0 -0.0025" quat="0 0.707107 0 0.707107"
                                    mass="0.000496"
                                    diaginertia="6.77867e-09 5.16667e-09 3.67867e-09" />
                                  <joint name="right_hand_finger5_joint4" pos="0 0 0" axis="0 0 1"
                                    range="0 1.5708" actuatorfrcrange="-100 100" frictionloss="0.05"
                                    armature="0.001" />
                                  <geom pos="0.005 0 -0.0025" quat="0.499998 0.5 -0.5 0.500002"
                                    type="mesh" contype="0" conaffinity="0" group="1" density="0"
                                    rgba="0.972549 0.529412 0.00392157 1"
                                    mesh="right_finger_5_distal_visual" />
                                </body>
                              </body>
                            </body>
                          </body>
                        </body>
                      </body>
                    </body>
                  </body>
                </body>
              </body>
            </body>
            <body name="neck_yaw" pos="0 -0.21948 -0.025" quat="0.707105 0.707108 0 0">
              <inertial pos="0 0 0.03" quat="0.707107 0.707107 0 0" mass="0.0779115"
                diaginertia="2.40227e-05 2.40227e-05 1.55823e-05" />
              <joint name="neck_yaw" pos="0 0 0" axis="0 0 1" range="-0.785398 0.785398"
                actuatorfrcrange="-100 100" frictionloss="0.1" armature="0.01" />
              <geom pos="0 0 0.03" quat="0.707105 0 0 0.707108" type="mesh" contype="0"
                conaffinity="0" group="1" density="0" rgba="0.647059 0.647059 0.647059 1"
                mesh="neck_yaw_visual" />
              <body name="neck_roll" pos="0 0.025 0.03" quat="0.707105 -0.707108 0 0">
                <inertial pos="0 -0.05 -0.035" quat="0.5 0.5 0.5 0.5" mass="0.0779115"
                  diaginertia="2.40227e-05 2.40227e-05 1.55823e-05" />
                <joint name="neck_roll" pos="0 0 0" axis="0 0 1" range="-0.523599 0.523599"
                  actuatorfrcrange="-100 100" frictionloss="0.1" armature="0.01" />
                <geom pos="0 -0.05 -0.035" quat="0.499998 0.5 -0.5 0.500002" type="mesh" contype="0"
                  conaffinity="0" group="1" density="0" rgba="0.231373 0.380392 0.705882 1"
                  mesh="neck_roll_visual" />
                <body name="head" pos="0.025 -0.05 -0.035"
                  quat="9.38184e-07 0.707105 -9.38187e-07 0.707108">
                  <inertial pos="0.01 0.06133 -0.025" quat="0.707107 0.707107 0 0" mass="4.73312"
                    diaginertia="0.018942 0.018942 0.0161021" />
                  <joint name="neck_pitch" pos="0 0 0" axis="0 0 1" range="-0.523599 0.523599"
                    actuatorfrcrange="-100 100" frictionloss="0.1" armature="0.01" />
                  <geom pos="0.01 0.06133 -0.025" quat="0.707105 -0.707108 0 0" type="mesh"
                    contype="0" conaffinity="0" group="1" density="0"
                    rgba="0.917647 0.917647 0.917647 1" mesh="head_visual" />
                </body>
              </body>
            </body>
          </body>
        </body>
      </body>
    </body>
  </worldbody>
  <actuator>
    <motor name="left_hip_pitch" joint="left_hip_pitch" forcerange="-10 10" />
    <motor name="left_hip_roll" joint="left_hip_roll" forcerange="-10 10" />
    <motor name="left_hip_yaw" joint="left_hip_yaw" forcerange="-10 10" />
    <motor name="left_knee_pitch" joint="left_knee_pitch" forcerange="-10 10" />
    <motor name="left_ankle_yaw" joint="left_ankle_yaw" forcerange="-10 10" />
    <motor name="left_ankle_roll" joint="left_ankle_roll" forcerange="-10 10" />
    <motor name="left_ankle_pitch" joint="left_ankle_pitch" forcerange="-10 10" />
    <motor name="right_hip_pitch" joint="right_hip_pitch" forcerange="-10 10" />
    <motor name="right_hip_roll" joint="right_hip_roll" forcerange="-10 10" />
    <motor name="right_hip_yaw" joint="right_hip_yaw" forcerange="-10 10" />
    <motor name="right_knee_pitch" joint="right_knee_pitch" forcerange="-10 10" />
    <motor name="right_ankle_yaw" joint="right_ankle_yaw" forcerange="-10 10" />
    <motor name="right_ankle_roll" joint="right_ankle_roll" forcerange="-10 10" />
    <motor name="right_ankle_pitch" joint="right_ankle_pitch" forcerange="-10 10" />
    <motor name="waist_yaw" joint="waist_yaw" forcerange="-10 10" />
    <motor name="waist_pitch" joint="waist_pitch" forcerange="-10 10" />
    <motor name="waist_roll" joint="waist_roll" forcerange="-10 10" />
    <motor name="left_shoulder_pitch" joint="left_shoulder_pitch" forcerange="-10 10" />
    <motor name="left_shoulder_roll" joint="left_shoulder_roll" forcerange="-10 10" />
    <motor name="left_shoulder_yaw" joint="left_shoulder_yaw" forcerange="-10 10" />
    <motor name="left_elbow_pitch" joint="left_elbow_pitch" forcerange="-10 10" />
    <motor name="left_wrist_yaw" joint="left_wrist_yaw" forcerange="-10 10" />
    <motor name="left_wrist_roll" joint="left_wrist_roll" forcerange="-10 10" />
    <motor name="left_wrist_pitch" joint="left_wrist_pitch" forcerange="-10 10" />
    <motor name="left_hand_finger1_joint1" joint="left_hand_finger1_joint1" forcerange="-10 10" />
    <motor name="left_hand_finger1_joint2" joint="left_hand_finger1_joint2" forcerange="-10 10" />
    <motor name="left_hand_finger1_joint3" joint="left_hand_finger1_joint3" forcerange="-10 10" />
    <motor name="left_hand_finger1_joint4" joint="left_hand_finger1_joint4" forcerange="-10 10" />
    <motor name="left_hand_finger2_joint1" joint="left_hand_finger2_joint1" forcerange="-10 10" />
    <motor name="left_hand_finger2_joint2" joint="left_hand_finger2_joint2" forcerange="-10 10" />
    <motor name="left_hand_finger2_joint3" joint="left_hand_finger2_joint3" forcerange="-10 10" />
    <motor name="left_hand_finger2_joint4" joint="left_hand_finger2_joint4" forcerange="-10 10" />
    <motor name="left_hand_finger3_joint1" joint="left_hand_finger3_joint1" forcerange="-10 10" />
    <motor name="left_hand_finger3_joint2" joint="left_hand_finger3_joint2" forcerange="-10 10" />
    <motor name="left_hand_finger3_joint3" joint="left_hand_finger3_joint3" forcerange="-10 10" />
    <motor name="left_hand_finger3_joint4" joint="left_hand_finger3_joint4" forcerange="-10 10" />
    <motor name="left_hand_finger4_joint1" joint="left_hand_finger4_joint1" forcerange="-10 10" />
    <motor name="left_hand_finger4_joint2" joint="left_hand_finger4_joint2" forcerange="-10 10" />
    <motor name="left_hand_finger4_joint3" joint="left_hand_finger4_joint3" forcerange="-10 10" />
    <motor name="left_hand_finger4_joint4" joint="left_hand_finger4_joint4" forcerange="-10 10" />
    <motor name="left_hand_finger5_joint1" joint="left_hand_finger5_joint1" forcerange="-10 10" />
    <motor name="left_hand_finger5_joint2" joint="left_hand_finger5_joint2" forcerange="-10 10" />
    <motor name="left_hand_finger5_joint3" joint="left_hand_finger5_joint3" forcerange="-10 10" />
    <motor name="left_hand_finger5_joint4" joint="left_hand_finger5_joint4" forcerange="-10 10" />
    <motor name="right_shoulder_pitch" joint="right_shoulder_pitch" forcerange="-10 10" />
    <motor name="right_shoulder_roll" joint="right_shoulder_roll" forcerange="-10 10" />
    <motor name="right_shoulder_yaw" joint="right_shoulder_yaw" forcerange="-10 10" />
    <motor name="right_elbow_pitch" joint="right_elbow_pitch" forcerange="-10 10" />
    <motor name="right_wrist_yaw" joint="right_wrist_yaw" forcerange="-10 10" />
    <motor name="right_wrist_roll" joint="right_wrist_roll" forcerange="-10 10" />
    <motor name="right_wrist_pitch" joint="right_wrist_pitch" forcerange="-10 10" />
    <motor name="right_hand_finger1_joint1" joint="right_hand_finger1_joint1" forcerange="-10 10" />
    <motor name="right_hand_finger1_joint2" joint="right_hand_finger1_joint2" forcerange="-10 10" />
    <motor name="right_hand_finger1_joint3" joint="right_hand_finger1_joint3" forcerange="-10 10" />
    <motor name="right_hand_finger1_joint4" joint="right_hand_finger1_joint4" forcerange="-10 10" />
    <motor name="right_hand_finger2_joint1" joint="right_hand_finger2_joint1" forcerange="-10 10" />
    <motor name="right_hand_finger2_joint2" joint="right_hand_finger2_joint2" forcerange="-10 10" />
    <motor name="right_hand_finger2_joint3" joint="right_hand_finger2_joint3" forcerange="-10 10" />
    <motor name="right_hand_finger2_joint4" joint="right_hand_finger2_joint4" forcerange="-10 10" />
    <motor name="right_hand_finger3_joint1" joint="right_hand_finger3_joint1" forcerange="-10 10" />
    <motor name="right_hand_finger3_joint2" joint="right_hand_finger3_joint2" forcerange="-10 10" />
    <motor name="right_hand_finger3_joint3" joint="right_hand_finger3_joint3" forcerange="-10 10" />
    <motor name="right_hand_finger3_joint4" joint="right_hand_finger3_joint4" forcerange="-10 10" />
    <motor name="right_hand_finger4_joint1" joint="right_hand_finger4_joint1" forcerange="-10 10" />
    <motor name="right_hand_finger4_joint2" joint="right_hand_finger4_joint2" forcerange="-10 10" />
    <motor name="right_hand_finger4_joint3" joint="right_hand_finger4_joint3" forcerange="-10 10" />
    <motor name="right_hand_finger4_joint4" joint="right_hand_finger4_joint4" forcerange="-10 10" />
    <motor name="right_hand_finger5_joint1" joint="right_hand_finger5_joint1" forcerange="-10 10" />
    <motor name="right_hand_finger5_joint2" joint="right_hand_finger5_joint2" forcerange="-10 10" />
    <motor name="right_hand_finger5_joint3" joint="right_hand_finger5_joint3" forcerange="-10 10" />
    <motor name="right_hand_finger5_joint4" joint="right_hand_finger5_joint4" forcerange="-10 10" />
    <motor name="neck_yaw" joint="neck_yaw" forcerange="-10 10" />
    <motor name="neck_roll" joint="neck_roll" forcerange="-10 10" />
    <motor name="neck_pitch" joint="neck_pitch" forcerange="-10 10" />
  </actuator>
  <sensor>
    <jointpos name="left_hip_pitch_pos" joint="left_hip_pitch" />
    <jointpos name="left_hip_roll_pos" joint="left_hip_roll" />
    <jointpos name="left_hip_yaw_pos" joint="left_hip_yaw" />
    <jointpos name="left_knee_pitch_pos" joint="left_knee_pitch" />
    <jointpos name="left_ankle_yaw_pos" joint="left_ankle_yaw" />
    <jointpos name="left_ankle_roll_pos" joint="left_ankle_roll" />
    <jointpos name="left_ankle_pitch_pos" joint="left_ankle_pitch" />
    <jointpos name="right_hip_pitch_pos" joint="right_hip_pitch" />
    <jointpos name="right_hip_roll_pos" joint="right_hip_roll" />
    <jointpos name="right_hip_yaw_pos" joint="right_hip_yaw" />
    <jointpos name="right_knee_pitch_pos" joint="right_knee_pitch" />
    <jointpos name="right_ankle_yaw_pos" joint="right_ankle_yaw" />
    <jointpos name="right_ankle_roll_pos" joint="right_ankle_roll" />
    <jointpos name="right_ankle_pitch_pos" joint="right_ankle_pitch" />
    <jointpos name="waist_yaw_pos" joint="waist_yaw" />
    <jointpos name="waist_pitch_pos" joint="waist_pitch" />
    <jointpos name="waist_roll_pos" joint="waist_roll" />
    <jointpos name="left_shoulder_pitch_pos" joint="left_shoulder_pitch" />
    <jointpos name="left_shoulder_roll_pos" joint="left_shoulder_roll" />
    <jointpos name="left_shoulder_yaw_pos" joint="left_shoulder_yaw" />
    <jointpos name="left_elbow_pitch_pos" joint="left_elbow_pitch" />
    <jointpos name="left_wrist_yaw_pos" joint="left_wrist_yaw" />
    <jointpos name="left_wrist_roll_pos" joint="left_wrist_roll" />
    <jointpos name="left_wrist_pitch_pos" joint="left_wrist_pitch" />
    <jointpos name="left_hand_finger1_joint1_pos" joint="left_hand_finger1_joint1" />
    <jointpos name="left_hand_finger1_joint2_pos" joint="left_hand_finger1_joint2" />
    <jointpos name="left_hand_finger1_joint3_pos" joint="left_hand_finger1_joint3" />
    <jointpos name="left_hand_finger1_joint4_pos" joint="left_hand_finger1_joint4" />
    <jointpos name="left_hand_finger2_joint1_pos" joint="left_hand_finger2_joint1" />
    <jointpos name="left_hand_finger2_joint2_pos" joint="left_hand_finger2_joint2" />
    <jointpos name="left_hand_finger2_joint3_pos" joint="left_hand_finger2_joint3" />
    <jointpos name="left_hand_finger2_joint4_pos" joint="left_hand_finger2_joint4" />
    <jointpos name="left_hand_finger3_joint1_pos" joint="left_hand_finger3_joint1" />
    <jointpos name="left_hand_finger3_joint2_pos" joint="left_hand_finger3_joint2" />
    <jointpos name="left_hand_finger3_joint3_pos" joint="left_hand_finger3_joint3" />
    <jointpos name="left_hand_finger3_joint4_pos" joint="left_hand_finger3_joint4" />
    <jointpos name="left_hand_finger4_joint1_pos" joint="left_hand_finger4_joint1" />
    <jointpos name="left_hand_finger4_joint2_pos" joint="left_hand_finger4_joint2" />
    <jointpos name="left_hand_finger4_joint3_pos" joint="left_hand_finger4_joint3" />
    <jointpos name="left_hand_finger4_joint4_pos" joint="left_hand_finger4_joint4" />
    <jointpos name="left_hand_finger5_joint1_pos" joint="left_hand_finger5_joint1" />
    <jointpos name="left_hand_finger5_joint2_pos" joint="left_hand_finger5_joint2" />
    <jointpos name="left_hand_finger5_joint3_pos" joint="left_hand_finger5_joint3" />
    <jointpos name="left_hand_finger5_joint4_pos" joint="left_hand_finger5_joint4" />
    <jointpos name="right_shoulder_pitch_pos" joint="right_shoulder_pitch" />
    <jointpos name="right_shoulder_roll_pos" joint="right_shoulder_roll" />
    <jointpos name="right_shoulder_yaw_pos" joint="right_shoulder_yaw" />
    <jointpos name="right_elbow_pitch_pos" joint="right_elbow_pitch" />
    <jointpos name="right_wrist_yaw_pos" joint="right_wrist_yaw" />
    <jointpos name="right_wrist_roll_pos" joint="right_wrist_roll" />
    <jointpos name="right_wrist_pitch_pos" joint="right_wrist_pitch" />
    <jointpos name="right_hand_finger1_joint1_pos" joint="right_hand_finger1_joint1" />
    <jointpos name="right_hand_finger1_joint2_pos" joint="right_hand_finger1_joint2" />
    <jointpos name="right_hand_finger1_joint3_pos" joint="right_hand_finger1_joint3" />
    <jointpos name="right_hand_finger1_joint4_pos" joint="right_hand_finger1_joint4" />
    <jointpos name="right_hand_finger2_joint1_pos" joint="right_hand_finger2_joint1" />
    <jointpos name="right_hand_finger2_joint2_pos" joint="right_hand_finger2_joint2" />
    <jointpos name="right_hand_finger2_joint3_pos" joint="right_hand_finger2_joint3" />
    <jointpos name="right_hand_finger2_joint4_pos" joint="right_hand_finger2_joint4" />
    <jointpos name="right_hand_finger3_joint1_pos" joint="right_hand_finger3_joint1" />
    <jointpos name="right_hand_finger3_joint2_pos" joint="right_hand_finger3_joint2" />
    <jointpos name="right_hand_finger3_joint3_pos" joint="right_hand_finger3_joint3" />
    <jointpos name="right_hand_finger3_joint4_pos" joint="right_hand_finger3_joint4" />
    <jointpos name="right_hand_finger4_joint1_pos" joint="right_hand_finger4_joint1" />
    <jointpos name="right_hand_finger4_joint2_pos" joint="right_hand_finger4_joint2" />
    <jointpos name="right_hand_finger4_joint3_pos" joint="right_hand_finger4_joint3" />
    <jointpos name="right_hand_finger4_joint4_pos" joint="right_hand_finger4_joint4" />
    <jointpos name="right_hand_finger5_joint1_pos" joint="right_hand_finger5_joint1" />
    <jointpos name="right_hand_finger5_joint2_pos" joint="right_hand_finger5_joint2" />
    <jointpos name="right_hand_finger5_joint3_pos" joint="right_hand_finger5_joint3" />
    <jointpos name="right_hand_finger5_joint4_pos" joint="right_hand_finger5_joint4" />
    <jointpos name="neck_yaw_pos" joint="neck_yaw" />
    <jointpos name="neck_roll_pos" joint="neck_roll" />
    <jointpos name="neck_pitch_pos" joint="neck_pitch" />
    <jointvel name="left_hip_pitch_vel" joint="left_hip_pitch" />
    <jointvel name="left_hip_roll_vel" joint="left_hip_roll" />
    <jointvel name="left_hip_yaw_vel" joint="left_hip_yaw" />
    <jointvel name="left_knee_pitch_vel" joint="left_knee_pitch" />
    <jointvel name="left_ankle_yaw_vel" joint="left_ankle_yaw" />
    <jointvel name="left_ankle_roll_vel" joint="left_ankle_roll" />
    <jointvel name="left_ankle_pitch_vel" joint="left_ankle_pitch" />
    <jointvel name="right_hip_pitch_vel" joint="right_hip_pitch" />
    <jointvel name="right_hip_roll_vel" joint="right_hip_roll" />
    <jointvel name="right_hip_yaw_vel" joint="right_hip_yaw" />
    <jointvel name="right_knee_pitch_vel" joint="right_knee_pitch" />
    <jointvel name="right_ankle_yaw_vel" joint="right_ankle_yaw" />
    <jointvel name="right_ankle_roll_vel" joint="right_ankle_roll" />
    <jointvel name="right_ankle_pitch_vel" joint="right_ankle_pitch" />
    <jointvel name="waist_yaw_vel" joint="waist_yaw" />
    <jointvel name="waist_pitch_vel" joint="waist_pitch" />
    <jointvel name="waist_roll_vel" joint="waist_roll" />
    <jointvel name="left_shoulder_pitch_vel" joint="left_shoulder_pitch" />
    <jointvel name="left_shoulder_roll_vel" joint="left_shoulder_roll" />
    <jointvel name="left_shoulder_yaw_vel" joint="left_shoulder_yaw" />
    <jointvel name="left_elbow_pitch_vel" joint="left_elbow_pitch" />
    <jointvel name="left_wrist_yaw_vel" joint="left_wrist_yaw" />
    <jointvel name="left_wrist_roll_vel" joint="left_wrist_roll" />
    <jointvel name="left_wrist_pitch_vel" joint="left_wrist_pitch" />
    <jointvel name="left_hand_finger1_joint1_vel" joint="left_hand_finger1_joint1" />
    <jointvel name="left_hand_finger1_joint2_vel" joint="left_hand_finger1_joint2" />
    <jointvel name="left_hand_finger1_joint3_vel" joint="left_hand_finger1_joint3" />
    <jointvel name="left_hand_finger1_joint4_vel" joint="left_hand_finger1_joint4" />
    <jointvel name="left_hand_finger2_joint1_vel" joint="left_hand_finger2_joint1" />
    <jointvel name="left_hand_finger2_joint2_vel" joint="left_hand_finger2_joint2" />
    <jointvel name="left_hand_finger2_joint3_vel" joint="left_hand_finger2_joint3" />
    <jointvel name="left_hand_finger2_joint4_vel" joint="left_hand_finger2_joint4" />
    <jointvel name="left_hand_finger3_joint1_vel" joint="left_hand_finger3_joint1" />
    <jointvel name="left_hand_finger3_joint2_vel" joint="left_hand_finger3_joint2" />
    <jointvel name="left_hand_finger3_joint3_vel" joint="left_hand_finger3_joint3" />
    <jointvel name="left_hand_finger3_joint4_vel" joint="left_hand_finger3_joint4" />
    <jointvel name="left_hand_finger4_joint1_vel" joint="left_hand_finger4_joint1" />
    <jointvel name="left_hand_finger4_joint2_vel" joint="left_hand_finger4_joint2" />
    <jointvel name="left_hand_finger4_joint3_vel" joint="left_hand_finger4_joint3" />
    <jointvel name="left_hand_finger4_joint4_vel" joint="left_hand_finger4_joint4" />
    <jointvel name="left_hand_finger5_joint1_vel" joint="left_hand_finger5_joint1" />
    <jointvel name="left_hand_finger5_joint2_vel" joint="left_hand_finger5_joint2" />
    <jointvel name="left_hand_finger5_joint3_vel" joint="left_hand_finger5_joint3" />
    <jointvel name="left_hand_finger5_joint4_vel" joint="left_hand_finger5_joint4" />
    <jointvel name="right_shoulder_pitch_vel" joint="right_shoulder_pitch" />
    <jointvel name="right_shoulder_roll_vel" joint="right_shoulder_roll" />
    <jointvel name="right_shoulder_yaw_vel" joint="right_shoulder_yaw" />
    <jointvel name="right_elbow_pitch_vel" joint="right_elbow_pitch" />
    <jointvel name="right_wrist_yaw_vel" joint="right_wrist_yaw" />
    <jointvel name="right_wrist_roll_vel" joint="right_wrist_roll" />
    <jointvel name="right_wrist_pitch_vel" joint="right_wrist_pitch" />
    <jointvel name="right_hand_finger1_joint1_vel" joint="right_hand_finger1_joint1" />
    <jointvel name="right_hand_finger1_joint2_vel" joint="right_hand_finger1_joint2" />
    <jointvel name="right_hand_finger1_joint3_vel" joint="right_hand_finger1_joint3" />
    <jointvel name="right_hand_finger1_joint4_vel" joint="right_hand_finger1_joint4" />
    <jointvel name="right_hand_finger2_joint1_vel" joint="right_hand_finger2_joint1" />
    <jointvel name="right_hand_finger2_joint2_vel" joint="right_hand_finger2_joint2" />
    <jointvel name="right_hand_finger2_joint3_vel" joint="right_hand_finger2_joint3" />
    <jointvel name="right_hand_finger2_joint4_vel" joint="right_hand_finger2_joint4" />
    <jointvel name="right_hand_finger3_joint1_vel" joint="right_hand_finger3_joint1" />
    <jointvel name="right_hand_finger3_joint2_vel" joint="right_hand_finger3_joint2" />
    <jointvel name="right_hand_finger3_joint3_vel" joint="right_hand_finger3_joint3" />
    <jointvel name="right_hand_finger3_joint4_vel" joint="right_hand_finger3_joint4" />
    <jointvel name="right_hand_finger4_joint1_vel" joint="right_hand_finger4_joint1" />
    <jointvel name="right_hand_finger4_joint2_vel" joint="right_hand_finger4_joint2" />
    <jointvel name="right_hand_finger4_joint3_vel" joint="right_hand_finger4_joint3" />
    <jointvel name="right_hand_finger4_joint4_vel" joint="right_hand_finger4_joint4" />
    <jointvel name="right_hand_finger5_joint1_vel" joint="right_hand_finger5_joint1" />
    <jointvel name="right_hand_finger5_joint2_vel" joint="right_hand_finger5_joint2" />
    <jointvel name="right_hand_finger5_joint3_vel" joint="right_hand_finger5_joint3" />
    <jointvel name="right_hand_finger5_joint4_vel" joint="right_hand_finger5_joint4" />
    <jointvel name="neck_yaw_vel" joint="neck_yaw" />
    <jointvel name="neck_roll_vel" joint="neck_roll" />
    <jointvel name="neck_pitch_vel" joint="neck_pitch" />
  </sensor>
</mujoco>