<?xml version='1.0' encoding='utf-8'?>
<mujoco model="lite">
  <compiler angle="radian" meshdir="../meshes/" />

  <asset>
    <mesh name="chest_visual" content_type="model/stl" file="chest_visual.stl" />
    <mesh name="left_shoulder_pitch_visual" content_type="model/stl"
      file="left_shoulder_pitch_visual.stl" />
    <mesh name="left_shoulder_roll_visual" content_type="model/stl"
      file="left_shoulder_roll_visual.stl" />
    <mesh name="left_shoulder_yaw_visual" content_type="model/stl"
      file="left_shoulder_yaw_visual.stl" />
    <mesh name="left_elbow_pitch_visual" content_type="model/stl" file="left_elbow_pitch_visual.stl" />
    <mesh name="left_wrist_yaw_visual" content_type="model/stl" file="left_wrist_yaw_visual.stl" />
    <mesh name="left_wrist_roll_visual" content_type="model/stl" file="left_wrist_roll_visual.stl" />
    <mesh name="left_hand_visual" content_type="model/stl" file="left_hand_visual.stl" />
    <mesh name="right_shoulder_pitch_visual" content_type="model/stl"
      file="right_shoulder_pitch_visual.stl" />
    <mesh name="right_shoulder_roll_visual" content_type="model/stl"
      file="right_shoulder_roll_visual.stl" />
    <mesh name="right_shoulder_yaw_visual" content_type="model/stl"
      file="right_shoulder_yaw_visual.stl" />
    <mesh name="right_elbow_pitch_visual" content_type="model/stl"
      file="right_elbow_pitch_visual.stl" />
    <mesh name="right_wrist_yaw_visual" content_type="model/stl" file="right_wrist_yaw_visual.stl" />
    <mesh name="right_wrist_roll_visual" content_type="model/stl" file="right_wrist_roll_visual.stl" />
    <mesh name="right_hand_visual" content_type="model/stl" file="right_hand_visual.stl" />
    <mesh name="neck_yaw_visual" content_type="model/stl" file="neck_yaw_visual.stl" />
    <mesh name="neck_roll_visual" content_type="model/stl" file="neck_roll_visual.stl" />
    <mesh name="head_visual" content_type="model/stl" file="head_visual.stl" />
  </asset>

  <worldbody>
    <body name="chest">
      <inertial pos="0.0229755 1.89075e-06 0.301247"
        quat="0.995694 2.09409e-05 -0.0926996 -0.00020815" mass="4.241"
        diaginertia="0.0300956 0.0293132 0.00962698" />
      <geom size="0.053 0.08" pos="0.025 0 0.28" quat="0.70256 0.0800467 -0.080047 -0.702563"
        type="capsule" />
      <geom size="0.02 0.04 0.09" pos="0.015 -0.04 0.32"
        quat="0.706863 0.0185097 -0.140975 -0.692913" type="box" />
      <geom size="0.02 0.04 0.09" pos="0.015 0.04 0.32" quat="0.69291 0.140974 -0.0185102 -0.706866"
        type="box" />
      <geom pos="0.0229755 1.89075e-06 0.301247" type="mesh" contype="0" conaffinity="0" group="1"
        density="0" rgba="0.914357 0.926071 0.933099 1" mesh="chest_visual" />
      <body name="left_shoulder_pitch" pos="0 0.09 0.39" quat="0.766046 -0.642786 0 0">
        <inertial pos="-6.27e-10 -0.00168619 -0.00682299"
          quat="0.696279 -0.123273 0.123273 0.696279" mass="0.375"
          diaginertia="0.000238351 0.000232695 0.000194679" />
        <joint name="left_shoulder_pitch" pos="0 0 0" axis="0 0 1" range="-3.14159 0.785398"
          actuatorfrcrange="-100 100" frictionloss="0.1" armature="0.009" />
        <geom pos="-6.27e-10 -0.00168619 -0.00682299" quat="0.766046 0.642786 0 0" type="mesh"
          contype="0" conaffinity="0" group="1" density="0" rgba="0.933333 0.933333 0.933333 1"
          mesh="left_shoulder_pitch_visual" />
        <body name="left_shoulder_roll" quat="0.541674 0.454519 0.541677 0.454519">
          <inertial pos="-2.61641e-06 0.0788959 1.66238e-07"
            quat="0.70711 0.707103 0.000188978 -0.000320556" mass="0.42"
            diaginertia="0.000535525 0.000505367 0.000205463" />
          <joint name="left_shoulder_roll" pos="0 0 0" axis="0 0 1" range="-1.5708 1.91986"
            actuatorfrcrange="-100 100" frictionloss="0.1" armature="0.009" />
          <geom pos="-2.61641e-06 0.0788959 1.66238e-07" quat="0.707105 0 -0.707108 0" type="mesh"
            contype="0" conaffinity="0" group="1" density="0" rgba="0.392063 0.392063 0.392063 1"
            mesh="left_shoulder_roll_visual" />
          <body name="left_shoulder_yaw" pos="0 0.12 0" quat="0.499998 0.5 -0.5 0.500002">
            <inertial pos="0.00515648 -2.4401e-08 -0.0554418"
              quat="0.996479 1.06824e-05 -0.0838439 -0.00012696" mass="0.43"
              diaginertia="0.00050483 0.000501106 0.000213278" />
            <joint name="left_shoulder_yaw" pos="0 0 0" axis="0 0 1" range="-1.5708 1.5708"
              actuatorfrcrange="-100 100" frictionloss="0.1" armature="0.009" />
            <geom size="0.035 0.06" pos="0 0 0.06"
              quat="9.38184e-07 -0.707105 -0.707108 9.38187e-07" type="capsule" />
            <geom pos="0.00515648 -2.4401e-08 -0.0554418" quat="0.707105 -0.707108 0 0" type="mesh"
              contype="0" conaffinity="0" group="1" density="0" rgba="0.933333 0.933333 0.933333 1"
              mesh="left_shoulder_yaw_visual" />
            <body name="left_elbow_pitch" pos="0.01 0 -0.08" quat="0.707105 -0.707108 0 0">
              <inertial pos="-0.00846207 0.0260402 3.13818e-06"
                quat="0.988908 0.000309112 5.70736e-05 0.148529" mass="0.11"
                diaginertia="0.000120399 9.14361e-05 8.0933e-05" />
              <joint name="left_elbow_pitch" pos="0 0 0" axis="0 0 1" range="-2.35619 0"
                actuatorfrcrange="-100 100" frictionloss="0.1" armature="0.009" />
              <geom pos="-0.00846207 0.0260402 3.13818e-06" type="mesh" contype="0" conaffinity="0"
                group="1" density="0" rgba="0.933333 0.933333 0.933333 1"
                mesh="left_elbow_pitch_visual" />
              <body name="left_wrist_yaw" pos="-0.01 0.055 0" quat="0.707105 0.707108 0 0">
                <inertial pos="-2.258e-07 0.000140958 -0.0577988"
                  quat="0.999972 -0.00742817 -3.53484e-07 -4.75856e-05" mass="0.54"
                  diaginertia="0.000826137 0.000817621 0.000268082" />
                <joint name="left_wrist_yaw" pos="0 0 0" axis="0 0 1" range="-1.5708 1.5708"
                  actuatorfrcrange="-100 100" frictionloss="0.1" armature="0.005" />
                <geom size="0.03 0.095" pos="0 0 -0.04" quat="1.32679e-06 0 0 -1" type="capsule" />
                <geom pos="-2.258e-07 0.000140958 -0.0577988" quat="0.707105 -0.707108 0 0"
                  type="mesh" contype="0" conaffinity="0" group="1" density="0"
                  rgba="0.933333 0.933333 0.933333 1" mesh="left_wrist_yaw_visual" />
                <body name="left_wrist_roll" pos="0 0 -0.135" quat="0.707105 -0.707108 0 0">
                  <inertial pos="3.48e-10 1e-12 -2.12e-10"
                    quat="0.500011 0.499989 0.500011 0.499989" mass="0.25"
                    diaginertia="9.19125e-05 9.04076e-05 7.92687e-05" />
                  <joint name="left_wrist_roll" pos="0 0 0" axis="0 0 1" range="-0.698132 0.698132"
                    actuatorfrcrange="-100 100" frictionloss="0.1" armature="0.005" />
                  <geom pos="3.48e-10 0 -2.12e-10" quat="1 0 0 0" type="mesh" contype="0"
                    conaffinity="0" group="1" density="0" rgba="0.933333 0.933333 0.933333 1"
                    mesh="left_wrist_roll_visual" />
                  <body name="left_hand" quat="0.707105 0 0.707108 0">
                    <inertial pos="0.0044138 0.1008 0.00606018"
                      quat="0.656957 0.753902 0.0039914 -0.00473008" mass="0.167493"
                      diaginertia="0.000456313 0.000413603 9.23022e-05" />
                    <joint name="left_wrist_pitch" pos="0 0 0" axis="0 0 1"
                      range="-0.785398 0.785398" actuatorfrcrange="-100 100" frictionloss="0.1"
                      armature="0.005" />
                    <geom size="0.006 0.03" pos="-0.007 0.194 0.0225"
                      quat="0.499998 0.5 0.5 -0.500002" type="capsule" />
                    <geom size="0.035 0.02" pos="0.01 0.1 0.0005" quat="0.499998 0.5 0.5 -0.500002"
                      type="capsule" />
                    <geom pos="0.0044138 0.1008 0.00606018" quat="0.707105 0 -0.707108 0"
                      type="mesh" contype="0" conaffinity="0" group="1" density="0"
                      rgba="0.935303 0.913041 0.886642 1" mesh="left_hand_visual" />
                    <body name="left_finger2_tip" pos="-0.007 0.225 0.0225"
                      quat="0.499998 -0.5 -0.500002 0.5">
                      <inertial pos="0 0 0" mass="1e-09" diaginertia="0 0 0" />
                    </body>
                  </body>
                </body>
              </body>
            </body>
          </body>
        </body>
      </body>
      <body name="right_shoulder_pitch" pos="0 -0.09 0.39" quat="0.642787 -0.766045 0 0">
        <inertial pos="6.27e-10 -0.00168619 0.00682299" quat="0.696279 0.123273 -0.123273 0.696279"
          mass="0.375" diaginertia="0.000238351 0.000232695 0.000194679" />
        <joint name="right_shoulder_pitch" pos="0 0 0" axis="0 0 1" range="-3.14159 0.785398"
          actuatorfrcrange="-100 100" frictionloss="0.1" armature="0.009" />
        <geom pos="6.27e-10 -0.00168619 0.00682299" quat="0.642787 0.766045 0 0" type="mesh"
          contype="0" conaffinity="0" group="1" density="0" rgba="0.933333 0.933333 0.933333 1"
          mesh="right_shoulder_pitch_visual" />
        <body name="right_shoulder_roll" quat="0.541674 -0.454519 0.541677 -0.454519">
          <inertial pos="4.38085e-05 0.0789688 1.65449e-07"
            quat="0.70711 0.707102 -0.000965659 -0.000450389" mass="0.42073"
            diaginertia="0.000536872 0.000507074 0.000205928" />
          <joint name="right_shoulder_roll" pos="0 0 0" axis="0 0 1" range="-1.91986 1.5708"
            actuatorfrcrange="-100 100" frictionloss="0.1" armature="0.009" />
          <geom pos="4.38085e-05 0.0789688 1.65449e-07"
            quat="9.38184e-07 0.707105 -9.38187e-07 0.707108" type="mesh" contype="0"
            conaffinity="0" group="1" density="0" rgba="0.393003 0.393003 0.393003 1"
            mesh="right_shoulder_roll_visual" />
          <body name="right_shoulder_yaw" pos="0 0.12 0" quat="0.499998 0.5 -0.5 0.500002">
            <inertial pos="0.00515641 2.57303e-07 -0.0554411"
              quat="0.996479 -1.3598e-05 -0.0838421 4.79531e-05" mass="0.43"
              diaginertia="0.000504843 0.000501118 0.000213278" />
            <joint name="right_shoulder_yaw" pos="0 0 0" axis="0 0 1" range="-1.5708 1.5708"
              actuatorfrcrange="-100 100" frictionloss="0.1" armature="0.009" />
            <geom size="0.035 0.06" pos="0 0 0.06"
              quat="9.38184e-07 -0.707105 -0.707108 9.38187e-07" type="capsule" />
            <geom pos="0.00515641 2.57303e-07 -0.0554411" quat="0.707105 0.707108 0 0" type="mesh"
              contype="0" conaffinity="0" group="1" density="0" rgba="0.933333 0.933333 0.933333 1"
              mesh="right_shoulder_yaw_visual" />
            <body name="right_elbow_pitch" pos="0.01 0 -0.08" quat="0.707105 -0.707108 0 0">
              <inertial pos="-0.00846033 0.0260389 8.87366e-07"
                quat="0.988903 -0.000149387 -9.75622e-05 0.148563" mass="0.11"
                diaginertia="0.000120407 9.14368e-05 8.0934e-05" />
              <joint name="right_elbow_pitch" pos="0 0 0" axis="0 0 1" range="-2.35619 0"
                actuatorfrcrange="-100 100" frictionloss="0.1" armature="0.009" />
              <geom pos="-0.00846033 0.0260389 8.87366e-07" quat="1.32679e-06 1 0 0" type="mesh"
                contype="0" conaffinity="0" group="1" density="0"
                rgba="0.933333 0.933333 0.933333 1" mesh="right_elbow_pitch_visual" />
              <body name="right_wrist_yaw" pos="-0.01 0.055 0" quat="0.707105 0.707108 0 0">
                <inertial pos="1.36083e-07 0.000140746 -0.0578009"
                  quat="0.999972 -0.0074245 -5.02671e-06 2.15434e-05" mass="0.54"
                  diaginertia="0.000826154 0.000817596 0.000268064" />
                <joint name="right_wrist_yaw" pos="0 0 0" axis="0 0 1" range="-1.5708 1.5708"
                  actuatorfrcrange="-100 100" frictionloss="0.1" armature="0.005" />
                <geom size="0.03 0.095" pos="0 0 -0.04" quat="1.32679e-06 0 0 -1" type="capsule" />
                <geom pos="1.36083e-07 0.000140746 -0.0578009" quat="0.707105 0.707108 0 0"
                  type="mesh" contype="0" conaffinity="0" group="1" density="0"
                  rgba="0.933333 0.933333 0.933333 1" mesh="right_wrist_yaw_visual" />
                <body name="right_wrist_roll" pos="0 0 -0.135" quat="0.707105 -0.707108 0 0">
                  <inertial pos="4.084e-09 -2e-12 -2.02e-10"
                    quat="0.499585 0.500415 0.499585 0.500415" mass="0.25"
                    diaginertia="9.19094e-05 9.04084e-05 7.92688e-05" />
                  <joint name="right_wrist_roll" pos="0 0 0" axis="0 0 1" range="-0.698132 0.698132"
                    actuatorfrcrange="-100 100" frictionloss="0.1" armature="0.005" />
                  <geom pos="4.084e-09 -2e-12 -2.02e-10" quat="1.32679e-06 1 0 0" type="mesh"
                    contype="0" conaffinity="0" group="1" density="0"
                    rgba="0.933333 0.933333 0.933333 1" mesh="right_wrist_roll_visual" />
                  <body name="right_hand" quat="0.707105 0 0.707108 0">
                    <inertial pos="-0.00441379 0.100801 0.0060602"
                      quat="0.656957 0.753902 -0.0039883 0.0047276" mass="0.167493"
                      diaginertia="0.000456312 0.000413602 9.23024e-05" />
                    <joint name="right_wrist_pitch" pos="0 0 0" axis="0 0 1"
                      range="-0.785398 0.785398" actuatorfrcrange="-100 100" frictionloss="0.1"
                      armature="0.005" />
                    <geom size="0.006 0.03" pos="0.007 0.194 0.0225"
                      quat="0.499998 0.5 -0.5 0.500002" type="capsule" />
                    <geom size="0.035 0.02" pos="-0.01 0.1 0.0005" quat="0.499998 0.5 -0.5 0.500002"
                      type="capsule" />
                    <geom pos="-0.00441379 0.100801 0.0060602"
                      quat="9.38184e-07 0.707105 -9.38187e-07 0.707108" type="mesh" contype="0"
                      conaffinity="0" group="1" density="0" rgba="0.935303 0.913041 0.886642 1"
                      mesh="right_hand_visual" />
                    <body name="right_finger2_tip" pos="0.007 0.225 0.0225"
                      quat="0.499998 0.5 0.500002 0.5">
                      <inertial pos="0 0 0" mass="1e-09" diaginertia="0 0 0" />
                    </body>
                  </body>
                </body>
              </body>
            </body>
          </body>
        </body>
      </body>
      <body name="neck_yaw" pos="-0.01 0 0.45">
        <inertial pos="0 0 0.03" quat="0.5 0.5 0.5 0.5" mass="0.0779115"
          diaginertia="2.40227e-05 2.40227e-05 1.55823e-05" />
        <joint name="neck_yaw" pos="0 0 0" axis="0 0 1" range="-0.785398 0.785398"
          actuatorfrcrange="-100 100" frictionloss="0.2" armature="0.01" />
        <geom pos="0 0 0.03" quat="1 0 0 0" type="mesh" contype="0" conaffinity="0" group="1"
          density="0" rgba="0.933333 0.933333 0.933333 1" mesh="neck_yaw_visual" />
        <body name="neck_roll" pos="0 0 0.03" quat="0.499998 0.5 0.500002 0.5">
          <inertial pos="0 0.03 0" quat="0.5 0.5 0.5 0.5" mass="0.0779115"
            diaginertia="2.40227e-05 2.40227e-05 1.55823e-05" />
          <joint name="neck_roll" pos="0 0 0" axis="0 0 1" range="-0.523599 0.523599"
            actuatorfrcrange="-100 100" frictionloss="0.2" armature="0.01" />
          <geom pos="0 0.03 0" quat="0.499998 -0.5 -0.5 -0.500002" type="mesh" contype="0"
            conaffinity="0" group="1" density="0" rgba="0.933333 0.933333 0.933333 1"
            mesh="neck_roll_visual" />
          <body name="head" pos="0 0.03 0" quat="0.707105 0 0.707108 0">
            <inertial pos="0.00134973 0.0584846 -5.43e-10"
              quat="0.589743 0.390132 -0.589743 0.390132" mass="4.7098"
              diaginertia="0.0201095 0.0200477 0.0150257" />
            <joint name="neck_pitch" pos="0 0 0" axis="0 0 1" range="-0.523599 0.523599"
              actuatorfrcrange="-100 100" frictionloss="0.2" armature="0.01" />
            <geom size="0.09 0.015" pos="0 0.05 0" quat="0.499998 -0.5 -0.5 -0.500002"
              type="capsule" />
            <geom pos="0.00134973 0.0584846 -5.43e-10"
              quat="9.38184e-07 9.38187e-07 -0.707108 -0.707105" type="mesh" contype="0"
              conaffinity="0" group="1" density="0" rgba="0.933333 0.933333 0.933333 1"
              mesh="head_visual" />
          </body>
        </body>
      </body>
    </body>
  </worldbody>
  <actuator>
    <motor name="left_shoulder_pitch" joint="left_shoulder_pitch" forcerange="-17 17" />
    <motor name="left_shoulder_roll" joint="left_shoulder_roll" forcerange="-14 14" />
    <motor name="left_shoulder_yaw" joint="left_shoulder_yaw" forcerange="-14 14" />
    <motor name="left_elbow_pitch" joint="left_elbow_pitch" forcerange="-14 14" />
    <motor name="left_wrist_yaw" joint="left_wrist_yaw" forcerange="-5.5 5.5" />
    <motor name="left_wrist_roll" joint="left_wrist_roll" forcerange="-5.5 5.5" />
    <motor name="left_wrist_pitch" joint="left_wrist_pitch" forcerange="-5.5 5.5" />
    <motor name="right_shoulder_pitch" joint="right_shoulder_pitch" forcerange="-17 17" />
    <motor name="right_shoulder_roll" joint="right_shoulder_roll" forcerange="-14 14" />
    <motor name="right_shoulder_yaw" joint="right_shoulder_yaw" forcerange="-14 14" />
    <motor name="right_elbow_pitch" joint="right_elbow_pitch" forcerange="-14 14" />
    <motor name="right_wrist_yaw" joint="right_wrist_yaw" forcerange="-5.5 5.5" />
    <motor name="right_wrist_roll" joint="right_wrist_roll" forcerange="-5.5 5.5" />
    <motor name="right_wrist_pitch" joint="right_wrist_pitch" forcerange="-5.5 5.5" />
    <motor name="neck_yaw" joint="neck_yaw" forcerange="-10 10" />
    <motor name="neck_roll" joint="neck_roll" forcerange="-10 10" />
    <motor name="neck_pitch" joint="neck_pitch" forcerange="-10 10" />
  </actuator>
  <sensor>
    <jointpos name="left_shoulder_pitch_pos" joint="left_shoulder_pitch" />
    <jointpos name="left_shoulder_roll_pos" joint="left_shoulder_roll" />
    <jointpos name="left_shoulder_yaw_pos" joint="left_shoulder_yaw" />
    <jointpos name="left_elbow_pitch_pos" joint="left_elbow_pitch" />
    <jointpos name="left_wrist_yaw_pos" joint="left_wrist_yaw" />
    <jointpos name="left_wrist_roll_pos" joint="left_wrist_roll" />
    <jointpos name="left_wrist_pitch_pos" joint="left_wrist_pitch" />
    <jointpos name="right_shoulder_pitch_pos" joint="right_shoulder_pitch" />
    <jointpos name="right_shoulder_roll_pos" joint="right_shoulder_roll" />
    <jointpos name="right_shoulder_yaw_pos" joint="right_shoulder_yaw" />
    <jointpos name="right_elbow_pitch_pos" joint="right_elbow_pitch" />
    <jointpos name="right_wrist_yaw_pos" joint="right_wrist_yaw" />
    <jointpos name="right_wrist_roll_pos" joint="right_wrist_roll" />
    <jointpos name="right_wrist_pitch_pos" joint="right_wrist_pitch" />
    <jointpos name="neck_yaw_pos" joint="neck_yaw" />
    <jointpos name="neck_roll_pos" joint="neck_roll" />
    <jointpos name="neck_pitch_pos" joint="neck_pitch" />
    <jointvel name="left_shoulder_pitch_vel" joint="left_shoulder_pitch" />
    <jointvel name="left_shoulder_roll_vel" joint="left_shoulder_roll" />
    <jointvel name="left_shoulder_yaw_vel" joint="left_shoulder_yaw" />
    <jointvel name="left_elbow_pitch_vel" joint="left_elbow_pitch" />
    <jointvel name="left_wrist_yaw_vel" joint="left_wrist_yaw" />
    <jointvel name="left_wrist_roll_vel" joint="left_wrist_roll" />
    <jointvel name="left_wrist_pitch_vel" joint="left_wrist_pitch" />
    <jointvel name="right_shoulder_pitch_vel" joint="right_shoulder_pitch" />
    <jointvel name="right_shoulder_roll_vel" joint="right_shoulder_roll" />
    <jointvel name="right_shoulder_yaw_vel" joint="right_shoulder_yaw" />
    <jointvel name="right_elbow_pitch_vel" joint="right_elbow_pitch" />
    <jointvel name="right_wrist_yaw_vel" joint="right_wrist_yaw" />
    <jointvel name="right_wrist_roll_vel" joint="right_wrist_roll" />
    <jointvel name="right_wrist_pitch_vel" joint="right_wrist_pitch" />
    <jointvel name="neck_yaw_vel" joint="neck_yaw" />
    <jointvel name="neck_roll_vel" joint="neck_roll" />
    <jointvel name="neck_pitch_vel" joint="neck_pitch" />
  </sensor>
</mujoco>