<?xml version="1.0" ?>
<!-- Generated using onshape-to-robot -->
<!-- Onshape document_id: e9ee61a2e2678af2088d9f31 -->
<robot name="miku">
  <!-- Link pelvis -->
  <link name="pelvis">
    <inertial>
      <origin xyz="8.977e-09 -0 0.00186483" rpy="0 0 0"/>
      <mass value="1.63184"/>
      <inertia ixx="0.00445142" ixy="4.71e-10" ixz="-1.682e-09" iyy="0.00217002" iyz="0" izz="0.00442459"/>
    </inertial>
    <!-- Part pelvis_parts -->
    <collision>
      <origin xyz="0 0 0.05" rpy="0 -0 -1.5708"/>
      <geometry>
        <cylinder length="0.1" radius="0.05"/>
      </geometry>
    </collision>
    <collision>
      <origin xyz="0 0 0" rpy="1.5708 1.5708 0"/>
      <geometry>
        <cylinder length="0.16" radius="0.05"/>
      </geometry>
    </collision>
    <visual>
      <origin xyz="8.977e-09 -0 0.00186483" rpy="0 -0 0"/>
      <geometry>
        <mesh filename="../meshes/pelvis_visual.stl"/>
      </geometry>
      <material name="pelvis_parts_material">
        <color rgba="0.615686 0.811765 0.929412 1"/>
      </material>
    </visual>
  </link>
  <!-- Link left_hip_pitch -->
  <link name="left_hip_pitch">
    <inertial>
      <origin xyz="-0.08 -0 -0" rpy="0 0 0"/>
      <mass value="0.486947"/>
      <inertia ixx="0.000608684" ixy="0" ixz="-0" iyy="0.000405789" iyz="0" izz="0.000405789"/>
    </inertial>
    <!-- Part left_hip_pitch_parts -->
    <visual>
      <origin xyz="-0.08 -0 0" rpy="1.5708 0 0"/>
      <geometry>
        <mesh filename="../meshes/left_hip_pitch_visual.stl"/>
      </geometry>
      <material name="left_hip_pitch_parts_material">
        <color rgba="0.647059 0.647059 0.647059 1"/>
      </material>
    </visual>
  </link>
  <!-- Link left_hip_roll -->
  <link name="left_hip_roll">
    <inertial>
      <origin xyz="0 0.21 -0" rpy="0 0 0"/>
      <mass value="3.11646"/>
      <inertia ixx="0.0285416" ixy="-0" ixz="0" iyy="0.00389557" iyz="0" izz="0.0285416"/>
    </inertial>
    <!-- Part left_hip_roll_parts -->
    <collision>
      <origin xyz="0 0.21 -0" rpy="1.5708 -0 -0"/>
      <geometry>
        <cylinder length="0.2" radius="0.05"/>
      </geometry>
    </collision>
    <visual>
      <origin xyz="0 0.21 -0" rpy="1.5708 -1.5708 0"/>
      <geometry>
        <mesh filename="../meshes/left_hip_roll_visual.stl"/>
      </geometry>
      <material name="left_hip_roll_parts_material">
        <color rgba="0.231373 0.380392 0.705882 1"/>
      </material>
    </visual>
  </link>
  <!-- Link left_hip_yaw -->
  <link name="left_hip_yaw">
    <inertial>
      <origin xyz="-0 -0 -0.42" rpy="0 0 0"/>
      <mass value="0.486947"/>
      <inertia ixx="0.000405789" ixy="0" ixz="-0" iyy="0.000608684" iyz="-0" izz="0.000405789"/>
    </inertial>
    <!-- Part left_hip_yaw_parts -->
    <visual>
      <origin xyz="-0 -0 -0.42" rpy="0 -0 0"/>
      <geometry>
        <mesh filename="../meshes/left_hip_yaw_visual.stl"/>
      </geometry>
      <material name="left_hip_yaw_parts_material">
        <color rgba="0.917647 0.917647 0.917647 1"/>
      </material>
    </visual>
  </link>
  <!-- Link left_knee_pitch -->
  <link name="left_knee_pitch">
    <inertial>
      <origin xyz="0 0.2 -0" rpy="0 0 0"/>
      <mass value="2.92168"/>
      <inertia ixx="0.0237387" ixy="0" ixz="0" iyy="0.0036521" iyz="0" izz="0.0237387"/>
    </inertial>
    <!-- Part left_knee_pitch_parts -->
    <collision>
      <origin xyz="0 0.2 -0" rpy="1.5708 1.5708 0"/>
      <geometry>
        <cylinder length="0.16" radius="0.05"/>
      </geometry>
    </collision>
    <visual>
      <origin xyz="0 0.2 -0" rpy="1.5708 -0 0"/>
      <geometry>
        <mesh filename="../meshes/left_knee_pitch_visual.stl"/>
      </geometry>
      <material name="left_knee_pitch_parts_material">
        <color rgba="0.768627 0.886275 0.952941 1"/>
      </material>
    </visual>
  </link>
  <!-- Link left_ankle_yaw -->
  <link name="left_ankle_yaw">
    <inertial>
      <origin xyz="0 -0 0" rpy="0 0 0"/>
      <mass value="0.121737"/>
      <inertia ixx="3.80427e-05" ixy="-0" ixz="-0" iyy="4.43832e-05" iyz="0" izz="4.43832e-05"/>
    </inertial>
    <!-- Part left_ankle_yaw_parts -->
    <visual>
      <origin xyz="0 -0 0" rpy="0 0 0"/>
      <geometry>
        <mesh filename="../meshes/left_ankle_yaw_visual.stl"/>
      </geometry>
      <material name="left_ankle_yaw_parts_material">
        <color rgba="0.768627 0.886275 0.952941 1"/>
      </material>
    </visual>
  </link>
  <!-- Link left_ankle_roll -->
  <link name="left_ankle_roll">
    <inertial>
      <origin xyz="0 -0 0" rpy="0 0 0"/>
      <mass value="0.121737"/>
      <inertia ixx="3.80427e-05" ixy="-0" ixz="-0" iyy="4.43832e-05" iyz="-0" izz="4.43832e-05"/>
    </inertial>
    <!-- Part left_ankle_roll_parts -->
    <visual>
      <origin xyz="0 -0 0" rpy="1.5708 -1.5708 0"/>
      <geometry>
        <mesh filename="../meshes/left_ankle_roll_visual.stl"/>
      </geometry>
      <material name="left_ankle_roll_parts_material">
        <color rgba="0.498039 0.498039 0.498039 1"/>
      </material>
    </visual>
  </link>
  <!-- Link left_foot -->
  <link name="left_foot">
    <inertial>
      <origin xyz="0.0525 0.045 -0" rpy="0 0 0"/>
      <mass value="0.433566"/>
      <inertia ixx="0.000175919" ixy="-0" ixz="-0" iyy="0.00137997" iyz="-0" izz="0.00126908"/>
    </inertial>
    <!-- Part left_foot_parts -->
    <collision>
      <origin xyz="0.052 0.045 -0" rpy="1.5708 1.5708 0"/>
      <geometry>
        <box size="0.063 0.185 0.03"/>
      </geometry>
    </collision>
    <visual>
      <origin xyz="0.0525 0.045 -0" rpy="1.5708 -0 0"/>
      <geometry>
        <mesh filename="../meshes/left_foot_visual.stl"/>
      </geometry>
      <material name="left_foot_parts_material">
        <color rgba="0.972549 0.529412 0.00392157 1"/>
      </material>
    </visual>
  </link>
  <!-- Joint from left_ankle_roll to left_foot -->
  <joint name="left_ankle_pitch" type="revolute">
    <origin xyz="0 -0 0" rpy="0 -1.5708 0"/>
    <parent link="left_ankle_roll"/>
    <child link="left_foot"/>
    <axis xyz="0 0 1"/>
    <limit effort="100" velocity="100" lower="-0.785398" upper="0.785398"/>
    <joint_properties friction="0.1"/>
  </joint>
  <!-- Joint from left_ankle_yaw to left_ankle_roll -->
  <joint name="left_ankle_roll" type="revolute">
    <origin xyz="0 0 0" rpy="-1.5708 -0 -1.5708"/>
    <parent link="left_ankle_yaw"/>
    <child link="left_ankle_roll"/>
    <axis xyz="0 0 1"/>
    <limit effort="100" velocity="100" lower="-0.349066" upper="0.349066"/>
    <joint_properties friction="0.1"/>
  </joint>
  <!-- Joint from left_knee_pitch to left_ankle_yaw -->
  <joint name="left_ankle_yaw" type="revolute">
    <origin xyz="0 0.4 0" rpy="1.5708 0 0"/>
    <parent link="left_knee_pitch"/>
    <child link="left_ankle_yaw"/>
    <axis xyz="0 0 1"/>
    <limit effort="100" velocity="100" lower="-0.785398" upper="0.785398"/>
    <joint_properties friction="0.1"/>
  </joint>
  <!-- Joint from left_hip_yaw to left_knee_pitch -->
  <joint name="left_knee_pitch" type="revolute">
    <origin xyz="-0 0 -0.42" rpy="-1.5708 -0 -0"/>
    <parent link="left_hip_yaw"/>
    <child link="left_knee_pitch"/>
    <axis xyz="0 0 1"/>
    <limit effort="100" velocity="100" lower="0" upper="2.35619"/>
    <joint_properties friction="0.1"/>
  </joint>
  <!-- Joint from left_hip_roll to left_hip_yaw -->
  <joint name="left_hip_yaw" type="revolute">
    <origin xyz="0 0 -0" rpy="1.5708 -1.5708 0"/>
    <parent link="left_hip_roll"/>
    <child link="left_hip_yaw"/>
    <axis xyz="0 0 1"/>
    <limit effort="100" velocity="100" lower="-0.785398" upper="0.785398"/>
    <joint_properties friction="0.1"/>
  </joint>
  <!-- Joint from left_hip_pitch to left_hip_roll -->
  <joint name="left_hip_roll" type="revolute">
    <origin xyz="0 -0 -0" rpy="0 1.5708 0"/>
    <parent link="left_hip_pitch"/>
    <child link="left_hip_roll"/>
    <axis xyz="0 0 1"/>
    <limit effort="100" velocity="100" lower="-0.261799" upper="1.5708"/>
    <joint_properties friction="0.1"/>
  </joint>
  <!-- Joint from pelvis to left_hip_pitch -->
  <joint name="left_hip_pitch" type="revolute">
    <origin xyz="-0 0.08 0" rpy="-1.5708 -0 0"/>
    <parent link="pelvis"/>
    <child link="left_hip_pitch"/>
    <axis xyz="0 0 1"/>
    <limit effort="100" velocity="100" lower="-2.35619" upper="0.785398"/>
    <joint_properties friction="0.1"/>
  </joint>
  <!-- Link right_hip_pitch -->
  <link name="right_hip_pitch">
    <inertial>
      <origin xyz="-0.08 -0 0" rpy="0 0 0"/>
      <mass value="0.486947"/>
      <inertia ixx="0.000608684" ixy="-0" ixz="0" iyy="0.000405789" iyz="0" izz="0.000405789"/>
    </inertial>
    <!-- Part right_hip_pitch_parts -->
    <visual>
      <origin xyz="-0.08 -0 0" rpy="1.5708 0 -0"/>
      <geometry>
        <mesh filename="../meshes/right_hip_pitch_visual.stl"/>
      </geometry>
      <material name="right_hip_pitch_parts_material">
        <color rgba="0.647059 0.647059 0.647059 1"/>
      </material>
    </visual>
  </link>
  <!-- Link right_hip_roll -->
  <link name="right_hip_roll">
    <inertial>
      <origin xyz="-0 0.21 -0" rpy="0 0 0"/>
      <mass value="3.11646"/>
      <inertia ixx="0.0285416" ixy="0" ixz="-0" iyy="0.00389557" iyz="-0" izz="0.0285416"/>
    </inertial>
    <!-- Part right_hip_roll_parts -->
    <collision>
      <origin xyz="-0 0.21 -0" rpy="1.5708 -0 0"/>
      <geometry>
        <cylinder length="0.2" radius="0.05"/>
      </geometry>
    </collision>
    <visual>
      <origin xyz="-0 0.21 -0" rpy="1.5708 -1.5708 0"/>
      <geometry>
        <mesh filename="../meshes/right_hip_roll_visual.stl"/>
      </geometry>
      <material name="right_hip_roll_parts_material">
        <color rgba="0.231373 0.380392 0.705882 1"/>
      </material>
    </visual>
  </link>
  <!-- Link right_hip_yaw -->
  <link name="right_hip_yaw">
    <inertial>
      <origin xyz="-0 0 -0.42" rpy="0 0 0"/>
      <mass value="0.486947"/>
      <inertia ixx="0.000405789" ixy="-0" ixz="0" iyy="0.000608684" iyz="0" izz="0.000405789"/>
    </inertial>
    <!-- Part right_hip_yaw_parts -->
    <visual>
      <origin xyz="-0 0 -0.42" rpy="0 0 0"/>
      <geometry>
        <mesh filename="../meshes/right_hip_yaw_visual.stl"/>
      </geometry>
      <material name="right_hip_yaw_parts_material">
        <color rgba="0.917647 0.917647 0.917647 1"/>
      </material>
    </visual>
  </link>
  <!-- Link right_knee_pitch -->
  <link name="right_knee_pitch">
    <inertial>
      <origin xyz="0 0.2 -0" rpy="0 0 0"/>
      <mass value="2.92168"/>
      <inertia ixx="0.0237387" ixy="-0" ixz="-0" iyy="0.0036521" iyz="0" izz="0.0237387"/>
    </inertial>
    <!-- Part right_knee_pitch_parts -->
    <collision>
      <origin xyz="0 0.2 -0" rpy="1.5708 1.5708 0"/>
      <geometry>
        <cylinder length="0.16" radius="0.05"/>
      </geometry>
    </collision>
    <visual>
      <origin xyz="0 0.2 -0" rpy="1.5708 -0 0"/>
      <geometry>
        <mesh filename="../meshes/right_knee_pitch_visual.stl"/>
      </geometry>
      <material name="right_knee_pitch_parts_material">
        <color rgba="0.768627 0.886275 0.952941 1"/>
      </material>
    </visual>
  </link>
  <!-- Link right_ankle_yaw -->
  <link name="right_ankle_yaw">
    <inertial>
      <origin xyz="0 -0 0" rpy="0 0 0"/>
      <mass value="0.121737"/>
      <inertia ixx="3.80427e-05" ixy="-0" ixz="-0" iyy="4.43832e-05" iyz="-0" izz="4.43832e-05"/>
    </inertial>
    <!-- Part right_ankle_yaw_parts -->
    <visual>
      <origin xyz="0 -0 0" rpy="0 -0 0"/>
      <geometry>
        <mesh filename="../meshes/right_ankle_yaw_visual.stl"/>
      </geometry>
      <material name="right_ankle_yaw_parts_material">
        <color rgba="0.768627 0.886275 0.952941 1"/>
      </material>
    </visual>
  </link>
  <!-- Link right_ankle_roll -->
  <link name="right_ankle_roll">
    <inertial>
      <origin xyz="0 0 -0" rpy="0 0 0"/>
      <mass value="0.121737"/>
      <inertia ixx="3.80427e-05" ixy="0" ixz="0" iyy="4.43832e-05" iyz="0" izz="4.43832e-05"/>
    </inertial>
    <!-- Part right_ankle_roll_parts -->
    <visual>
      <origin xyz="0 0 -0" rpy="1.5708 -1.5708 0"/>
      <geometry>
        <mesh filename="../meshes/right_ankle_roll_visual.stl"/>
      </geometry>
      <material name="right_ankle_roll_parts_material">
        <color rgba="0.498039 0.498039 0.498039 1"/>
      </material>
    </visual>
  </link>
  <!-- Link right_foot -->
  <link name="right_foot">
    <inertial>
      <origin xyz="0.0525 0.045 -0" rpy="0 0 0"/>
      <mass value="0.433566"/>
      <inertia ixx="0.000175919" ixy="0" ixz="0" iyy="0.00137997" iyz="-0" izz="0.00126908"/>
    </inertial>
    <!-- Part right_foot_parts -->
    <collision>
      <origin xyz="0.052 0.045 -0" rpy="1.5708 1.5708 0"/>
      <geometry>
        <box size="0.063 0.185 0.03"/>
      </geometry>
    </collision>
    <visual>
      <origin xyz="0.0525 0.045 -0" rpy="1.5708 0 0"/>
      <geometry>
        <mesh filename="../meshes/right_foot_visual.stl"/>
      </geometry>
      <material name="right_foot_parts_material">
        <color rgba="0.972549 0.529412 0.00392157 1"/>
      </material>
    </visual>
  </link>
  <!-- Joint from right_ankle_roll to right_foot -->
  <joint name="right_ankle_pitch" type="revolute">
    <origin xyz="0 0 -0" rpy="-0 -1.5708 0"/>
    <parent link="right_ankle_roll"/>
    <child link="right_foot"/>
    <axis xyz="0 0 1"/>
    <limit effort="100" velocity="100" lower="-0.785398" upper="0.785398"/>
    <joint_properties friction="0.1"/>
  </joint>
  <!-- Joint from right_ankle_yaw to right_ankle_roll -->
  <joint name="right_ankle_roll" type="revolute">
    <origin xyz="0 0 0" rpy="-1.5708 0 -1.5708"/>
    <parent link="right_ankle_yaw"/>
    <child link="right_ankle_roll"/>
    <axis xyz="0 0 1"/>
    <limit effort="100" velocity="100" lower="-0.349066" upper="0.349066"/>
    <joint_properties friction="0.1"/>
  </joint>
  <!-- Joint from right_knee_pitch to right_ankle_yaw -->
  <joint name="right_ankle_yaw" type="revolute">
    <origin xyz="0 0.4 0" rpy="1.5708 -0 0"/>
    <parent link="right_knee_pitch"/>
    <child link="right_ankle_yaw"/>
    <axis xyz="0 0 1"/>
    <limit effort="100" velocity="100" lower="-0.785398" upper="0.785398"/>
    <joint_properties friction="0.1"/>
  </joint>
  <!-- Joint from right_hip_yaw to right_knee_pitch -->
  <joint name="right_knee_pitch" type="revolute">
    <origin xyz="-0 -0 -0.42" rpy="-1.5708 0 0"/>
    <parent link="right_hip_yaw"/>
    <child link="right_knee_pitch"/>
    <axis xyz="0 0 1"/>
    <limit effort="100" velocity="100" lower="0" upper="2.35619"/>
    <joint_properties friction="0.1"/>
  </joint>
  <!-- Joint from right_hip_roll to right_hip_yaw -->
  <joint name="right_hip_yaw" type="revolute">
    <origin xyz="0 0 0" rpy="1.5708 -1.5708 0"/>
    <parent link="right_hip_roll"/>
    <child link="right_hip_yaw"/>
    <axis xyz="0 0 1"/>
    <limit effort="100" velocity="100" lower="-0.785398" upper="0.785398"/>
    <joint_properties friction="0.1"/>
  </joint>
  <!-- Joint from right_hip_pitch to right_hip_roll -->
  <joint name="right_hip_roll" type="revolute">
    <origin xyz="-0 -0 0" rpy="0 1.5708 0"/>
    <parent link="right_hip_pitch"/>
    <child link="right_hip_roll"/>
    <axis xyz="0 0 1"/>
    <limit effort="100" velocity="100" lower="-1.5708" upper="0.261799"/>
    <joint_properties friction="0.1"/>
  </joint>
  <!-- Joint from pelvis to right_hip_pitch -->
  <joint name="right_hip_pitch" type="revolute">
    <origin xyz="0 -0.08 0" rpy="-1.5708 0 0"/>
    <parent link="pelvis"/>
    <child link="right_hip_pitch"/>
    <axis xyz="0 0 1"/>
    <limit effort="100" velocity="100" lower="-2.35619" upper="0.785398"/>
    <joint_properties friction="0.1"/>
  </joint>
  <!-- Link waist_yaw -->
  <link name="waist_yaw">
    <inertial>
      <origin xyz="0 0 -0" rpy="0 0 0"/>
      <mass value="0.311646"/>
      <inertia ixx="0.000189585" ixy="0" ixz="0" iyy="0.000249317" iyz="0" izz="0.000189585"/>
    </inertial>
    <!-- Part waist_yaw_parts -->
    <visual>
      <origin xyz="0 0 -0" rpy="0 0 -0"/>
      <geometry>
        <mesh filename="../meshes/waist_yaw_visual.stl"/>
      </geometry>
      <material name="waist_yaw_parts_material">
        <color rgba="0.615686 0.811765 0.929412 1"/>
      </material>
    </visual>
  </link>
  <!-- Link waist_pitch -->
  <link name="waist_pitch">
    <inertial>
      <origin xyz="-0 0.09 -0" rpy="0 0 0"/>
      <mass value="0.486947"/>
      <inertia ixx="0.000608684" ixy="0" ixz="0" iyy="0.000405789" iyz="-0" izz="0.000405789"/>
    </inertial>
    <!-- Part waist_pitch_parts -->
    <visual>
      <origin xyz="-0 0.09 -0" rpy="1.5708 0 -3.14159"/>
      <geometry>
        <mesh filename="../meshes/waist_pitch_visual.stl"/>
      </geometry>
      <material name="waist_pitch_parts_material">
        <color rgba="0.980392 0.713725 0.00392157 1"/>
      </material>
    </visual>
  </link>
  <!-- Link torso -->
  <link name="torso">
    <inertial>
      <origin xyz="-3.7508e-08 0.15145 4.09014e-07" rpy="0 0 0"/>
      <mass value="1.31699"/>
      <inertia ixx="0.0027968" ixy="-2.32e-09" ixz="-3.9e-09" iyy="0.00170098" iyz="-2.357e-08" izz="0.00298334"/>
    </inertial>
    <!-- Part torso_parts -->
    <collision>
      <origin xyz="0 0.14 0" rpy="1.5708 -0 -3.14159"/>
      <geometry>
        <cylinder length="0.12" radius="0.04"/>
      </geometry>
    </collision>
    <collision>
      <origin xyz="0 0.17 0" rpy="1.5708 -0 -1.5708"/>
      <geometry>
        <cylinder length="0.08" radius="0.05"/>
      </geometry>
    </collision>
    <visual>
      <origin xyz="-3.7508e-08 0.15145 4.09014e-07" rpy="-1.5708 -1.5708 0"/>
      <geometry>
        <mesh filename="../meshes/torso_visual.stl"/>
      </geometry>
      <material name="torso_parts_material">
        <color rgba="0.647059 0.647059 0.647059 1"/>
      </material>
    </visual>
  </link>
  <!-- Link left_shoulder_pitch -->
  <link name="left_shoulder_pitch">
    <inertial>
      <origin xyz="-0 0 -0" rpy="0 0 0"/>
      <mass value="0.311646"/>
      <inertia ixx="0.000249317" ixy="-0" ixz="-0" iyy="0.000189585" iyz="0" izz="0.000189585"/>
    </inertial>
    <!-- Part left_shoulder_pitch_parts -->
    <visual>
      <origin xyz="-0 0 -0" rpy="1.5708 0 0"/>
      <geometry>
        <mesh filename="../meshes/left_shoulder_pitch_visual.stl"/>
      </geometry>
      <material name="left_shoulder_pitch_parts_material">
        <color rgba="0.231373 0.380392 0.705882 1"/>
      </material>
    </visual>
  </link>
  <!-- Link left_shoulder_roll -->
  <link name="left_shoulder_roll">
    <inertial>
      <origin xyz="0 0.105 -0" rpy="0 0 0"/>
      <mass value="0.455782"/>
      <inertia ixx="0.000744444" ixy="-0" ixz="0" iyy="0.000205102" iyz="0" izz="0.000744444"/>
    </inertial>
    <!-- Part left_shoulder_roll_parts -->
    <collision>
      <origin xyz="0 0.105 -0" rpy="1.5708 -0 -0"/>
      <geometry>
        <cylinder length="0.08" radius="0.03"/>
      </geometry>
    </collision>
    <visual>
      <origin xyz="0 0.105 -0" rpy="0 -1.5708 0"/>
      <geometry>
        <mesh filename="../meshes/left_shoulder_roll_visual.stl"/>
      </geometry>
      <material name="left_shoulder_roll_parts_material">
        <color rgba="0.917647 0.917647 0.917647 1"/>
      </material>
    </visual>
  </link>
  <!-- Link left_shoulder_yaw -->
  <link name="left_shoulder_yaw">
    <inertial>
      <origin xyz="0 0 0.2" rpy="0 0 0"/>
      <mass value="0.175301"/>
      <inertia ixx="7.59637e-05" ixy="-0" ixz="0" iyy="7.88854e-05" iyz="-0" izz="7.59637e-05"/>
    </inertial>
    <!-- Part left_shoulder_yaw_parts -->
    <visual>
      <origin xyz="0 0 0.2" rpy="1.5708 0 -0"/>
      <geometry>
        <mesh filename="../meshes/left_shoulder_yaw_visual.stl"/>
      </geometry>
      <material name="left_shoulder_yaw_parts_material">
        <color rgba="0.768627 0.886275 0.952941 1"/>
      </material>
    </visual>
  </link>
  <!-- Link left_elbow_pitch -->
  <link name="left_elbow_pitch">
    <inertial>
      <origin xyz="0 0.0925 -0" rpy="0 0 0"/>
      <mass value="0.304342"/>
      <inertia ixx="0.000443832" ixy="-0" ixz="0" iyy="9.51068e-05" iyz="-0" izz="0.000443832"/>
    </inertial>
    <!-- Part left_elbow_pitch_parts -->
    <collision>
      <origin xyz="0 0.095 -0" rpy="1.5708 1.5708 0"/>
      <geometry>
        <cylinder length="0.08" radius="0.025"/>
      </geometry>
    </collision>
    <visual>
      <origin xyz="0 0.0925 -0" rpy="-0 0 -0"/>
      <geometry>
        <mesh filename="../meshes/left_elbow_pitch_visual.stl"/>
      </geometry>
      <material name="left_elbow_pitch_parts_material">
        <color rgba="0.972549 0.529412 0.00392157 1"/>
      </material>
    </visual>
  </link>
  <!-- Link left_wrist_yaw -->
  <link name="left_wrist_yaw">
    <inertial>
      <origin xyz="0 0 -0" rpy="0 0 0"/>
      <mass value="0.0779115"/>
      <inertia ixx="2.40227e-05" ixy="0" ixz="0" iyy="1.55823e-05" iyz="0" izz="2.40227e-05"/>
    </inertial>
    <!-- Part left_wrist_yaw_parts -->
    <visual>
      <origin xyz="0 0 -0" rpy="1.5708 0 -0"/>
      <geometry>
        <mesh filename="../meshes/left_wrist_yaw_visual.stl"/>
      </geometry>
      <material name="left_wrist_yaw_parts_material">
        <color rgba="0.980392 0.713725 0.00392157 1"/>
      </material>
    </visual>
  </link>
  <!-- Link left_wrist_roll -->
  <link name="left_wrist_roll">
    <inertial>
      <origin xyz="0 -0 0" rpy="0 0 0"/>
      <mass value="0.0779115"/>
      <inertia ixx="1.55823e-05" ixy="0" ixz="0" iyy="2.40227e-05" iyz="0" izz="2.40227e-05"/>
    </inertial>
    <!-- Part left_wrist_roll_parts -->
    <visual>
      <origin xyz="0 -0 0" rpy="-0 0 -0"/>
      <geometry>
        <mesh filename="../meshes/left_wrist_roll_visual.stl"/>
      </geometry>
      <material name="left_wrist_roll_parts_material">
        <color rgba="0.498039 0.498039 0.498039 1"/>
      </material>
    </visual>
  </link>
  <!-- Link left_hand -->
  <link name="left_hand">
    <inertial>
      <origin xyz="0 0.0479645 -0.0118716" rpy="0 0 0"/>
      <mass value="0.028365"/>
      <inertia ixx="7.37812e-06" ixy="-0" ixz="0" iyy="5.11736e-06" iyz="2.58217e-07" izz="3.32444e-06"/>
    </inertial>
    <!-- Part left_hand_parts -->
    <collision>
      <origin xyz="0 0.08 0" rpy="1.5708 0 -1.5708"/>
      <geometry>
        <box size="0.1 0.07 0.015"/>
      </geometry>
    </collision>
    <visual>
      <origin xyz="0 0.0479645 -0.0118716" rpy="-0 -1.5708 0"/>
      <geometry>
        <mesh filename="../meshes/left_hand_visual.stl"/>
      </geometry>
      <material name="left_hand_parts_material">
        <color rgba="0.615686 0.811765 0.929412 1"/>
      </material>
    </visual>
  </link>
  <!-- Link left_finger_1_j1 -->
  <link name="left_finger_1_j1">
    <inertial>
      <origin xyz="0 0.0025 0" rpy="0 0 0"/>
      <mass value="0.000744"/>
      <inertia ixx="1.0478e-08" ixy="0" ixz="-0" iyy="1.5128e-08" iyz="0" izz="7.75e-09"/>
    </inertial>
    <!-- Part left_finger_1_j1_parts -->
    <visual>
      <origin xyz="0 0.0025 0" rpy="-1.5708 -0.785398 1.5708"/>
      <geometry>
        <mesh filename="../meshes/left_finger_1_j1_visual.stl"/>
      </geometry>
      <material name="left_finger_1_j1_parts_material">
        <color rgba="0.498039 0.498039 0.498039 1"/>
      </material>
    </visual>
  </link>
  <!-- Link left_finger_1_j2 -->
  <link name="left_finger_1_j2">
    <inertial>
      <origin xyz="-0 0.01 0" rpy="0 0 0"/>
      <mass value="0.002976"/>
      <inertia ixx="1.24e-07" ixy="-0" ixz="0" iyy="6.0512e-08" iyz="0" izz="1.34912e-07"/>
    </inertial>
    <!-- Part left_finger_1_j2_parts -->
    <visual>
      <origin xyz="-0 0.01 0" rpy="-0 -0 0.785398"/>
      <geometry>
        <mesh filename="../meshes/left_finger_1_j2_visual.stl"/>
      </geometry>
      <material name="left_finger_1_j2_parts_material">
        <color rgba="0.972549 0.529412 0.00392157 1"/>
      </material>
    </visual>
  </link>
  <!-- Link left_finger_1_j3 -->
  <link name="left_finger_1_j3">
    <inertial>
      <origin xyz="-0 0.01 -0" rpy="0 0 0"/>
      <mass value="0.001984"/>
      <inertia ixx="8.2667e-08" ixy="0" ixz="0" iyy="2.7115e-08" iyz="0" izz="7.6715e-08"/>
    </inertial>
    <!-- Part left_finger_1_j3_parts -->
    <visual>
      <origin xyz="-0 0.01 -0" rpy="-1.5708 -0.785398 1.5708"/>
      <geometry>
        <mesh filename="../meshes/left_finger_1_j3_visual.stl"/>
      </geometry>
      <material name="left_finger_1_j3_parts_material">
        <color rgba="0.498039 0.498039 0.498039 1"/>
      </material>
    </visual>
  </link>
  <!-- Link left_finger_1_j4 -->
  <link name="left_finger_1_j4">
    <inertial>
      <origin xyz="-0.000271318 0.00682171 0" rpy="0 0 0"/>
      <mass value="0.001333"/>
      <inertia ixx="3.2905e-08" ixy="2.247e-09" ixz="0" iyy="1.7887e-08" iyz="-0" izz="2.8576e-08"/>
    </inertial>
    <!-- Part left_finger_1_j4_parts -->
    <visual>
      <origin xyz="-0.000271318 0.00682171 0" rpy="-1.5708 -0.785398 1.5708"/>
      <geometry>
        <mesh filename="../meshes/left_finger_1_j4_visual.stl"/>
      </geometry>
      <material name="left_finger_1_j4_parts_material">
        <color rgba="0.980392 0.713725 0.00392157 1"/>
      </material>
    </visual>
  </link>
  <!-- Joint from left_finger_1_j3 to left_finger_1_j4 -->
  <joint name="left_finger1_j4" type="revolute">
    <origin xyz="0 0.025 0" rpy="-0 0 -0"/>
    <parent link="left_finger_1_j3"/>
    <child link="left_finger_1_j4"/>
    <axis xyz="0 0 1"/>
    <limit effort="100" velocity="100" lower="-1.91986" upper="0.0872665"/>
    <joint_properties friction="0.1"/>
  </joint>
  <!-- Joint from left_finger_1_j2 to left_finger_1_j3 -->
  <joint name="left_finger1_j3" type="revolute">
    <origin xyz="0 0.025 0" rpy="0 1.5708 0"/>
    <parent link="left_finger_1_j2"/>
    <child link="left_finger_1_j3"/>
    <axis xyz="0 0 1"/>
    <limit effort="100" velocity="100" lower="-1.91986" upper="0.0872665"/>
    <joint_properties friction="0.1"/>
  </joint>
  <!-- Joint from left_finger_1_j1 to left_finger_1_j2 -->
  <joint name="left_finger1_j2" type="revolute">
    <origin xyz="0 0.01 -0" rpy="0 -1.5708 0"/>
    <parent link="left_finger_1_j1"/>
    <child link="left_finger_1_j2"/>
    <axis xyz="0 0 1"/>
    <limit effort="100" velocity="100" lower="-0.349066" upper="0.349066"/>
    <joint_properties friction="0.1"/>
  </joint>
  <!-- Joint from left_hand to left_finger_1_j1 -->
  <joint name="left_finger1_j1" type="revolute">
    <origin xyz="0 0.035 0.015" rpy="0.785398 0 -0"/>
    <parent link="left_hand"/>
    <child link="left_finger_1_j1"/>
    <axis xyz="0 0 1"/>
    <limit effort="100" velocity="100" lower="-1.91986" upper="0.0872665"/>
    <joint_properties friction="0.1"/>
  </joint>
  <!-- Link left_finger_2_j1 -->
  <link name="left_finger_2_j1">
    <inertial>
      <origin xyz="0 0.0025 -0" rpy="0 0 0"/>
      <mass value="0.000496"/>
      <inertia ixx="3.679e-09" ixy="-0" ixz="0" iyy="6.779e-09" iyz="-0" izz="5.167e-09"/>
    </inertial>
    <!-- Part left_finger_2_j1_parts -->
    <visual>
      <origin xyz="0 0.0025 -0" rpy="-0 -1.5708 0"/>
      <geometry>
        <mesh filename="../meshes/left_finger_2_j1_visual.stl"/>
      </geometry>
      <material name="left_finger_2_j1_parts_material">
        <color rgba="0.980392 0.713725 0.00392157 1"/>
      </material>
    </visual>
  </link>
  <!-- Link left_finger_2_j2 -->
  <link name="left_finger_2_j2">
    <inertial>
      <origin xyz="0 0.0125 -0" rpy="0 0 0"/>
      <mass value="0.00248"/>
      <inertia ixx="1.49833e-07" ixy="0" ixz="0" iyy="3.3893e-08" iyz="-0" izz="1.42393e-07"/>
    </inertial>
    <!-- Part left_finger_2_j2_parts -->
    <visual>
      <origin xyz="0 0.0125 -0" rpy="-0 0 -0"/>
      <geometry>
        <mesh filename="../meshes/left_finger_2_j2_visual.stl"/>
      </geometry>
      <material name="left_finger_2_j2_parts_material">
        <color rgba="0.647059 0.647059 0.647059 1"/>
      </material>
    </visual>
  </link>
  <!-- Link left_finger_2_j3 -->
  <link name="left_finger_2_j3">
    <inertial>
      <origin xyz="0 0.01 0" rpy="0 0 0"/>
      <mass value="0.0011904"/>
      <inertia ixx="4.3251e-08" ixy="-0" ixz="0" iyy="9.92e-09" iyz="-0" izz="4.6029e-08"/>
    </inertial>
    <!-- Part left_finger_2_j3_parts -->
    <visual>
      <origin xyz="0 0.01 0" rpy="-0 -1.5708 0"/>
      <geometry>
        <mesh filename="../meshes/left_finger_2_j3_visual.stl"/>
      </geometry>
      <material name="left_finger_2_j3_parts_material">
        <color rgba="0.498039 0.498039 0.498039 1"/>
      </material>
    </visual>
  </link>
  <!-- Link left_finger_2_j4 -->
  <link name="left_finger_2_j4">
    <inertial>
      <origin xyz="-0.000432099 0.00438272 0" rpy="0 0 0"/>
      <mass value="0.0004185"/>
      <inertia ixx="3.877e-09" ixy="6.61e-10" ixz="0" iyy="2.909e-09" iyz="-0" izz="5.043e-09"/>
    </inertial>
    <!-- Part left_finger_2_j4_parts -->
    <visual>
      <origin xyz="-0.000432099 0.00438272 0" rpy="-0 -1.5708 0"/>
      <geometry>
        <mesh filename="../meshes/left_finger_2_j4_visual.stl"/>
      </geometry>
      <material name="left_finger_2_j4_parts_material">
        <color rgba="0.980392 0.713725 0.00392157 1"/>
      </material>
    </visual>
  </link>
  <!-- Joint from left_finger_2_j3 to left_finger_2_j4 -->
  <joint name="left_finger2_j4" type="revolute">
    <origin xyz="0 0.025 0" rpy="0 0 -0"/>
    <parent link="left_finger_2_j3"/>
    <child link="left_finger_2_j4"/>
    <axis xyz="0 0 1"/>
    <limit effort="100" velocity="100" lower="-1.91986" upper="0.0872665"/>
    <joint_properties friction="0.1"/>
  </joint>
  <!-- Joint from left_finger_2_j2 to left_finger_2_j3 -->
  <joint name="left_finger2_j3" type="revolute">
    <origin xyz="-0 0.03 0" rpy="0 1.5708 0"/>
    <parent link="left_finger_2_j2"/>
    <child link="left_finger_2_j3"/>
    <axis xyz="0 0 1"/>
    <limit effort="100" velocity="100" lower="-1.91986" upper="0.0872665"/>
    <joint_properties friction="0.1"/>
  </joint>
  <!-- Joint from left_finger_2_j1 to left_finger_2_j2 -->
  <joint name="left_finger2_j2" type="revolute">
    <origin xyz="0 0.01 0" rpy="0 -1.5708 0"/>
    <parent link="left_finger_2_j1"/>
    <child link="left_finger_2_j2"/>
    <axis xyz="0 0 1"/>
    <limit effort="100" velocity="100" lower="-0.349066" upper="0.349066"/>
    <joint_properties friction="0.1"/>
  </joint>
  <!-- Joint from left_hand to left_finger_2_j1 -->
  <joint name="left_finger2_j1" type="revolute">
    <origin xyz="0 0.07 0.015" rpy="-0 0 -0"/>
    <parent link="left_hand"/>
    <child link="left_finger_2_j1"/>
    <axis xyz="0 0 1"/>
    <limit effort="100" velocity="100" lower="-1.91986" upper="0.0872665"/>
    <joint_properties friction="0.1"/>
  </joint>
  <!-- Link left_finger_3_j1 -->
  <link name="left_finger_3_j1">
    <inertial>
      <origin xyz="0 0.0025 -0" rpy="0 0 0"/>
      <mass value="0.000496"/>
      <inertia ixx="3.679e-09" ixy="-0" ixz="0" iyy="6.779e-09" iyz="-0" izz="5.167e-09"/>
    </inertial>
    <!-- Part left_finger_3_j1_parts -->
    <visual>
      <origin xyz="0 0.0025 -0" rpy="-0 -1.5708 0"/>
      <geometry>
        <mesh filename="../meshes/left_finger_3_j1_visual.stl"/>
      </geometry>
      <material name="left_finger_3_j1_parts_material">
        <color rgba="0.615686 0.811765 0.929412 1"/>
      </material>
    </visual>
  </link>
  <!-- Link left_finger_3_j2 -->
  <link name="left_finger_3_j2">
    <inertial>
      <origin xyz="0 0.015 0" rpy="0 0 0"/>
      <mass value="0.002976"/>
      <inertia ixx="2.48e-07" ixy="0" ixz="-0" iyy="4.0672e-08" iyz="-0" izz="2.39072e-07"/>
    </inertial>
    <!-- Part left_finger_3_j2_parts -->
    <visual>
      <origin xyz="0 0.015 0" rpy="-0 0 -0"/>
      <geometry>
        <mesh filename="../meshes/left_finger_3_j2_visual.stl"/>
      </geometry>
      <material name="left_finger_3_j2_parts_material">
        <color rgba="0.231373 0.380392 0.705882 1"/>
      </material>
    </visual>
  </link>
  <!-- Link left_finger_3_j3 -->
  <link name="left_finger_3_j3">
    <inertial>
      <origin xyz="-0 0.0125 0" rpy="0 0 0"/>
      <mass value="0.001488"/>
      <inertia ixx="8.1964e-08" ixy="0" ixz="0" iyy="1.24e-08" iyz="0" izz="8.5436e-08"/>
    </inertial>
    <!-- Part left_finger_3_j3_parts -->
    <visual>
      <origin xyz="-0 0.0125 0" rpy="-0 -1.5708 0"/>
      <geometry>
        <mesh filename="../meshes/left_finger_3_j3_visual.stl"/>
      </geometry>
      <material name="left_finger_3_j3_parts_material">
        <color rgba="0.615686 0.811765 0.929412 1"/>
      </material>
    </visual>
  </link>
  <!-- Link left_finger_3_j4 -->
  <link name="left_finger_3_j4">
    <inertial>
      <origin xyz="-0.000432099 0.00438272 0" rpy="0 0 0"/>
      <mass value="0.0004185"/>
      <inertia ixx="3.877e-09" ixy="6.61e-10" ixz="0" iyy="2.909e-09" iyz="-0" izz="5.043e-09"/>
    </inertial>
    <!-- Part left_finger_3_j4_parts -->
    <visual>
      <origin xyz="-0.000432099 0.00438272 0" rpy="-0 -1.5708 0"/>
      <geometry>
        <mesh filename="../meshes/left_finger_3_j4_visual.stl"/>
      </geometry>
      <material name="left_finger_3_j4_parts_material">
        <color rgba="0.647059 0.647059 0.647059 1"/>
      </material>
    </visual>
  </link>
  <!-- Joint from left_finger_3_j3 to left_finger_3_j4 -->
  <joint name="left_finger3_j4" type="revolute">
    <origin xyz="0 0.03 0" rpy="-0 0 0"/>
    <parent link="left_finger_3_j3"/>
    <child link="left_finger_3_j4"/>
    <axis xyz="0 0 1"/>
    <limit effort="100" velocity="100" lower="-1.91986" upper="0.0872665"/>
    <joint_properties friction="0.1"/>
  </joint>
  <!-- Joint from left_finger_3_j2 to left_finger_3_j3 -->
  <joint name="left_finger3_j3" type="revolute">
    <origin xyz="0 0.035 0" rpy="-0 1.5708 0"/>
    <parent link="left_finger_3_j2"/>
    <child link="left_finger_3_j3"/>
    <axis xyz="0 0 1"/>
    <limit effort="100" velocity="100" lower="-1.91986" upper="0.0872665"/>
    <joint_properties friction="0.1"/>
  </joint>
  <!-- Joint from left_finger_3_j1 to left_finger_3_j2 -->
  <joint name="left_finger3_j2" type="revolute">
    <origin xyz="0 0.01 -0" rpy="-0 -1.5708 0"/>
    <parent link="left_finger_3_j1"/>
    <child link="left_finger_3_j2"/>
    <axis xyz="0 0 1"/>
    <limit effort="100" velocity="100" lower="-0.349066" upper="0.349066"/>
    <joint_properties friction="0.1"/>
  </joint>
  <!-- Joint from left_hand to left_finger_3_j1 -->
  <joint name="left_finger3_j1" type="revolute">
    <origin xyz="0 0.07 0" rpy="-0 0 -0"/>
    <parent link="left_hand"/>
    <child link="left_finger_3_j1"/>
    <axis xyz="0 0 1"/>
    <limit effort="100" velocity="100" lower="-1.91986" upper="0.0872665"/>
    <joint_properties friction="0.1"/>
  </joint>
  <!-- Link left_finger_4_j1 -->
  <link name="left_finger_4_j1">
    <inertial>
      <origin xyz="-0 0.0025 -0" rpy="0 0 0"/>
      <mass value="0.000496"/>
      <inertia ixx="3.679e-09" ixy="0" ixz="0" iyy="6.779e-09" iyz="0" izz="5.167e-09"/>
    </inertial>
    <!-- Part left_finger_4_j1_parts -->
    <visual>
      <origin xyz="-0 0.0025 -0" rpy="-0 -1.5708 0"/>
      <geometry>
        <mesh filename="../meshes/left_finger_4_j1_visual.stl"/>
      </geometry>
      <material name="left_finger_4_j1_parts_material">
        <color rgba="0.647059 0.647059 0.647059 1"/>
      </material>
    </visual>
  </link>
  <!-- Link left_finger_4_j2 -->
  <link name="left_finger_4_j2">
    <inertial>
      <origin xyz="-0 0.015 -0" rpy="0 0 0"/>
      <mass value="0.002976"/>
      <inertia ixx="2.48e-07" ixy="-0" ixz="0" iyy="4.0672e-08" iyz="-0" izz="2.39072e-07"/>
    </inertial>
    <!-- Part left_finger_4_j2_parts -->
    <visual>
      <origin xyz="-0 0.015 -0" rpy="-0 0 -0"/>
      <geometry>
        <mesh filename="../meshes/left_finger_4_j2_visual.stl"/>
      </geometry>
      <material name="left_finger_4_j2_parts_material">
        <color rgba="0.917647 0.917647 0.917647 1"/>
      </material>
    </visual>
  </link>
  <!-- Link left_finger_4_j3 -->
  <link name="left_finger_4_j3">
    <inertial>
      <origin xyz="0 0.01 0" rpy="0 0 0"/>
      <mass value="0.0011904"/>
      <inertia ixx="4.3251e-08" ixy="-0" ixz="-0" iyy="9.92e-09" iyz="-0" izz="4.6029e-08"/>
    </inertial>
    <!-- Part left_finger_4_j3_parts -->
    <visual>
      <origin xyz="0 0.01 0" rpy="-0 -1.5708 0"/>
      <geometry>
        <mesh filename="../meshes/left_finger_4_j3_visual.stl"/>
      </geometry>
      <material name="left_finger_4_j3_parts_material">
        <color rgba="0.231373 0.380392 0.705882 1"/>
      </material>
    </visual>
  </link>
  <!-- Link left_finger_4_j4 -->
  <link name="left_finger_4_j4">
    <inertial>
      <origin xyz="-0.000432099 0.00438272 0" rpy="0 0 0"/>
      <mass value="0.0004185"/>
      <inertia ixx="3.877e-09" ixy="6.61e-10" ixz="0" iyy="2.909e-09" iyz="-0" izz="5.043e-09"/>
    </inertial>
    <!-- Part left_finger_4_j4_parts -->
    <visual>
      <origin xyz="-0.000432099 0.00438272 0" rpy="-0 -1.5708 0"/>
      <geometry>
        <mesh filename="../meshes/left_finger_4_j4_visual.stl"/>
      </geometry>
      <material name="left_finger_4_j4_parts_material">
        <color rgba="0.917647 0.917647 0.917647 1"/>
      </material>
    </visual>
  </link>
  <!-- Joint from left_finger_4_j3 to left_finger_4_j4 -->
  <joint name="left_finger4_j4" type="revolute">
    <origin xyz="-0 0.025 0" rpy="0 -0 0"/>
    <parent link="left_finger_4_j3"/>
    <child link="left_finger_4_j4"/>
    <axis xyz="0 0 1"/>
    <limit effort="100" velocity="100" lower="-1.91986" upper="0.0872665"/>
    <joint_properties friction="0.1"/>
  </joint>
  <!-- Joint from left_finger_4_j2 to left_finger_4_j3 -->
  <joint name="left_finger4_j3" type="revolute">
    <origin xyz="-0 0.035 0" rpy="0 1.5708 0"/>
    <parent link="left_finger_4_j2"/>
    <child link="left_finger_4_j3"/>
    <axis xyz="0 0 1"/>
    <limit effort="100" velocity="100" lower="-1.91986" upper="0.0872665"/>
    <joint_properties friction="0.1"/>
  </joint>
  <!-- Joint from left_finger_4_j1 to left_finger_4_j2 -->
  <joint name="left_finger4_j2" type="revolute">
    <origin xyz="0 0.01 0" rpy="0 -1.5708 0"/>
    <parent link="left_finger_4_j1"/>
    <child link="left_finger_4_j2"/>
    <axis xyz="0 0 1"/>
    <limit effort="100" velocity="100" lower="-0.349066" upper="0.349066"/>
    <joint_properties friction="0.1"/>
  </joint>
  <!-- Joint from left_hand to left_finger_4_j1 -->
  <joint name="left_finger4_j1" type="revolute">
    <origin xyz="0 0.07 -0.015" rpy="-0 0 -0"/>
    <parent link="left_hand"/>
    <child link="left_finger_4_j1"/>
    <axis xyz="0 0 1"/>
    <limit effort="100" velocity="100" lower="-1.91986" upper="0.0872665"/>
    <joint_properties friction="0.1"/>
  </joint>
  <!-- Link left_finger_5_j1 -->
  <link name="left_finger_5_j1">
    <inertial>
      <origin xyz="-0 0.0025 -0" rpy="0 0 0"/>
      <mass value="0.000496"/>
      <inertia ixx="3.679e-09" ixy="0" ixz="0" iyy="6.779e-09" iyz="0" izz="5.167e-09"/>
    </inertial>
    <!-- Part left_finger_5_j1_parts -->
    <visual>
      <origin xyz="-0 0.0025 -0" rpy="-0 -1.5708 0"/>
      <geometry>
        <mesh filename="../meshes/left_finger_5_j1_visual.stl"/>
      </geometry>
      <material name="left_finger_5_j1_parts_material">
        <color rgba="0.231373 0.380392 0.705882 1"/>
      </material>
    </visual>
  </link>
  <!-- Link left_finger_5_j2 -->
  <link name="left_finger_5_j2">
    <inertial>
      <origin xyz="-0 0.01 -0" rpy="0 0 0"/>
      <mass value="0.001984"/>
      <inertia ixx="8.2667e-08" ixy="0" ixz="0" iyy="2.7115e-08" iyz="-0" izz="7.6715e-08"/>
    </inertial>
    <!-- Part left_finger_5_j2_parts -->
    <visual>
      <origin xyz="-0 0.01 -0" rpy="-0 0 -0"/>
      <geometry>
        <mesh filename="../meshes/left_finger_5_j2_visual.stl"/>
      </geometry>
      <material name="left_finger_5_j2_parts_material">
        <color rgba="0.768627 0.886275 0.952941 1"/>
      </material>
    </visual>
  </link>
  <!-- Link left_finger_5_j3 -->
  <link name="left_finger_5_j3">
    <inertial>
      <origin xyz="0 0.0075 0" rpy="0 0 0"/>
      <mass value="0.0008928"/>
      <inertia ixx="1.9418e-08" ixy="0" ixz="-0" iyy="7.44e-09" iyz="-0" izz="2.1502e-08"/>
    </inertial>
    <!-- Part left_finger_5_j3_parts -->
    <visual>
      <origin xyz="0 0.0075 0" rpy="-0 -1.5708 0"/>
      <geometry>
        <mesh filename="../meshes/left_finger_5_j3_visual.stl"/>
      </geometry>
      <material name="left_finger_5_j3_parts_material">
        <color rgba="0.768627 0.886275 0.952941 1"/>
      </material>
    </visual>
  </link>
  <!-- Link left_finger_5_j4 -->
  <link name="left_finger_5_j4">
    <inertial>
      <origin xyz="-0.000432099 0.00438272 0" rpy="0 0 0"/>
      <mass value="0.0004185"/>
      <inertia ixx="3.877e-09" ixy="6.61e-10" ixz="0" iyy="2.909e-09" iyz="-0" izz="5.043e-09"/>
    </inertial>
    <!-- Part left_finger_5_j4_parts -->
    <visual>
      <origin xyz="-0.000432099 0.00438272 0" rpy="-0 -1.5708 0"/>
      <geometry>
        <mesh filename="../meshes/left_finger_5_j4_visual.stl"/>
      </geometry>
      <material name="left_finger_5_j4_parts_material">
        <color rgba="0.972549 0.529412 0.00392157 1"/>
      </material>
    </visual>
  </link>
  <!-- Joint from left_finger_5_j3 to left_finger_5_j4 -->
  <joint name="left_finger5_j4" type="revolute">
    <origin xyz="-0 0.02 0" rpy="-0 0 -0"/>
    <parent link="left_finger_5_j3"/>
    <child link="left_finger_5_j4"/>
    <axis xyz="0 0 1"/>
    <limit effort="100" velocity="100" lower="-1.91986" upper="0.0872665"/>
    <joint_properties friction="0.1"/>
  </joint>
  <!-- Joint from left_finger_5_j2 to left_finger_5_j3 -->
  <joint name="left_finger5_j3" type="revolute">
    <origin xyz="0 0.025 0" rpy="0 1.5708 0"/>
    <parent link="left_finger_5_j2"/>
    <child link="left_finger_5_j3"/>
    <axis xyz="0 0 1"/>
    <limit effort="100" velocity="100" lower="-1.91986" upper="0.0872665"/>
    <joint_properties friction="0.1"/>
  </joint>
  <!-- Joint from left_finger_5_j1 to left_finger_5_j2 -->
  <joint name="left_finger5_j2" type="revolute">
    <origin xyz="0 0.01 -0" rpy="0 -1.5708 0"/>
    <parent link="left_finger_5_j1"/>
    <child link="left_finger_5_j2"/>
    <axis xyz="0 0 1"/>
    <limit effort="100" velocity="100" lower="-0.349066" upper="0.349066"/>
    <joint_properties friction="0.1"/>
  </joint>
  <!-- Joint from left_hand to left_finger_5_j1 -->
  <joint name="left_finger5_j1" type="revolute">
    <origin xyz="0 0.07 -0.03" rpy="-0 0 -0"/>
    <parent link="left_hand"/>
    <child link="left_finger_5_j1"/>
    <axis xyz="0 0 1"/>
    <limit effort="100" velocity="100" lower="-1.91986" upper="0.0872665"/>
    <joint_properties friction="0.1"/>
  </joint>
  <!-- Joint from left_wrist_roll to left_hand -->
  <joint name="left_wrist_pitch" type="revolute">
    <origin xyz="-0 -0 0" rpy="0 1.5708 0"/>
    <parent link="left_wrist_roll"/>
    <child link="left_hand"/>
    <axis xyz="0 0 1"/>
    <limit effort="100" velocity="100" lower="-1.5708" upper="1.5708"/>
    <joint_properties friction="0.1"/>
  </joint>
  <!-- Joint from left_wrist_yaw to left_wrist_roll -->
  <joint name="left_wrist_roll" type="revolute">
    <origin xyz="0 0 0" rpy="1.5708 0 -0"/>
    <parent link="left_wrist_yaw"/>
    <child link="left_wrist_roll"/>
    <axis xyz="0 0 1"/>
    <limit effort="100" velocity="100" lower="-0.349066" upper="0.349066"/>
    <joint_properties friction="0.1"/>
  </joint>
  <!-- Joint from left_elbow_pitch to left_wrist_yaw -->
  <joint name="left_wrist_yaw" type="revolute">
    <origin xyz="-0 0.18 0" rpy="-1.5708 0 0"/>
    <parent link="left_elbow_pitch"/>
    <child link="left_wrist_yaw"/>
    <axis xyz="0 0 1"/>
    <limit effort="100" velocity="100" lower="-1.5708" upper="1.5708"/>
    <joint_properties friction="0.1"/>
  </joint>
  <!-- Joint from left_shoulder_yaw to left_elbow_pitch -->
  <joint name="left_elbow_pitch" type="revolute">
    <origin xyz="0 -0 0.2" rpy="1.5708 0 -0"/>
    <parent link="left_shoulder_yaw"/>
    <child link="left_elbow_pitch"/>
    <axis xyz="0 0 1"/>
    <limit effort="100" velocity="100" lower="-2.35619" upper="0"/>
    <joint_properties friction="0.1"/>
  </joint>
  <!-- Joint from left_shoulder_roll to left_shoulder_yaw -->
  <joint name="left_shoulder_yaw" type="revolute">
    <origin xyz="0 0 0" rpy="-1.5708 -1.5708 0"/>
    <parent link="left_shoulder_roll"/>
    <child link="left_shoulder_yaw"/>
    <axis xyz="0 0 1"/>
    <limit effort="100" velocity="100" lower="-1.5708" upper="1.5708"/>
    <joint_properties friction="0.1"/>
  </joint>
  <!-- Joint from left_shoulder_pitch to left_shoulder_roll -->
  <joint name="left_shoulder_roll" type="revolute">
    <origin xyz="0 0 0" rpy="1.5708 -0 1.5708"/>
    <parent link="left_shoulder_pitch"/>
    <child link="left_shoulder_roll"/>
    <axis xyz="0 0 1"/>
    <limit effort="100" velocity="100" lower="-1.74533" upper="1.74533"/>
    <joint_properties friction="0.1"/>
  </joint>
  <!-- Joint from torso to left_shoulder_pitch -->
  <joint name="left_shoulder_pitch" type="revolute">
    <origin xyz="0.09 0.17 0" rpy="-3.14159 -1.5708 0"/>
    <parent link="torso"/>
    <child link="left_shoulder_pitch"/>
    <axis xyz="0 0 1"/>
    <limit effort="100" velocity="100" lower="-3.14159" upper="0.785398"/>
    <joint_properties friction="0.1"/>
  </joint>
  <!-- Link right_shoulder_pitch -->
  <link name="right_shoulder_pitch">
    <inertial>
      <origin xyz="-0 0 0" rpy="0 0 0"/>
      <mass value="0.311646"/>
      <inertia ixx="0.000249317" ixy="-0" ixz="0" iyy="0.000189585" iyz="0" izz="0.000189585"/>
    </inertial>
    <!-- Part right_shoulder_pitch_parts -->
    <visual>
      <origin xyz="-0 0 0" rpy="1.5708 0 -0"/>
      <geometry>
        <mesh filename="../meshes/right_shoulder_pitch_visual.stl"/>
      </geometry>
      <material name="right_shoulder_pitch_parts_material">
        <color rgba="0.231373 0.380392 0.705882 1"/>
      </material>
    </visual>
  </link>
  <!-- Link right_shoulder_roll -->
  <link name="right_shoulder_roll">
    <inertial>
      <origin xyz="0 -0.105 -0" rpy="0 0 0"/>
      <mass value="0.455782"/>
      <inertia ixx="0.000744444" ixy="-0" ixz="-0" iyy="0.000205102" iyz="0" izz="0.000744444"/>
    </inertial>
    <!-- Part right_shoulder_roll_parts -->
    <collision>
      <origin xyz="0 -0.105 -0" rpy="1.5708 -0 -0"/>
      <geometry>
        <cylinder length="0.08" radius="0.03"/>
      </geometry>
    </collision>
    <visual>
      <origin xyz="0 -0.105 -0" rpy="-0 -1.5708 0"/>
      <geometry>
        <mesh filename="../meshes/right_shoulder_roll_visual.stl"/>
      </geometry>
      <material name="right_shoulder_roll_parts_material">
        <color rgba="0.917647 0.917647 0.917647 1"/>
      </material>
    </visual>
  </link>
  <!-- Link right_shoulder_yaw -->
  <link name="right_shoulder_yaw">
    <inertial>
      <origin xyz="-0 -0 0.2" rpy="0 0 0"/>
      <mass value="0.175301"/>
      <inertia ixx="7.59637e-05" ixy="-0" ixz="-0" iyy="7.88854e-05" iyz="-0" izz="7.59637e-05"/>
    </inertial>
    <!-- Part right_shoulder_yaw_parts -->
    <visual>
      <origin xyz="-0 -0 0.2" rpy="-1.5708 -0 0"/>
      <geometry>
        <mesh filename="../meshes/right_shoulder_yaw_visual.stl"/>
      </geometry>
      <material name="right_shoulder_yaw_parts_material">
        <color rgba="0.768627 0.886275 0.952941 1"/>
      </material>
    </visual>
  </link>
  <!-- Link right_elbow_pitch -->
  <link name="right_elbow_pitch">
    <inertial>
      <origin xyz="-0 0.0925 0" rpy="0 0 0"/>
      <mass value="0.304342"/>
      <inertia ixx="0.000443832" ixy="-0" ixz="-0" iyy="9.51068e-05" iyz="0" izz="0.000443832"/>
    </inertial>
    <!-- Part right_elbow_pitch_parts -->
    <collision>
      <origin xyz="-0 0.095 0" rpy="-1.5708 -1.5708 0"/>
      <geometry>
        <cylinder length="0.08" radius="0.025"/>
      </geometry>
    </collision>
    <visual>
      <origin xyz="-0 0.0925 0" rpy="-3.14159 0 -0"/>
      <geometry>
        <mesh filename="../meshes/right_elbow_pitch_visual.stl"/>
      </geometry>
      <material name="right_elbow_pitch_parts_material">
        <color rgba="0.972549 0.529412 0.00392157 1"/>
      </material>
    </visual>
  </link>
  <!-- Link right_wrist_yaw -->
  <link name="right_wrist_yaw">
    <inertial>
      <origin xyz="0 -0 -0" rpy="0 0 0"/>
      <mass value="0.0779115"/>
      <inertia ixx="2.40227e-05" ixy="-0" ixz="-0" iyy="1.55823e-05" iyz="0" izz="2.40227e-05"/>
    </inertial>
    <!-- Part right_wrist_yaw_parts -->
    <visual>
      <origin xyz="0 -0 -0" rpy="-1.5708 0 0"/>
      <geometry>
        <mesh filename="../meshes/right_wrist_yaw_visual.stl"/>
      </geometry>
      <material name="right_wrist_yaw_parts_material">
        <color rgba="0.980392 0.713725 0.00392157 1"/>
      </material>
    </visual>
  </link>
  <!-- Link right_wrist_roll -->
  <link name="right_wrist_roll">
    <inertial>
      <origin xyz="0 -0 -0" rpy="0 0 0"/>
      <mass value="0.0779115"/>
      <inertia ixx="1.55823e-05" ixy="0" ixz="0" iyy="2.40227e-05" iyz="0" izz="2.40227e-05"/>
    </inertial>
    <!-- Part right_wrist_roll_parts -->
    <visual>
      <origin xyz="0 -0 -0" rpy="-3.14159 0 -0"/>
      <geometry>
        <mesh filename="../meshes/right_wrist_roll_visual.stl"/>
      </geometry>
      <material name="right_wrist_roll_parts_material">
        <color rgba="0.498039 0.498039 0.498039 1"/>
      </material>
    </visual>
  </link>
  <!-- Link right_hand -->
  <link name="right_hand">
    <inertial>
      <origin xyz="0 0.0479645 -0.0118716" rpy="0 0 0"/>
      <mass value="0.028365"/>
      <inertia ixx="7.37812e-06" ixy="0" ixz="-0" iyy="5.11736e-06" iyz="2.58217e-07" izz="3.32444e-06"/>
    </inertial>
    <!-- Part right_hand_parts -->
    <collision>
      <origin xyz="0 0.08 0" rpy="1.5708 -0 1.5708"/>
      <geometry>
        <box size="0.1 0.07 0.015"/>
      </geometry>
    </collision>
    <visual>
      <origin xyz="0 0.0479645 -0.0118716" rpy="-3.14159 -1.5708 0"/>
      <geometry>
        <mesh filename="../meshes/right_hand_visual.stl"/>
      </geometry>
      <material name="right_hand_parts_material">
        <color rgba="0.615686 0.811765 0.929412 1"/>
      </material>
    </visual>
  </link>
  <!-- Link right_finger_1_j1 -->
  <link name="right_finger_1_j1">
    <inertial>
      <origin xyz="-0 0.0025 0" rpy="0 0 0"/>
      <mass value="0.000744"/>
      <inertia ixx="1.0478e-08" ixy="0" ixz="0" iyy="1.5128e-08" iyz="-0" izz="7.75e-09"/>
    </inertial>
    <!-- Part right_finger_1_j1_parts -->
    <visual>
      <origin xyz="-0 0.0025 0" rpy="1.5708 -0.785398 1.5708"/>
      <geometry>
        <mesh filename="../meshes/right_finger_1_j1_visual.stl"/>
      </geometry>
      <material name="right_finger_1_j1_parts_material">
        <color rgba="0.498039 0.498039 0.498039 1"/>
      </material>
    </visual>
  </link>
  <!-- Link right_finger_1_j2 -->
  <link name="right_finger_1_j2">
    <inertial>
      <origin xyz="-0 0.01 -0" rpy="0 0 0"/>
      <mass value="0.002976"/>
      <inertia ixx="1.24e-07" ixy="-0" ixz="-0" iyy="6.0512e-08" iyz="-0" izz="1.34912e-07"/>
    </inertial>
    <!-- Part right_finger_1_j2_parts -->
    <visual>
      <origin xyz="-0 0.01 -0" rpy="-0 -0 2.35619"/>
      <geometry>
        <mesh filename="../meshes/right_finger_1_j2_visual.stl"/>
      </geometry>
      <material name="right_finger_1_j2_parts_material">
        <color rgba="0.972549 0.529412 0.00392157 1"/>
      </material>
    </visual>
  </link>
  <!-- Link right_finger_1_j3 -->
  <link name="right_finger_1_j3">
    <inertial>
      <origin xyz="-0 0.01 0" rpy="0 0 0"/>
      <mass value="0.001984"/>
      <inertia ixx="8.2667e-08" ixy="0" ixz="-0" iyy="2.7115e-08" iyz="0" izz="7.6715e-08"/>
    </inertial>
    <!-- Part right_finger_1_j3_parts -->
    <visual>
      <origin xyz="-0 0.01 0" rpy="1.5708 -0.785398 1.5708"/>
      <geometry>
        <mesh filename="../meshes/right_finger_1_j3_visual.stl"/>
      </geometry>
      <material name="right_finger_1_j3_parts_material">
        <color rgba="0.498039 0.498039 0.498039 1"/>
      </material>
    </visual>
  </link>
  <!-- Link right_finger_1_j4 -->
  <link name="right_finger_1_j4">
    <inertial>
      <origin xyz="0.000271318 0.00682171 -0" rpy="0 0 0"/>
      <mass value="0.001333"/>
      <inertia ixx="3.2905e-08" ixy="-2.247e-09" ixz="0" iyy="1.7887e-08" iyz="0" izz="2.8576e-08"/>
    </inertial>
    <!-- Part right_finger_1_j4_parts -->
    <visual>
      <origin xyz="0.000271318 0.00682171 -0" rpy="1.5708 -0.785398 1.5708"/>
      <geometry>
        <mesh filename="../meshes/right_finger_1_j4_visual.stl"/>
      </geometry>
      <material name="right_finger_1_j4_parts_material">
        <color rgba="0.980392 0.713725 0.00392157 1"/>
      </material>
    </visual>
  </link>
  <!-- Joint from right_finger_1_j3 to right_finger_1_j4 -->
  <joint name="right_finger1_j4" type="revolute">
    <origin xyz="0 0.025 -0" rpy="-0 0 -0"/>
    <parent link="right_finger_1_j3"/>
    <child link="right_finger_1_j4"/>
    <axis xyz="0 0 1"/>
    <limit effort="100" velocity="100" lower="-0.0872665" upper="1.91986"/>
    <joint_properties friction="0.1"/>
  </joint>
  <!-- Joint from right_finger_1_j2 to right_finger_1_j3 -->
  <joint name="right_finger1_j3" type="revolute">
    <origin xyz="0 0.025 0" rpy="-0 -1.5708 0"/>
    <parent link="right_finger_1_j2"/>
    <child link="right_finger_1_j3"/>
    <axis xyz="0 0 1"/>
    <limit effort="100" velocity="100" lower="-0.0872665" upper="1.91986"/>
    <joint_properties friction="0.1"/>
  </joint>
  <!-- Joint from right_finger_1_j1 to right_finger_1_j2 -->
  <joint name="right_finger1_j2" type="revolute">
    <origin xyz="-0 0.01 -0" rpy="0 1.5708 0"/>
    <parent link="right_finger_1_j1"/>
    <child link="right_finger_1_j2"/>
    <axis xyz="0 0 1"/>
    <limit effort="100" velocity="100" lower="-0.349066" upper="0.349066"/>
    <joint_properties friction="0.1"/>
  </joint>
  <!-- Joint from right_hand to right_finger_1_j1 -->
  <joint name="right_finger1_j1" type="revolute">
    <origin xyz="0 0.035 0.015" rpy="0.785398 0 0"/>
    <parent link="right_hand"/>
    <child link="right_finger_1_j1"/>
    <axis xyz="0 0 1"/>
    <limit effort="100" velocity="100" lower="-0.0872665" upper="1.91986"/>
    <joint_properties friction="0.1"/>
  </joint>
  <!-- Link right_finger_2_j1 -->
  <link name="right_finger_2_j1">
    <inertial>
      <origin xyz="0 0.0025 0" rpy="0 0 0"/>
      <mass value="0.000496"/>
      <inertia ixx="3.679e-09" ixy="0" ixz="0" iyy="6.779e-09" iyz="0" izz="5.167e-09"/>
    </inertial>
    <!-- Part right_finger_2_j1_parts -->
    <visual>
      <origin xyz="0 0.0025 0" rpy="-3.14159 -1.5708 0"/>
      <geometry>
        <mesh filename="../meshes/right_finger_2_j1_visual.stl"/>
      </geometry>
      <material name="right_finger_2_j1_parts_material">
        <color rgba="0.980392 0.713725 0.00392157 1"/>
      </material>
    </visual>
  </link>
  <!-- Link right_finger_2_j2 -->
  <link name="right_finger_2_j2">
    <inertial>
      <origin xyz="0 0.0125 0" rpy="0 0 0"/>
      <mass value="0.00248"/>
      <inertia ixx="1.49833e-07" ixy="-0" ixz="0" iyy="3.3893e-08" iyz="0" izz="1.42393e-07"/>
    </inertial>
    <!-- Part right_finger_2_j2_parts -->
    <visual>
      <origin xyz="0 0.0125 0" rpy="0 -0 -3.14159"/>
      <geometry>
        <mesh filename="../meshes/right_finger_2_j2_visual.stl"/>
      </geometry>
      <material name="right_finger_2_j2_parts_material">
        <color rgba="0.647059 0.647059 0.647059 1"/>
      </material>
    </visual>
  </link>
  <!-- Link right_finger_2_j3 -->
  <link name="right_finger_2_j3">
    <inertial>
      <origin xyz="0 0.01 -0" rpy="0 0 0"/>
      <mass value="0.0011904"/>
      <inertia ixx="4.3251e-08" ixy="-0" ixz="0" iyy="9.92e-09" iyz="0" izz="4.6029e-08"/>
    </inertial>
    <!-- Part right_finger_2_j3_parts -->
    <visual>
      <origin xyz="0 0.01 -0" rpy="-3.14159 -1.5708 0"/>
      <geometry>
        <mesh filename="../meshes/right_finger_2_j3_visual.stl"/>
      </geometry>
      <material name="right_finger_2_j3_parts_material">
        <color rgba="0.498039 0.498039 0.498039 1"/>
      </material>
    </visual>
  </link>
  <!-- Link right_finger_2_j4 -->
  <link name="right_finger_2_j4">
    <inertial>
      <origin xyz="0.000432099 0.00438272 -0" rpy="0 0 0"/>
      <mass value="0.0004185"/>
      <inertia ixx="3.877e-09" ixy="-6.61e-10" ixz="0" iyy="2.909e-09" iyz="0" izz="5.043e-09"/>
    </inertial>
    <!-- Part right_finger_2_j4_parts -->
    <visual>
      <origin xyz="0.000432099 0.00438272 -0" rpy="-3.14159 -1.5708 0"/>
      <geometry>
        <mesh filename="../meshes/right_finger_2_j4_visual.stl"/>
      </geometry>
      <material name="right_finger_2_j4_parts_material">
        <color rgba="0.980392 0.713725 0.00392157 1"/>
      </material>
    </visual>
  </link>
  <!-- Joint from right_finger_2_j3 to right_finger_2_j4 -->
  <joint name="right_finger2_j4" type="revolute">
    <origin xyz="0 0.025 -0" rpy="0 0 0"/>
    <parent link="right_finger_2_j3"/>
    <child link="right_finger_2_j4"/>
    <axis xyz="0 0 1"/>
    <limit effort="100" velocity="100" lower="-0.0872665" upper="1.91986"/>
    <joint_properties friction="0.1"/>
  </joint>
  <!-- Joint from right_finger_2_j2 to right_finger_2_j3 -->
  <joint name="right_finger2_j3" type="revolute">
    <origin xyz="0 0.03 0" rpy="0 -1.5708 0"/>
    <parent link="right_finger_2_j2"/>
    <child link="right_finger_2_j3"/>
    <axis xyz="0 0 1"/>
    <limit effort="100" velocity="100" lower="-0.0872665" upper="1.91986"/>
    <joint_properties friction="0.1"/>
  </joint>
  <!-- Joint from right_finger_2_j1 to right_finger_2_j2 -->
  <joint name="right_finger2_j2" type="revolute">
    <origin xyz="-0 0.01 -0" rpy="0 1.5708 0"/>
    <parent link="right_finger_2_j1"/>
    <child link="right_finger_2_j2"/>
    <axis xyz="0 0 1"/>
    <limit effort="100" velocity="100" lower="-0.349066" upper="0.349066"/>
    <joint_properties friction="0.1"/>
  </joint>
  <!-- Joint from right_hand to right_finger_2_j1 -->
  <joint name="right_finger2_j1" type="revolute">
    <origin xyz="0 0.07 0.015" rpy="0 0 0"/>
    <parent link="right_hand"/>
    <child link="right_finger_2_j1"/>
    <axis xyz="0 0 1"/>
    <limit effort="100" velocity="100" lower="-0.0872665" upper="1.91986"/>
    <joint_properties friction="0.1"/>
  </joint>
  <!-- Link right_finger_3_j1 -->
  <link name="right_finger_3_j1">
    <inertial>
      <origin xyz="0 0.0025 -0" rpy="0 0 0"/>
      <mass value="0.000496"/>
      <inertia ixx="3.679e-09" ixy="0" ixz="0" iyy="6.779e-09" iyz="-0" izz="5.167e-09"/>
    </inertial>
    <!-- Part right_finger_3_j1_parts -->
    <visual>
      <origin xyz="0 0.0025 -0" rpy="-3.14159 -1.5708 0"/>
      <geometry>
        <mesh filename="../meshes/right_finger_3_j1_visual.stl"/>
      </geometry>
      <material name="right_finger_3_j1_parts_material">
        <color rgba="0.615686 0.811765 0.929412 1"/>
      </material>
    </visual>
  </link>
  <!-- Link right_finger_3_j2 -->
  <link name="right_finger_3_j2">
    <inertial>
      <origin xyz="0 0.015 0" rpy="0 0 0"/>
      <mass value="0.002976"/>
      <inertia ixx="2.48e-07" ixy="-0" ixz="-0" iyy="4.0672e-08" iyz="-0" izz="2.39072e-07"/>
    </inertial>
    <!-- Part right_finger_3_j2_parts -->
    <visual>
      <origin xyz="0 0.015 0" rpy="0 -0 -3.14159"/>
      <geometry>
        <mesh filename="../meshes/right_finger_3_j2_visual.stl"/>
      </geometry>
      <material name="right_finger_3_j2_parts_material">
        <color rgba="0.231373 0.380392 0.705882 1"/>
      </material>
    </visual>
  </link>
  <!-- Link right_finger_3_j3 -->
  <link name="right_finger_3_j3">
    <inertial>
      <origin xyz="0 0.0125 -0" rpy="0 0 0"/>
      <mass value="0.001488"/>
      <inertia ixx="8.1964e-08" ixy="0" ixz="-0" iyy="1.24e-08" iyz="0" izz="8.5436e-08"/>
    </inertial>
    <!-- Part right_finger_3_j3_parts -->
    <visual>
      <origin xyz="0 0.0125 -0" rpy="-3.14159 -1.5708 0"/>
      <geometry>
        <mesh filename="../meshes/right_finger_3_j3_visual.stl"/>
      </geometry>
      <material name="right_finger_3_j3_parts_material">
        <color rgba="0.615686 0.811765 0.929412 1"/>
      </material>
    </visual>
  </link>
  <!-- Link right_finger_3_j4 -->
  <link name="right_finger_3_j4">
    <inertial>
      <origin xyz="0.000432099 0.00438272 -0" rpy="0 0 0"/>
      <mass value="0.0004185"/>
      <inertia ixx="3.877e-09" ixy="-6.61e-10" ixz="-0" iyy="2.909e-09" iyz="-0" izz="5.043e-09"/>
    </inertial>
    <!-- Part right_finger_3_j4_parts -->
    <visual>
      <origin xyz="0.000432099 0.00438272 -0" rpy="-3.14159 -1.5708 0"/>
      <geometry>
        <mesh filename="../meshes/right_finger_3_j4_visual.stl"/>
      </geometry>
      <material name="right_finger_3_j4_parts_material">
        <color rgba="0.647059 0.647059 0.647059 1"/>
      </material>
    </visual>
  </link>
  <!-- Joint from right_finger_3_j3 to right_finger_3_j4 -->
  <joint name="right_finger3_j4" type="revolute">
    <origin xyz="-0 0.03 -0" rpy="0 0 0"/>
    <parent link="right_finger_3_j3"/>
    <child link="right_finger_3_j4"/>
    <axis xyz="0 0 1"/>
    <limit effort="100" velocity="100" lower="-0.0872665" upper="1.91986"/>
    <joint_properties friction="0.1"/>
  </joint>
  <!-- Joint from right_finger_3_j2 to right_finger_3_j3 -->
  <joint name="right_finger3_j3" type="revolute">
    <origin xyz="0 0.035 0" rpy="0 -1.5708 0"/>
    <parent link="right_finger_3_j2"/>
    <child link="right_finger_3_j3"/>
    <axis xyz="0 0 1"/>
    <limit effort="100" velocity="100" lower="-0.0872665" upper="1.91986"/>
    <joint_properties friction="0.1"/>
  </joint>
  <!-- Joint from right_finger_3_j1 to right_finger_3_j2 -->
  <joint name="right_finger3_j2" type="revolute">
    <origin xyz="0 0.01 0" rpy="-0 1.5708 0"/>
    <parent link="right_finger_3_j1"/>
    <child link="right_finger_3_j2"/>
    <axis xyz="0 0 1"/>
    <limit effort="100" velocity="100" lower="-0.349066" upper="0.349066"/>
    <joint_properties friction="0.1"/>
  </joint>
  <!-- Joint from right_hand to right_finger_3_j1 -->
  <joint name="right_finger3_j1" type="revolute">
    <origin xyz="0 0.07 -0" rpy="0 0 -0"/>
    <parent link="right_hand"/>
    <child link="right_finger_3_j1"/>
    <axis xyz="0 0 1"/>
    <limit effort="100" velocity="100" lower="-0.0872665" upper="1.91986"/>
    <joint_properties friction="0.1"/>
  </joint>
  <!-- Link right_finger_4_j1 -->
  <link name="right_finger_4_j1">
    <inertial>
      <origin xyz="-0 0.0025 0" rpy="0 0 0"/>
      <mass value="0.000496"/>
      <inertia ixx="3.679e-09" ixy="0" ixz="0" iyy="6.779e-09" iyz="-0" izz="5.167e-09"/>
    </inertial>
    <!-- Part right_finger_4_j1_parts -->
    <visual>
      <origin xyz="0 0.0025 0" rpy="-3.14159 -1.5708 0"/>
      <geometry>
        <mesh filename="../meshes/right_finger_4_j1_visual.stl"/>
      </geometry>
      <material name="right_finger_4_j1_parts_material">
        <color rgba="0.647059 0.647059 0.647059 1"/>
      </material>
    </visual>
  </link>
  <!-- Link right_finger_4_j2 -->
  <link name="right_finger_4_j2">
    <inertial>
      <origin xyz="0 0.015 0" rpy="0 0 0"/>
      <mass value="0.002976"/>
      <inertia ixx="2.48e-07" ixy="0" ixz="-0" iyy="4.0672e-08" iyz="-0" izz="2.39072e-07"/>
    </inertial>
    <!-- Part right_finger_4_j2_parts -->
    <visual>
      <origin xyz="0 0.015 0" rpy="0 -0 -3.14159"/>
      <geometry>
        <mesh filename="../meshes/right_finger_4_j2_visual.stl"/>
      </geometry>
      <material name="right_finger_4_j2_parts_material">
        <color rgba="0.917647 0.917647 0.917647 1"/>
      </material>
    </visual>
  </link>
  <!-- Link right_finger_4_j3 -->
  <link name="right_finger_4_j3">
    <inertial>
      <origin xyz="0 0.01 -0" rpy="0 0 0"/>
      <mass value="0.0011904"/>
      <inertia ixx="4.3251e-08" ixy="-0" ixz="0" iyy="9.92e-09" iyz="0" izz="4.6029e-08"/>
    </inertial>
    <!-- Part right_finger_4_j3_parts -->
    <visual>
      <origin xyz="0 0.01 -0" rpy="-3.14159 -1.5708 0"/>
      <geometry>
        <mesh filename="../meshes/right_finger_4_j3_visual.stl"/>
      </geometry>
      <material name="right_finger_4_j3_parts_material">
        <color rgba="0.231373 0.380392 0.705882 1"/>
      </material>
    </visual>
  </link>
  <!-- Link right_finger_4_j4 -->
  <link name="right_finger_4_j4">
    <inertial>
      <origin xyz="0.000432099 0.00438272 -0" rpy="0 0 0"/>
      <mass value="0.0004185"/>
      <inertia ixx="3.877e-09" ixy="-6.61e-10" ixz="0" iyy="2.909e-09" iyz="0" izz="5.043e-09"/>
    </inertial>
    <!-- Part right_finger_4_j4_parts -->
    <visual>
      <origin xyz="0.000432099 0.00438272 -0" rpy="-3.14159 -1.5708 0"/>
      <geometry>
        <mesh filename="../meshes/right_finger_4_j4_visual.stl"/>
      </geometry>
      <material name="right_finger_4_j4_parts_material">
        <color rgba="0.917647 0.917647 0.917647 1"/>
      </material>
    </visual>
  </link>
  <!-- Joint from right_finger_4_j3 to right_finger_4_j4 -->
  <joint name="right_finger4_j4" type="revolute">
    <origin xyz="0 0.025 0" rpy="-0 0 0"/>
    <parent link="right_finger_4_j3"/>
    <child link="right_finger_4_j4"/>
    <axis xyz="0 0 1"/>
    <limit effort="100" velocity="100" lower="-0.0872665" upper="1.91986"/>
    <joint_properties friction="0.1"/>
  </joint>
  <!-- Joint from right_finger_4_j2 to right_finger_4_j3 -->
  <joint name="right_finger4_j3" type="revolute">
    <origin xyz="0 0.035 -0" rpy="-0 -1.5708 0"/>
    <parent link="right_finger_4_j2"/>
    <child link="right_finger_4_j3"/>
    <axis xyz="0 0 1"/>
    <limit effort="100" velocity="100" lower="-0.0872665" upper="1.91986"/>
    <joint_properties friction="0.1"/>
  </joint>
  <!-- Joint from right_finger_4_j1 to right_finger_4_j2 -->
  <joint name="right_finger4_j2" type="revolute">
    <origin xyz="0 0.01 0" rpy="-0 1.5708 0"/>
    <parent link="right_finger_4_j1"/>
    <child link="right_finger_4_j2"/>
    <axis xyz="0 0 1"/>
    <limit effort="100" velocity="100" lower="-0.349066" upper="0.349066"/>
    <joint_properties friction="0.1"/>
  </joint>
  <!-- Joint from right_hand to right_finger_4_j1 -->
  <joint name="right_finger4_j1" type="revolute">
    <origin xyz="0 0.07 -0.015" rpy="-0 0 -0"/>
    <parent link="right_hand"/>
    <child link="right_finger_4_j1"/>
    <axis xyz="0 0 1"/>
    <limit effort="100" velocity="100" lower="-0.0872665" upper="1.91986"/>
    <joint_properties friction="0.1"/>
  </joint>
  <!-- Link right_finger_5_j1 -->
  <link name="right_finger_5_j1">
    <inertial>
      <origin xyz="0 0.0025 0" rpy="0 0 0"/>
      <mass value="0.000496"/>
      <inertia ixx="3.679e-09" ixy="-0" ixz="0" iyy="6.779e-09" iyz="0" izz="5.167e-09"/>
    </inertial>
    <!-- Part right_finger_5_j1_parts -->
    <visual>
      <origin xyz="0 0.0025 0" rpy="-3.14159 -1.5708 0"/>
      <geometry>
        <mesh filename="../meshes/right_finger_5_j1_visual.stl"/>
      </geometry>
      <material name="right_finger_5_j1_parts_material">
        <color rgba="0.231373 0.380392 0.705882 1"/>
      </material>
    </visual>
  </link>
  <!-- Link right_finger_5_j2 -->
  <link name="right_finger_5_j2">
    <inertial>
      <origin xyz="0 0.01 0" rpy="0 0 0"/>
      <mass value="0.001984"/>
      <inertia ixx="8.2667e-08" ixy="0" ixz="-0" iyy="2.7115e-08" iyz="0" izz="7.6715e-08"/>
    </inertial>
    <!-- Part right_finger_5_j2_parts -->
    <visual>
      <origin xyz="0 0.01 0" rpy="0 -0 -3.14159"/>
      <geometry>
        <mesh filename="../meshes/right_finger_5_j2_visual.stl"/>
      </geometry>
      <material name="right_finger_5_j2_parts_material">
        <color rgba="0.768627 0.886275 0.952941 1"/>
      </material>
    </visual>
  </link>
  <!-- Link right_finger_5_j3 -->
  <link name="right_finger_5_j3">
    <inertial>
      <origin xyz="0 0.0075 -0" rpy="0 0 0"/>
      <mass value="0.0008928"/>
      <inertia ixx="1.9418e-08" ixy="-0" ixz="-0" iyy="7.44e-09" iyz="0" izz="2.1502e-08"/>
    </inertial>
    <!-- Part right_finger_5_j3_parts -->
    <visual>
      <origin xyz="0 0.0075 -0" rpy="-3.14159 -1.5708 0"/>
      <geometry>
        <mesh filename="../meshes/right_finger_5_j3_visual.stl"/>
      </geometry>
      <material name="right_finger_5_j3_parts_material">
        <color rgba="0.768627 0.886275 0.952941 1"/>
      </material>
    </visual>
  </link>
  <!-- Link right_finger_5_j4 -->
  <link name="right_finger_5_j4">
    <inertial>
      <origin xyz="0.000432099 0.00438272 -0" rpy="0 0 0"/>
      <mass value="0.0004185"/>
      <inertia ixx="3.877e-09" ixy="-6.61e-10" ixz="0" iyy="2.909e-09" iyz="0" izz="5.043e-09"/>
    </inertial>
    <!-- Part right_finger_5_j4_parts -->
    <visual>
      <origin xyz="0.000432099 0.00438272 -0" rpy="-3.14159 -1.5708 0"/>
      <geometry>
        <mesh filename="../meshes/right_finger_5_j4_visual.stl"/>
      </geometry>
      <material name="right_finger_5_j4_parts_material">
        <color rgba="0.972549 0.529412 0.00392157 1"/>
      </material>
    </visual>
  </link>
  <!-- Joint from right_finger_5_j3 to right_finger_5_j4 -->
  <joint name="right_finger5_j4" type="revolute">
    <origin xyz="-0 0.02 0" rpy="0 0 0"/>
    <parent link="right_finger_5_j3"/>
    <child link="right_finger_5_j4"/>
    <axis xyz="0 0 1"/>
    <limit effort="100" velocity="100" lower="-0.0872665" upper="1.91986"/>
    <joint_properties friction="0.1"/>
  </joint>
  <!-- Joint from right_finger_5_j2 to right_finger_5_j3 -->
  <joint name="right_finger5_j3" type="revolute">
    <origin xyz="0 0.025 -0" rpy="-0 -1.5708 0"/>
    <parent link="right_finger_5_j2"/>
    <child link="right_finger_5_j3"/>
    <axis xyz="0 0 1"/>
    <limit effort="100" velocity="100" lower="-0.0872665" upper="1.91986"/>
    <joint_properties friction="0.1"/>
  </joint>
  <!-- Joint from right_finger_5_j1 to right_finger_5_j2 -->
  <joint name="right_finger5_j2" type="revolute">
    <origin xyz="0 0.01 -0" rpy="-0 1.5708 0"/>
    <parent link="right_finger_5_j1"/>
    <child link="right_finger_5_j2"/>
    <axis xyz="0 0 1"/>
    <limit effort="100" velocity="100" lower="-0.349066" upper="0.349066"/>
    <joint_properties friction="0.1"/>
  </joint>
  <!-- Joint from right_hand to right_finger_5_j1 -->
  <joint name="right_finger5_j1" type="revolute">
    <origin xyz="0 0.07 -0.03" rpy="0 0 -0"/>
    <parent link="right_hand"/>
    <child link="right_finger_5_j1"/>
    <axis xyz="0 0 1"/>
    <limit effort="100" velocity="100" lower="-0.0872665" upper="1.91986"/>
    <joint_properties friction="0.1"/>
  </joint>
  <!-- Joint from right_wrist_roll to right_hand -->
  <joint name="right_wrist_pitch" type="revolute">
    <origin xyz="0 0 0" rpy="0 1.5708 0"/>
    <parent link="right_wrist_roll"/>
    <child link="right_hand"/>
    <axis xyz="0 0 1"/>
    <limit effort="100" velocity="100" lower="-1.5708" upper="1.5708"/>
    <joint_properties friction="0.1"/>
  </joint>
  <!-- Joint from right_wrist_yaw to right_wrist_roll -->
  <joint name="right_wrist_roll" type="revolute">
    <origin xyz="-0 0 0" rpy="1.5708 0 0"/>
    <parent link="right_wrist_yaw"/>
    <child link="right_wrist_roll"/>
    <axis xyz="0 0 1"/>
    <limit effort="100" velocity="100" lower="-0.349066" upper="0.349066"/>
    <joint_properties friction="0.1"/>
  </joint>
  <!-- Joint from right_elbow_pitch to right_wrist_yaw -->
  <joint name="right_wrist_yaw" type="revolute">
    <origin xyz="0 0.18 0" rpy="-1.5708 -0 -0"/>
    <parent link="right_elbow_pitch"/>
    <child link="right_wrist_yaw"/>
    <axis xyz="0 0 1"/>
    <limit effort="100" velocity="100" lower="-1.5708" upper="1.5708"/>
    <joint_properties friction="0.1"/>
  </joint>
  <!-- Joint from right_shoulder_yaw to right_elbow_pitch -->
  <joint name="right_elbow_pitch" type="revolute">
    <origin xyz="-0 -0 0.2" rpy="1.5708 -0 -0"/>
    <parent link="right_shoulder_yaw"/>
    <child link="right_elbow_pitch"/>
    <axis xyz="0 0 1"/>
    <limit effort="100" velocity="100" lower="-2.35619" upper="0"/>
    <joint_properties friction="0.1"/>
  </joint>
  <!-- Joint from right_shoulder_roll to right_shoulder_yaw -->
  <joint name="right_shoulder_yaw" type="revolute">
    <origin xyz="0 0 0" rpy="1.5708 -1.5708 0"/>
    <parent link="right_shoulder_roll"/>
    <child link="right_shoulder_yaw"/>
    <axis xyz="0 0 1"/>
    <limit effort="100" velocity="100" lower="-1.5708" upper="1.5708"/>
    <joint_properties friction="0.1"/>
  </joint>
  <!-- Joint from right_shoulder_pitch to right_shoulder_roll -->
  <joint name="right_shoulder_roll" type="revolute">
    <origin xyz="-0 0 0" rpy="1.5708 -0 1.5708"/>
    <parent link="right_shoulder_pitch"/>
    <child link="right_shoulder_roll"/>
    <axis xyz="0 0 1"/>
    <limit effort="100" velocity="100" lower="-1.74533" upper="1.74533"/>
    <joint_properties friction="0.1"/>
  </joint>
  <!-- Joint from torso to right_shoulder_pitch -->
  <joint name="right_shoulder_pitch" type="revolute">
    <origin xyz="-0.09 0.17 -0" rpy="-3.14159 -1.5708 0"/>
    <parent link="torso"/>
    <child link="right_shoulder_pitch"/>
    <axis xyz="0 0 1"/>
    <limit effort="100" velocity="100" lower="-3.14159" upper="0.785398"/>
    <joint_properties friction="0.1"/>
  </joint>
  <!-- Link neck_yaw -->
  <link name="neck_yaw">
    <inertial>
      <origin xyz="-0 -0 0.04" rpy="0 0 0"/>
      <mass value="0.0779115"/>
      <inertia ixx="1.55823e-05" ixy="0" ixz="-0" iyy="2.40227e-05" iyz="0" izz="2.40227e-05"/>
    </inertial>
    <!-- Part neck_yaw_parts -->
    <visual>
      <origin xyz="-0 -0 0.04" rpy="0 0 -0"/>
      <geometry>
        <mesh filename="../meshes/neck_yaw_visual.stl"/>
      </geometry>
      <material name="neck_yaw_parts_material">
        <color rgba="0.647059 0.647059 0.647059 1"/>
      </material>
    </visual>
  </link>
  <!-- Link neck_roll -->
  <link name="neck_roll">
    <inertial>
      <origin xyz="-0 0.04 -0" rpy="0 0 0"/>
      <mass value="0.0779115"/>
      <inertia ixx="1.55823e-05" ixy="-0" ixz="0" iyy="2.40227e-05" iyz="-0" izz="2.40227e-05"/>
    </inertial>
    <!-- Part neck_roll_parts -->
    <visual>
      <origin xyz="-0 0.04 -0" rpy="-1.5708 -1.5708 0"/>
      <geometry>
        <mesh filename="../meshes/neck_roll_visual.stl"/>
      </geometry>
      <material name="neck_roll_parts_material">
        <color rgba="0.231373 0.380392 0.705882 1"/>
      </material>
    </visual>
  </link>
  <!-- Link head -->
  <link name="head">
    <inertial>
      <origin xyz="-0.00171328 0.0447946 -0" rpy="0 0 0"/>
      <mass value="4.83041"/>
      <inertia ixx="0.0191927" ixy="-8.25886e-05" ixz="0" iyy="0.0170256" iyz="0" izz="0.0196608"/>
    </inertial>
    <!-- Part head_parts -->
    <collision>
      <origin xyz="0 0.04 -0" rpy="-1.5708 1.5708 0"/>
      <geometry>
        <cylinder length="0.03" radius="0.09"/>
      </geometry>
    </collision>
    <visual>
      <origin xyz="-0.00171328 0.0447946 -0" rpy="1.5708 0 3.14159"/>
      <geometry>
        <mesh filename="../meshes/head_visual.stl"/>
      </geometry>
      <material name="head_parts_material">
        <color rgba="0.917647 0.917647 0.917647 1"/>
      </material>
    </visual>
  </link>
  <!-- Joint from neck_roll to head -->
  <joint name="neck_pitch" type="revolute">
    <origin xyz="-0 0.04 0" rpy="-0 1.5708 0"/>
    <parent link="neck_roll"/>
    <child link="head"/>
    <axis xyz="0 0 1"/>
    <limit effort="100" velocity="100" lower="-0.523599" upper="0.523599"/>
    <joint_properties friction="0.1"/>
  </joint>
  <!-- Joint from neck_yaw to neck_roll -->
  <joint name="neck_roll" type="revolute">
    <origin xyz="-0 0 0.04" rpy="1.5708 -0 1.5708"/>
    <parent link="neck_yaw"/>
    <child link="neck_roll"/>
    <axis xyz="0 0 1"/>
    <limit effort="100" velocity="100" lower="-0.523599" upper="0.523599"/>
    <joint_properties friction="0.1"/>
  </joint>
  <!-- Joint from torso to neck_yaw -->
  <joint name="neck_yaw" type="revolute">
    <origin xyz="-0 0.23 0" rpy="-1.5708 -1.5708 0"/>
    <parent link="torso"/>
    <child link="neck_yaw"/>
    <axis xyz="0 0 1"/>
    <limit effort="100" velocity="100" lower="-0.785398" upper="0.785398"/>
    <joint_properties friction="0.1"/>
  </joint>
  <!-- Joint from waist_pitch to torso -->
  <joint name="waist_roll" type="revolute">
    <origin xyz="-0 0.09 -0" rpy="0 -1.5708 0"/>
    <parent link="waist_pitch"/>
    <child link="torso"/>
    <axis xyz="0 0 1"/>
    <limit effort="100" velocity="100" lower="-1.0472" upper="1.0472"/>
    <joint_properties friction="0.1"/>
  </joint>
  <!-- Joint from waist_yaw to waist_pitch -->
  <joint name="waist_pitch" type="revolute">
    <origin xyz="0 -0 0" rpy="1.5708 0 3.14159"/>
    <parent link="waist_yaw"/>
    <child link="waist_pitch"/>
    <axis xyz="0 0 1"/>
    <limit effort="100" velocity="100" lower="-0.785398" upper="1.5708"/>
    <joint_properties friction="0.1"/>
  </joint>
  <!-- Joint from pelvis to waist_yaw -->
  <joint name="waist_yaw" type="revolute">
    <origin xyz="0 -0 0.12" rpy="-0 -0 0"/>
    <parent link="pelvis"/>
    <child link="waist_yaw"/>
    <axis xyz="0 0 1"/>
    <limit effort="100" velocity="100" lower="-1.5708" upper="1.5708"/>
    <joint_properties friction="0.1"/>
  </joint>
</robot>
